{"data":[{"e":"depthUpdate","E":1557445922064,"s":"BNBBTC","U":264200028,"u":264200039,"b":[["0.00303070","5.60000000"],["0.00303020","0.00000000"],["0.00303010","0.00000000"],["0.00297270","0.00000000"]],"a":[["0.00303320","5.60000000"],["0.00303340","0.00000000"],["0.00303600","0.00000000"]]},{"e":"depthUpdate","E":1557445923064,"s":"BNBBTC","U":264200040,"u":264200047,"b":[["0.00303070","17.37000000"],["0.00299650","50.06000000"],["0.00297110","1.27000000"],["0.00292510","2.20000000"],["0.00292090","2.00000000"]],"a":[["0.00304160","26.36000000"],["0.00304800","17.47000000"],["0.00305000","552.93000000"]]},{"e":"depthUpdate","E":1557445924064,"s":"BNBBTC","U":264200048,"u":264200058,"b":[["0.00303070","0.00000000"],["0.00302890","1067.37000000"],["0.00302390","9.85000000"],["0.00299530","2.15000000"],["0.00298880","21.80000000"]],"a":[["0.00303070","11.01000000"],["0.00303280","0.00000000"],["0.00303310","3.40000000"],["0.00303320","5.60000000"],["0.00303340","0.00000000"]]},{"e":"depthUpdate","E":1557445925064,"s":"BNBBTC","U":264200059,"u":264200078,"b":[["0.00303060","20.68000000"],["0.00302900","134.36000000"],["0.00302890","762.44000000"],["0.00302400","105.44000000"],["0.00302380","60.56000000"],["0.00302370","0.00000000"],["0.00302260","421.12000000"],["0.00302250","0.00000000"],["0.00299570","13.05000000"],["0.00299490","2.54000000"],["0.00299270","3.34000000"],["0.00299180","66.73000000"],["0.00298970","10.42000000"],["0.00296800","16.61000000"],["0.00296750","0.37000000"],["0.00296450","6.56000000"]],"a":[["0.00303070","0.00000000"],["0.00303420","119.30000000"],["0.00303610","59.85000000"]]},{"e":"depthUpdate","E":1557445926064,"s":"BNBBTC","U":264200079,"u":264200108,"b":[["0.00303010","0.00000000"],["0.00302920","0.00000000"],["0.00302910","65.19000000"],["0.00302390","0.00000000"],["0.00302030","79.86000000"],["0.00302000","2.00000000"],["0.00301900","332.00000000"],["0.00301180","3.86000000"],["0.00299650","0.00000000"],["0.00299600","233.63000000"]],"a":[["0.00303160","16.28000000"],["0.00303270","5.60000000"],["0.00303280","28.43000000"],["0.00303290","0.00000000"],["0.00303300","0.00000000"],["0.00303310","70.00000000"],["0.00303320","0.00000000"],["0.00303340","0.00000000"],["0.00303440","79.62000000"]]},{"e":"depthUpdate","E":1557445927064,"s":"BNBBTC","U":264200109,"u":264200114,"b":[["0.00302410","81.74000000"],["0.00302400","23.01000000"]],"a":[["0.00303540","295.06000000"],["0.00305970","0.00000000"],["0.00308760","1.79000000"],["0.00308810","0.00000000"]]},{"e":"depthUpdate","E":1557445928064,"s":"BNBBTC","U":264200115,"u":264200119,"b":[],"a":[["0.00303280","0.00000000"],["0.00304700","0.00000000"],["0.00304800","117.47000000"],["0.00305000","452.93000000"]]},{"e":"depthUpdate","E":1557445929064,"s":"BNBBTC","U":264200120,"u":264200131,"b":[["0.00302900","130.00000000"],["0.00302890","0.00000000"],["0.00302420","9.85000000"],["0.00302410","81.74000000"],["0.00302400","23.01000000"],["0.00302390","82.82000000"],["0.00302180","797.93000000"],["0.00302040","1.36000000"]],"a":[["0.00303540","0.00000000"],["0.00306020","54.20000000"]]},{"e":"depthUpdate","E":1557445930064,"s":"BNBBTC","U":264200132,"u":264200157,"b":[["0.00302900","0.00000000"],["0.00302470","9.85000000"],["0.00302460","111.38000000"],["0.00302450","304.94000000"],["0.00302440","0.00000000"],["0.00302430","143.17000000"],["0.00302420","120.88000000"],["0.00302410","81.74000000"],["0.00302400","327.95000000"],["0.00302390","0.00000000"],["0.00302380","0.00000000"],["0.00302230","0.00000000"],["0.00302000","332.00000000"],["0.00301900","2.00000000"]],"a":[["0.00303510","0.00000000"]]},{"e":"depthUpdate","E":1557445931064,"s":"BNBBTC","U":264200158,"u":264200172,"b":[["0.00302910","0.00000000"],["0.00302490","121.23000000"],["0.00302480","156.08000000"],["0.00302470","0.00000000"],["0.00302460","0.00000000"],["0.00302410","0.00000000"],["0.00302030","0.00000000"],["0.00298610","11.36000000"],["0.00298430","4.46000000"]],"a":[["0.00303490","20.00000000"],["0.00303590","0.00000000"]]},{"e":"depthUpdate","E":1557445932064,"s":"BNBBTC","U":264200173,"u":264200189,"b":[["0.00303000","0.00000000"],["0.00302510","121.23000000"],["0.00302500","270.79000000"],["0.00302490","70.00000000"],["0.00302480","79.24000000"],["0.00302420","0.00000000"],["0.00299610","183.57000000"],["0.00299600","50.06000000"],["0.00298790","6.62000000"]],"a":[["0.00306020","0.79000000"]]},{"e":"depthUpdate","E":1557445933065,"s":"BNBBTC","U":264200190,"u":264200212,"b":[["0.00303070","762.02000000"],["0.00302530","121.23000000"],["0.00302520","261.42000000"],["0.00302510","4.36000000"],["0.00302500","62.13000000"],["0.00302430","77.69000000"],["0.00302260","0.00000000"],["0.00299250","11.33000000"],["0.00298620","0.40000000"]],"a":[["0.00303300","60.78000000"],["0.00303430","0.00000000"],["0.00303560","22.99000000"],["0.00303600","295.05000000"],["0.00303680","0.00000000"],["0.00304800","17.47000000"]]},{"e":"depthUpdate","E":1557445934066,"s":"BNBBTC","U":264200213,"u":264200224,"b":[["0.00302550","121.22000000"],["0.00302540","75.41000000"],["0.00302530","0.00000000"],["0.00302520","183.92000000"],["0.00299090","12.02000000"]],"a":[["0.00303160","12.28000000"],["0.00304700","100.00000000"]]},{"e":"depthUpdate","E":1557445935065,"s":"BNBBTC","U":264200225,"u":264200236,"b":[["0.00302960","80.80000000"],["0.00302570","121.22000000"],["0.00302560","74.39000000"],["0.00302550","0.00000000"],["0.00302540","0.00000000"],["0.00302490","0.00000000"]],"a":[["0.00303160","4.32000000"],["0.00303300","0.00000000"]]},{"e":"depthUpdate","E":1557445936065,"s":"BNBBTC","U":264200237,"u":264200253,"b":[["0.00302590","121.22000000"],["0.00302580","79.89000000"],["0.00302570","0.00000000"],["0.00302560","0.00000000"],["0.00302510","0.00000000"],["0.00302460","797.25000000"],["0.00302180","0.00000000"]],"a":[["0.00303270","6.13000000"],["0.00303490","315.02000000"],["0.00303590","60.93000000"],["0.00304670","0.00000000"],["0.00304820","927.65000000"],["0.00305960","51.50000000"]]},{"e":"depthUpdate","E":1557445937066,"s":"BNBBTC","U":264200254,"u":264200272,"b":[["0.00302610","111.37000000"],["0.00302600","75.95000000"],["0.00302590","9.85000000"],["0.00302580","0.00000000"],["0.00302530","0.00000000"],["0.00302100","330.00000000"],["0.00302000","2.00000000"]],"a":[["0.00303160","0.92000000"],["0.00303270","0.53000000"],["0.00303300","9.00000000"],["0.00303320","0.00000000"],["0.00303490","20.00000000"],["0.00304600","100.00000000"],["0.00304700","0.00000000"]]},{"e":"depthUpdate","E":1557445938065,"s":"BNBBTC","U":264200273,"u":264200283,"b":[["0.00302630","111.37000000"],["0.00302620","81.99000000"],["0.00302610","0.00000000"],["0.00302600","0.00000000"],["0.00302530","128.24000000"]],"a":[["0.00304600","0.00000000"],["0.00304700","100.00000000"],["0.00322000","2.39000000"],["0.00325000","197.96000000"]]},{"e":"depthUpdate","E":1557445940066,"s":"BNBBTC","U":264200284,"u":264200289,"b":[["0.00296870","0.00000000"],["0.00296770","24.55000000"]],"a":[["0.00304160","0.00000000"],["0.00304480","0.00000000"]]},{"e":"depthUpdate","E":1557445941066,"s":"BNBBTC","U":264200290,"u":264200297,"b":[["0.00302650","111.37000000"],["0.00302640","75.91000000"],["0.00302630","0.00000000"],["0.00302620","0.00000000"],["0.00302540","0.00000000"]],"a":[]},{"e":"depthUpdate","E":1557445942066,"s":"BNBBTC","U":264200298,"u":264200302,"b":[["0.00303070","758.43000000"],["0.00303060","0.00000000"]],"a":[["0.00303600","0.00000000"],["0.00303640","295.02000000"],["0.00304040","13.19000000"]]},{"e":"depthUpdate","E":1557445943066,"s":"BNBBTC","U":264200303,"u":264200307,"b":[["0.00303100","109.16000000"],["0.00261530","0.60000000"]],"a":[["0.00303640","0.00000000"],["0.00304040","26.38000000"],["0.00304360","13.19000000"]]},{"e":"depthUpdate","E":1557445944067,"s":"BNBBTC","U":264200308,"u":264200318,"b":[["0.00303080","4.36000000"],["0.00302670","111.35000000"],["0.00302660","81.54000000"],["0.00302650","0.00000000"],["0.00302640","0.00000000"],["0.00299030","2.14000000"],["0.00298990","0.83000000"]],"a":[["0.00303440","0.00000000"],["0.00304360","26.38000000"]]},{"e":"depthUpdate","E":1557445945066,"s":"BNBBTC","U":264200319,"u":264200324,"b":[["0.00303100","179.16000000"],["0.00302960","10.80000000"]],"a":[["0.00303490","0.00000000"],["0.00303600","20.00000000"],["0.00303610","354.85000000"],["0.00303660","75.47000000"]]},{"e":"depthUpdate","E":1557445946066,"s":"BNBBTC","U":264200325,"u":264200327,"b":[["0.00302600","23.01000000"],["0.00302400","304.94000000"],["0.00301170","0.00000000"]],"a":[]},{"e":"depthUpdate","E":1557445947066,"s":"BNBBTC","U":264200328,"u":264200330,"b":[["0.00302680","9.84000000"],["0.00302590","0.00000000"]],"a":[["0.00303160","10.91000000"]]},{"e":"depthUpdate","E":1557445948067,"s":"BNBBTC","U":264200331,"u":264200339,"b":[["0.00303160","9.76000000"],["0.00303100","170.95000000"],["0.00303080","0.00000000"],["0.00302200","330.00000000"],["0.00302100","0.00000000"]],"a":[["0.00303160","0.00000000"],["0.00303540","0.00000000"],["0.00303610","295.00000000"],["0.00305960","0.00000000"]]},{"e":"depthUpdate","E":1557445949068,"s":"BNBBTC","U":264200340,"u":264200348,"b":[["0.00302700","111.34000000"],["0.00302690","76.15000000"],["0.00302670","0.00000000"],["0.00302660","0.00000000"]],"a":[["0.00303610","0.00000000"],["0.00304040","13.19000000"],["0.00304810","64.47000000"]]},{"e":"depthUpdate","E":1557445950068,"s":"BNBBTC","U":264200349,"u":264200352,"b":[["0.00303080","4.36000000"],["0.00301190","3.68000000"],["0.00297900","0.00000000"]],"a":[["0.00305980","54.63000000"]]},{"e":"depthUpdate","E":1557445951069,"s":"BNBBTC","U":264200353,"u":264200354,"b":[["0.00298320","1.67000000"]],"a":[["0.00303590","355.93000000"]]},{"e":"depthUpdate","E":1557445952068,"s":"BNBBTC","U":264200355,"u":264200358,"b":[["0.00301180","0.65000000"]],"a":[["0.00303420","0.00000000"],["0.00303540","127.51000000"]]},{"e":"depthUpdate","E":1557445953068,"s":"BNBBTC","U":264200359,"u":264200370,"b":[["0.00303160","5.69000000"],["0.00303080","0.00000000"],["0.00302530","0.00000000"],["0.00300060","0.00000000"]],"a":[["0.00303300","5.60000000"],["0.00303320","3.40000000"],["0.00303590","60.93000000"],["0.00305980","0.55000000"]]},{"e":"depthUpdate","E":1557445954068,"s":"BNBBTC","U":264200371,"u":264200395,"b":[["0.00303080","4.36000000"],["0.00302720","111.34000000"],["0.00302710","80.00000000"],["0.00302700","0.00000000"],["0.00302690","0.00000000"],["0.00302200","0.00000000"],["0.00301800","330.00000000"],["0.00300970","0.49000000"],["0.00299700","183.51000000"],["0.00299610","0.00000000"]],"a":[["0.00303300","5.60000000"],["0.00303320","3.40000000"],["0.00303500","20.00000000"],["0.00303560","0.00000000"],["0.00303600","0.00000000"],["0.00303640","294.99000000"],["0.00304580","22.99000000"]]},{"e":"depthUpdate","E":1557445955068,"s":"BNBBTC","U":264200396,"u":264200414,"b":[["0.00295650","14.85000000"],["0.00295440","0.00000000"]],"a":[["0.00303300","5.60000000"],["0.00303320","3.40000000"],["0.00305990","42.55000000"]]},{"e":"depthUpdate","E":1557445956068,"s":"BNBBTC","U":264200415,"u":264200446,"b":[["0.00303270","2.12000000"],["0.00303160","1.54000000"],["0.00303150","5.60000000"],["0.00303140","9.84000000"],["0.00303130","0.00000000"],["0.00303120","3.40000000"],["0.00303110","28.55000000"],["0.00302830","20.00000000"],["0.00302720","82.79000000"],["0.00302680","0.00000000"],["0.00301180","0.00000000"]],"a":[["0.00303270","0.00000000"],["0.00303300","0.00000000"],["0.00303310","0.00000000"],["0.00303320","0.00000000"],["0.00303330","0.00000000"],["0.00303350","0.00000000"],["0.00303450","0.00000000"],["0.00303490","0.00000000"],["0.00303500","0.00000000"],["0.00303530","12.05000000"],["0.00303540","18.32000000"],["0.00303640","0.00000000"],["0.00304680","0.00000000"],["0.00305990","0.00000000"]]},{"e":"depthUpdate","E":1557445957068,"s":"BNBBTC","U":264200447,"u":264200474,"b":[["0.00303290","0.00000000"],["0.00303280","2.42000000"],["0.00303270","70.00000000"],["0.00303170","90.95000000"],["0.00303150","0.00000000"],["0.00303120","0.00000000"],["0.00303110","159.72000000"],["0.00303100","100.95000000"],["0.00302520","59.92000000"],["0.00301390","4.08000000"],["0.00300380","0.00000000"]],"a":[["0.00303540","0.00000000"],["0.00303550","0.00000000"],["0.00303560","3.40000000"],["0.00303760","294.99000000"],["0.00304040","0.00000000"],["0.00304350","75.12000000"],["0.00307520","0.00000000"],["0.00307620","177.00000000"]]},{"e":"depthUpdate","E":1557445958068,"s":"BNBBTC","U":264200475,"u":264200508,"b":[["0.00303310","0.00000000"],["0.00303300","0.00000000"],["0.00303290","0.00000000"],["0.00303280","28.53000000"],["0.00303180","0.00000000"],["0.00303140","0.00000000"],["0.00303110","131.17000000"],["0.00303080","0.00000000"],["0.00302960","0.00000000"],["0.00302460","0.00000000"],["0.00302410","797.43000000"],["0.00300370","0.99000000"]],"a":[["0.00303300","0.00000000"],["0.00303520","9.00000000"],["0.00303530","5.81000000"],["0.00303550","0.00000000"],["0.00303560","0.00000000"],["0.00303590","0.00000000"],["0.00303640","65.24000000"],["0.00303660","95.47000000"],["0.00303760","0.00000000"],["0.00304700","0.00000000"],["0.00304800","148.63000000"],["0.00305000","552.93000000"]]},{"e":"depthUpdate","E":1557445959069,"s":"BNBBTC","U":264200509,"u":264200521,"b":[["0.00303300","20.51000000"],["0.00303290","39.59000000"],["0.00303280","0.00000000"],["0.00301390","6.13000000"],["0.00300530","12.18000000"],["0.00299510","0.00000000"],["0.00296550","0.00000000"]],"a":[["0.00303630","8.02000000"],["0.00303670","136.03000000"],["0.00304630","0.00000000"],["0.00304720","13.17000000"],["0.00304820","902.47000000"]]},{"e":"depthUpdate","E":1557445960069,"s":"BNBBTC","U":264200522,"u":264200526,"b":[["0.00303170","79.18000000"]],"a":[["0.00304130","0.00000000"],["0.00304220","77.09000000"],["0.00304720","26.34000000"],["0.00305360","37.71000000"]]},{"e":"depthUpdate","E":1557445961069,"s":"BNBBTC","U":264200527,"u":264200538,"b":[["0.00303300","20.51000000"],["0.00303180","0.00000000"],["0.00303170","0.00000000"],["0.00301820","10.00000000"]],"a":[["0.00304710","27.80000000"],["0.00304960","157.07000000"],["0.00305130","25.48000000"],["0.00306150","51.30000000"]]},{"e":"depthUpdate","E":1557445962070,"s":"BNBBTC","U":264200539,"u":264200545,"b":[["0.00303300","0.00000000"],["0.00303130","20.51000000"],["0.00303120","64.26000000"],["0.00302520","0.00000000"],["0.00301160","2.13000000"]],"a":[["0.00304990","0.00000000"],["0.00306160","51.63000000"]]},{"e":"depthUpdate","E":1557445963069,"s":"BNBBTC","U":264200546,"u":264200553,"b":[["0.00303290","0.00000000"],["0.00300210","5.23000000"],["0.00299840","0.00000000"],["0.00294930","0.40000000"],["0.00294720","0.00000000"]],"a":[["0.00305340","1.78000000"],["0.00306150","0.00000000"],["0.00306820","0.00000000"]]},{"e":"depthUpdate","E":1557445964069,"s":"BNBBTC","U":264200554,"u":264200560,"b":[["0.00303300","5.00000000"],["0.00302930","20.00000000"],["0.00302830","0.00000000"]],"a":[["0.00303520","5.60000000"],["0.00303620","3.40000000"],["0.00307170","3.75000000"],["0.00308760","0.00000000"]]},{"e":"depthUpdate","E":1557445965069,"s":"BNBBTC","U":264200561,"u":264200577,"b":[["0.00303280","9.84000000"],["0.00303070","0.00000000"],["0.00302720","0.00000000"],["0.00302510","82.75000000"],["0.00300020","183.32000000"],["0.00299700","0.00000000"]],"a":[["0.00303520","0.00000000"],["0.00303530","0.00000000"],["0.00303560","5.60000000"],["0.00303570","3.79000000"],["0.00303580","5.21000000"],["0.00303620","3.40000000"],["0.00303630","8.02000000"],["0.00309020","1.80000000"]]},{"e":"depthUpdate","E":1557445966070,"s":"BNBBTC","U":264200578,"u":264200584,"b":[["0.00303300","6.10000000"],["0.00303280","0.00000000"],["0.00303140","9.84000000"],["0.00297940","2.18000000"],["0.00296950","0.00000000"],["0.00293930","15.96000000"],["0.00293800","0.00000000"]],"a":[]},{"e":"depthUpdate","E":1557445967069,"s":"BNBBTC","U":264200585,"u":264200595,"b":[["0.00303300","0.00000000"],["0.00303270","52.70000000"]],"a":[["0.00303540","9.00000000"],["0.00303550","29.08000000"],["0.00303560","0.00000000"],["0.00303580","0.00000000"],["0.00303620","0.00000000"],["0.00303630","8.02000000"]]},{"e":"depthUpdate","E":1557445968069,"s":"BNBBTC","U":264200596,"u":264200598,"b":[["0.00303290","11.77000000"],["0.00303280","23.54000000"]],"a":[]},{"e":"depthUpdate","E":1557445969069,"s":"BNBBTC","U":264200599,"u":264200603,"b":[["0.00303290","63.13000000"]],"a":[["0.00303550","0.00000000"],["0.00303660","75.47000000"],["0.00303870","20.00000000"]]},{"e":"depthUpdate","E":1557445970070,"s":"BNBBTC","U":264200604,"u":264200612,"b":[["0.00303300","30.35000000"],["0.00303290","86.67000000"],["0.00303140","0.00000000"],["0.00303130","0.00000000"],["0.00295000","1045.88000000"]],"a":[["0.00303540","3.40000000"],["0.00303560","5.60000000"]]},{"e":"depthUpdate","E":1557445971069,"s":"BNBBTC","U":264200613,"u":264200616,"b":[["0.00299600","0.00000000"],["0.00299270","53.40000000"]],"a":[["0.00303730","140.00000000"],["0.00303870","0.00000000"]]},{"e":"depthUpdate","E":1557445972069,"s":"BNBBTC","U":264200617,"u":264200640,"b":[["0.00303340","3.39000000"],["0.00303330","9.84000000"],["0.00303320","54.57000000"],["0.00303310","11.77000000"],["0.00303300","0.00000000"],["0.00303290","74.90000000"],["0.00303280","0.00000000"],["0.00302410","0.00000000"],["0.00301810","798.17000000"],["0.00301700","0.00000000"],["0.00298750","32.74000000"],["0.00298070","3.11000000"]],"a":[["0.00303540","0.00000000"],["0.00303560","0.00000000"],["0.00303570","0.00000000"],["0.00303630","13.62000000"],["0.00303730","120.00000000"],["0.00304790","905.09000000"],["0.00304820","0.00000000"],["0.00305000","452.93000000"],["0.00305100","101.36000000"]]},{"e":"depthUpdate","E":1557445973069,"s":"BNBBTC","U":264200641,"u":264200667,"b":[["0.00303380","0.00000000"],["0.00303370","0.00000000"],["0.00303360","10.65000000"],["0.00303350","11.77000000"],["0.00303340","0.00000000"],["0.00303330","0.00000000"],["0.00303320","78.11000000"],["0.00303290","23.54000000"],["0.00293960","0.00000000"]],"a":[["0.00303620","2.58000000"],["0.00303660","1.18000000"],["0.00304360","0.00000000"],["0.00305100","1.36000000"],["0.00305200","100.00000000"],["0.00305360","12.53000000"]]},{"e":"depthUpdate","E":1557445974070,"s":"BNBBTC","U":264200668,"u":264200676,"b":[["0.00303390","0.81000000"],["0.00303380","3.72000000"],["0.00303360","9.84000000"],["0.00303350","51.36000000"],["0.00303290","11.77000000"],["0.00302930","0.00000000"]],"a":[["0.00304030","27.49000000"],["0.00304760","74.33000000"],["0.00305130","0.00000000"]]},{"e":"depthUpdate","E":1557445975070,"s":"BNBBTC","U":264200677,"u":264200690,"b":[["0.00303410","0.81000000"],["0.00303400","11.77000000"],["0.00303390","70.00000000"],["0.00303360","0.00000000"],["0.00303290","0.00000000"],["0.00303270","0.00000000"],["0.00303130","20.51000000"],["0.00301660","28.07000000"]],"a":[["0.00303630","5.60000000"],["0.00303640","8.02000000"],["0.00305550","25.16000000"],["0.00306160","2.29000000"]]},{"e":"depthUpdate","E":1557445976069,"s":"BNBBTC","U":264200691,"u":264200710,"b":[["0.00303430","0.81000000"],["0.00303420","11.77000000"],["0.00303410","3.73000000"],["0.00303400","23.54000000"],["0.00303380","0.00000000"],["0.00303310","0.00000000"],["0.00303030","20.00000000"],["0.00301010","23.25000000"],["0.00299060","4.52000000"],["0.00298590","3.48000000"]],"a":[["0.00303620","0.00000000"],["0.00303630","0.00000000"],["0.00303640","2.58000000"],["0.00303650","124.82000000"],["0.00303660","9.20000000"],["0.00304210","60.53000000"],["0.00305000","780.79000000"]]},{"e":"depthUpdate","E":1557445977070,"s":"BNBBTC","U":264200711,"u":264200721,"b":[["0.00303430","4.54000000"],["0.00303410","0.00000000"],["0.00303350","39.59000000"],["0.00303320","0.00000000"],["0.00303140","9.83000000"]],"a":[["0.00304200","22.99000000"],["0.00304580","0.00000000"],["0.00305240","25.46000000"],["0.00306390","39.94000000"]]},{"e":"depthUpdate","E":1557445978069,"s":"BNBBTC","U":264200722,"u":264200725,"b":[["0.00303350","0.00000000"],["0.00301530","2.11000000"],["0.00300610","11.73000000"]],"a":[["0.00325000","247.96000000"]]},{"e":"depthUpdate","E":1557445979069,"s":"BNBBTC","U":264200726,"u":264200741,"b":[["0.00303430","9.32000000"],["0.00303400","11.77000000"],["0.00303150","0.00000000"],["0.00303140","0.00000000"],["0.00303130","30.34000000"]],"a":[["0.00303630","38.28000000"],["0.00303640","10.37000000"],["0.00303650","119.23000000"],["0.00303660","1.18000000"]]},{"e":"depthUpdate","E":1557445980069,"s":"BNBBTC","U":264200742,"u":264200750,"b":[["0.00303440","0.00000000"],["0.00303420","0.00000000"],["0.00303400","0.00000000"],["0.00303140","1.04000000"]],"a":[["0.00303620","2.35000000"],["0.00303640","8.02000000"]]},{"e":"depthUpdate","E":1557445981069,"s":"BNBBTC","U":264200751,"u":264200770,"b":[["0.00303440","0.00000000"],["0.00303430","3.73000000"],["0.00303410","1.04000000"],["0.00303400","8.23000000"],["0.00303190","9.83000000"],["0.00303180","20.50000000"],["0.00303170","76.99000000"],["0.00303140","0.00000000"],["0.00303130","0.00000000"],["0.00302480","0.00000000"],["0.00300030","50.00000000"],["0.00299270","3.34000000"],["0.00298070","36.32000000"],["0.00297150","2.16000000"]],"a":[["0.00303910","34.85000000"],["0.00304030","7.49000000"]]},{"e":"depthUpdate","E":1557445982069,"s":"BNBBTC","U":264200771,"u":264200774,"b":[["0.00303410","0.00000000"],["0.00303200","1.04000000"],["0.00303100","0.00000000"],["0.00300820","0.00000000"]],"a":[]},{"e":"depthUpdate","E":1557445983069,"s":"BNBBTC","U":264200775,"u":264200777,"b":[["0.00303130","109.37000000"],["0.00303030","0.00000000"],["0.00302870","20.00000000"]],"a":[]},{"e":"depthUpdate","E":1557445984069,"s":"BNBBTC","U":264200778,"u":264200798,"b":[["0.00303450","9.27000000"],["0.00303440","79.18000000"],["0.00303410","0.00000000"],["0.00303400","0.00000000"],["0.00303230","9.83000000"],["0.00303220","20.50000000"],["0.00303210","121.16000000"],["0.00303200","0.00000000"],["0.00303190","0.00000000"],["0.00303180","0.00000000"],["0.00303110","0.00000000"],["0.00302870","0.00000000"],["0.00302720","82.71000000"],["0.00302510","0.00000000"]],"a":[["0.00303630","9.43000000"],["0.00303640","0.00000000"],["0.00303720","9.02000000"]]},{"e":"depthUpdate","E":1557445985069,"s":"BNBBTC","U":264200799,"u":264200815,"b":[["0.00303440","90.95000000"],["0.00303290","20.50000000"],["0.00303280","20.00000000"],["0.00303220","0.00000000"],["0.00302410","797.43000000"],["0.00301810","0.00000000"],["0.00301800","0.00000000"],["0.00300960","1.97000000"],["0.00299980","2.12000000"]],"a":[["0.00303620","0.00000000"],["0.00303630","2.35000000"],["0.00303640","8.23000000"],["0.00303910","14.85000000"],["0.00304080","21.36000000"],["0.00304110","78.66000000"],["0.00304350","0.00000000"]]},{"e":"depthUpdate","E":1557445986069,"s":"BNBBTC","U":264200816,"u":264200833,"b":[["0.00303480","0.00000000"],["0.00303470","8.23000000"],["0.00303460","11.77000000"],["0.00303450","3.39000000"],["0.00303120","0.00000000"],["0.00302730","65.12000000"],["0.00302000","332.00000000"],["0.00300330","6.69000000"],["0.00300020","0.00000000"],["0.00299570","6.34000000"]],"a":[["0.00303620","5.00000000"],["0.00303630","0.00000000"],["0.00303640","1.20000000"],["0.00303650","91.69000000"]]},{"e":"depthUpdate","E":1557445987069,"s":"BNBBTC","U":264200834,"u":264200841,"b":[["0.00302500","392.13000000"],["0.00302000","2.00000000"],["0.00300190","183.21000000"],["0.00300020","3.33000000"],["0.00299720","11.15000000"],["0.00299270","0.00000000"],["0.00298970","0.34000000"]],"a":[["0.00303620","55.00000000"]]},{"e":"depthUpdate","E":1557445988069,"s":"BNBBTC","U":264200842,"u":264200847,"b":[["0.00303440","11.77000000"],["0.00298470","0.00000000"]],"a":[["0.00303640","9.22000000"],["0.00303720","1.00000000"]]},{"e":"depthUpdate","E":1557445989069,"s":"BNBBTC","U":264200848,"u":264200861,"b":[["0.00303480","55.64000000"],["0.00303450","0.00000000"],["0.00303440","3.39000000"],["0.00303230","0.00000000"],["0.00303130","0.00000000"],["0.00302740","85.11000000"],["0.00302500","62.13000000"],["0.00302430","0.00000000"],["0.00299520","2.13000000"]],"a":[["0.00303640","1.20000000"],["0.00303790","8.02000000"],["0.00305200","0.00000000"]]},{"e":"depthUpdate","E":1557445990070,"s":"BNBBTC","U":264200862,"u":264200875,"b":[["0.00303480","126.26000000"],["0.00303460","0.00000000"],["0.00302750","105.03000000"],["0.00302710","0.00000000"],["0.00302600","0.00000000"]],"a":[["0.00304710","0.00000000"],["0.00305240","0.00000000"],["0.00305550","0.00000000"]]},{"e":"depthUpdate","E":1557445991069,"s":"BNBBTC","U":264200876,"u":264200889,"b":[["0.00303290","0.00000000"],["0.00303280","0.00000000"],["0.00303230","9.83000000"],["0.00303220","20.50000000"],["0.00303140","20.00000000"],["0.00303110","11.09000000"],["0.00302740","75.28000000"],["0.00302410","0.00000000"],["0.00301660","0.00000000"],["0.00301420","798.17000000"],["0.00300490","50.65000000"],["0.00300030","0.00000000"]],"a":[["0.00305370","27.73000000"],["0.00305690","25.16000000"]]},{"e":"depthUpdate","E":1557445992069,"s":"BNBBTC","U":264200890,"u":264200891,"b":[],"a":[["0.00304080","1.36000000"],["0.00305280","25.45000000"]]},{"e":"depthUpdate","E":1557445993069,"s":"BNBBTC","U":264200892,"u":264200893,"b":[["0.00300020","9.92000000"],["0.00298790","0.00000000"]],"a":[]},{"e":"depthUpdate","E":1557445994069,"s":"BNBBTC","U":264200894,"u":264200899,"b":[["0.00303480","90.51000000"],["0.00299250","2.15000000"]],"a":[["0.00303980","20.00000000"]]},{"e":"depthUpdate","E":1557445995069,"s":"BNBBTC","U":264200900,"u":264200900,"b":[["0.00299680","10.91000000"]],"a":[]},{"e":"depthUpdate","E":1557445996069,"s":"BNBBTC","U":264200901,"u":264200911,"b":[["0.00303500","100.81000000"],["0.00303480","0.00000000"],["0.00303230","0.00000000"],["0.00302770","9.83000000"],["0.00302760","64.98000000"],["0.00302500","0.00000000"],["0.00299090","0.00000000"]],"a":[["0.00308000","0.46000000"]]},{"e":"depthUpdate","E":1557445997069,"s":"BNBBTC","U":264200912,"u":264200926,"b":[["0.00303510","89.88000000"],["0.00303250","20.49000000"],["0.00303240","20.00000000"],["0.00303220","0.00000000"],["0.00303140","0.00000000"],["0.00300090","0.00000000"],["0.00299420","11.61000000"]],"a":[["0.00303790","0.00000000"],["0.00303970","8.02000000"],["0.00304100","119.35000000"],["0.00304800","17.47000000"],["0.00308150","0.61000000"]]},{"e":"depthUpdate","E":1557445998069,"s":"BNBBTC","U":264200927,"u":264200939,"b":[["0.00303510","159.88000000"],["0.00303440","0.00000000"],["0.00303390","0.00000000"],["0.00303260","9.83000000"],["0.00303250","23.88000000"],["0.00302780","0.00000000"],["0.00302770","0.00000000"],["0.00301020","3.33000000"],["0.00300190","0.00000000"],["0.00300020","193.24000000"]],"a":[["0.00304200","0.00000000"],["0.00304710","22.99000000"]]},{"e":"depthUpdate","E":1557445999069,"s":"BNBBTC","U":264200940,"u":264200940,"b":[["0.00303510","159.09000000"]],"a":[]},{"e":"depthUpdate","E":1557446000069,"s":"BNBBTC","U":264200941,"u":264200942,"b":[["0.00212060","0.00000000"]],"a":[]},{"e":"depthUpdate","E":1557446001069,"s":"BNBBTC","U":264200943,"u":264200945,"b":[["0.00303510","131.17000000"]],"a":[]},{"e":"depthUpdate","E":1557446002069,"s":"BNBBTC","U":264200946,"u":264200949,"b":[["0.00303510","70.00000000"],["0.00300560","1.16000000"],["0.00299620","0.00000000"]],"a":[]},{"e":"depthUpdate","E":1557446004070,"s":"BNBBTC","U":264200950,"u":264200966,"b":[["0.00303510","0.00000000"],["0.00303500","0.00000000"],["0.00303270","3.39000000"],["0.00303260","52.70000000"],["0.00303250","0.00000000"],["0.00302770","82.70000000"],["0.00302720","0.00000000"],["0.00297990","3.82000000"],["0.00297200","14.67000000"]],"a":[["0.00303500","368.06000000"],["0.00303610","8.02000000"],["0.00303620","125.00000000"],["0.00303970","0.00000000"],["0.00304720","0.00000000"],["0.00305280","0.00000000"]]},{"e":"depthUpdate","E":1557446005071,"s":"BNBBTC","U":264200967,"u":264201008,"b":[["0.00303470","0.00000000"],["0.00303430","0.00000000"],["0.00303270","8.23000000"],["0.00303260","0.00000000"],["0.00303240","0.00000000"],["0.00303220","0.00000000"],["0.00303210","0.00000000"],["0.00303170","0.00000000"],["0.00302980","0.00000000"],["0.00302970","0.00000000"],["0.00302800","38.21000000"],["0.00302790","82.75000000"],["0.00302780","200.97000000"],["0.00302770","52.70000000"],["0.00302760","64.98000000"],["0.00302750","23.01000000"],["0.00301020","1.36000000"]],"a":[["0.00303490","11.80000000"],["0.00303500","438.06000000"],["0.00303610","0.00000000"],["0.00303620","55.00000000"],["0.00303640","0.00000000"],["0.00304000","151.37000000"],["0.00305470","28.75000000"]]},{"e":"depthUpdate","E":1557446006072,"s":"BNBBTC","U":264201009,"u":264201034,"b":[["0.00303270","0.00000000"],["0.00303170","8.23000000"],["0.00302820","38.22000000"],["0.00302810","82.78000000"],["0.00302800","139.83000000"],["0.00302790","0.00000000"],["0.00302740","0.00000000"],["0.00302730","0.00000000"]],"a":[["0.00303470","11.80000000"],["0.00303480","27.82000000"],["0.00303490","156.51000000"],["0.00304210","0.00000000"],["0.00304370","13.18000000"],["0.00304810","0.00000000"],["0.00305370","0.00000000"]]},{"e":"depthUpdate","E":1557446007071,"s":"BNBBTC","U":264201035,"u":264201048,"b":[["0.00302460","81.80000000"],["0.00302030","28.03000000"]],"a":[["0.00303450","11.80000000"],["0.00303460","30.30000000"],["0.00303470","0.00000000"],["0.00303490","126.91000000"],["0.00303610","81.43000000"],["0.00303980","0.00000000"],["0.00304110","0.00000000"],["0.00304670","13.18000000"],["0.00304940","27.77000000"],["0.00305340","0.00000000"]]},{"e":"depthUpdate","E":1557446008072,"s":"BNBBTC","U":264201049,"u":264201057,"b":[["0.00302690","20.00000000"]],"a":[["0.00303430","11.80000000"],["0.00303440","27.91000000"],["0.00303450","0.00000000"],["0.00303460","0.00000000"],["0.00303720","21.00000000"],["0.00305290","1.77000000"]]},{"e":"depthUpdate","E":1557446009071,"s":"BNBBTC","U":264201058,"u":264201060,"b":[],"a":[["0.00303470","80.64000000"],["0.00304220","0.00000000"],["0.00304940","0.00000000"]]},{"e":"depthUpdate","E":1557446010071,"s":"BNBBTC","U":264201061,"u":264201065,"b":[["0.00303170","4.83000000"],["0.00303110","11.62000000"]],"a":[["0.00303480","0.00000000"],["0.00304840","27.77000000"],["0.00306390","0.00000000"]]},{"e":"depthUpdate","E":1557446011071,"s":"BNBBTC","U":264201066,"u":264201077,"b":[["0.00303000","1.00000000"],["0.00302790","23.01000000"],["0.00302750","0.00000000"],["0.00300490","0.65000000"],["0.00300030","50.00000000"]],"a":[["0.00303460","130.89000000"],["0.00303610","101.43000000"],["0.00303720","1.00000000"],["0.00303790","905.53000000"],["0.00304100","0.00000000"],["0.00304790","0.00000000"],["0.00306220","41.59000000"]]},{"e":"depthUpdate","E":1557446012071,"s":"BNBBTC","U":264201078,"u":264201083,"b":[["0.00303170","0.00000000"],["0.00303120","8.23000000"],["0.00303010","0.00000000"]],"a":[["0.00303650","110.17000000"],["0.00306220","0.00000000"]]},{"e":"depthUpdate","E":1557446013071,"s":"BNBBTC","U":264201084,"u":264201088,"b":[],"a":[["0.00303430","88.38000000"],["0.00303500","70.00000000"],["0.00304760","0.00000000"],["0.00304960","0.00000000"],["0.00306230","45.28000000"]]},{"e":"depthUpdate","E":1557446014071,"s":"BNBBTC","U":264201089,"u":264201095,"b":[["0.00303110","11.09000000"]],"a":[["0.00303410","11.80000000"],["0.00303420","61.51000000"],["0.00303430","76.58000000"],["0.00303490","63.39000000"]]},{"e":"depthUpdate","E":1557446015071,"s":"BNBBTC","U":264201096,"u":264201099,"b":[["0.00301360","2.14000000"],["0.00300680","0.00000000"]],"a":[["0.00303410","42.32000000"],["0.00303440","0.00000000"]]},{"e":"depthUpdate","E":1557446016071,"s":"BNBBTC","U":264201100,"u":264201118,"b":[["0.00302840","38.22000000"],["0.00302830","82.78000000"],["0.00302820","124.88000000"],["0.00302810","0.00000000"],["0.00302780","78.37000000"],["0.00294100","16.99000000"],["0.00293920","0.00000000"]],"a":[["0.00303390","11.80000000"],["0.00303400","27.82000000"],["0.00303410","30.52000000"],["0.00303500","90.00000000"],["0.00303610","81.43000000"]]},{"e":"depthUpdate","E":1557446017071,"s":"BNBBTC","U":264201119,"u":264201148,"b":[["0.00303160","0.00000000"],["0.00303130","0.00000000"],["0.00303120","0.00000000"],["0.00303110","0.00000000"],["0.00303000","0.00000000"],["0.00302840","0.00000000"],["0.00302830","0.00000000"],["0.00302820","0.00000000"],["0.00302810","5.00000000"],["0.00302800","0.00000000"],["0.00302770","0.00000000"],["0.00302460","134.50000000"]],"a":[["0.00302800","0.00000000"],["0.00303360","11.77000000"],["0.00303370","3.57000000"],["0.00303380","30.00000000"],["0.00303390","70.00000000"],["0.00303410","0.00000000"],["0.00303500","20.00000000"],["0.00304750","157.11000000"]]},{"e":"depthUpdate","E":1557446018071,"s":"BNBBTC","U":264201149,"u":264201221,"b":[["0.00302830","9.85000000"],["0.00302820","39.59000000"],["0.00302780","0.00000000"],["0.00302470","82.88000000"],["0.00302030","0.00000000"],["0.00301720","140.98000000"],["0.00301240","122.28000000"]],"a":[["0.00303230","3.40000000"],["0.00303240","7.88000000"],["0.00303250","0.00000000"],["0.00303260","0.00000000"],["0.00303270","0.00000000"],["0.00303280","0.00000000"],["0.00303290","0.00000000"],["0.00303300","28.55000000"],["0.00303310","287.83000000"],["0.00303320","0.00000000"],["0.00303330","0.00000000"],["0.00303340","0.00000000"],["0.00303350","27.91000000"],["0.00303370","0.00000000"],["0.00303380","0.00000000"],["0.00303500","0.00000000"],["0.00303630","20.00000000"]]},{"e":"depthUpdate","E":1557446019071,"s":"BNBBTC","U":264201222,"u":264201238,"b":[["0.00302790","0.00000000"],["0.00302690","72.70000000"],["0.00302490","82.87000000"],["0.00302480","99.77000000"],["0.00302470","0.00000000"],["0.00302460","81.80000000"]],"a":[["0.00303210","3.40000000"],["0.00303220","36.43000000"],["0.00303230","70.00000000"],["0.00303240","0.00000000"],["0.00303300","0.00000000"],["0.00303390","0.00000000"],["0.00303600","22.99000000"],["0.00304710","0.00000000"]]},{"e":"depthUpdate","E":1557446020071,"s":"BNBBTC","U":264201239,"u":264201242,"b":[["0.00300040","183.30000000"],["0.00300020","9.92000000"],["0.00299180","0.00000000"]],"a":[["0.00303400","0.00000000"]]},{"e":"depthUpdate","E":1557446021071,"s":"BNBBTC","U":264201243,"u":264201256,"b":[["0.00303190","0.00000000"],["0.00302850","0.00000000"],["0.00302840","3.29000000"],["0.00302510","82.87000000"],["0.00302500","68.53000000"],["0.00302490","0.00000000"],["0.00301300","28.09000000"],["0.00299850","68.71000000"]],"a":[["0.00303210","0.11000000"]]},{"e":"depthUpdate","E":1557446022071,"s":"BNBBTC","U":264201257,"u":264201291,"b":[["0.00302860","0.00000000"],["0.00302850","0.00000000"],["0.00302840","34.16000000"],["0.00302830","0.00000000"],["0.00302820","0.00000000"],["0.00302690","20.00000000"],["0.00302510","0.00000000"],["0.00302500","0.00000000"],["0.00302490","82.87000000"],["0.00301300","0.00000000"]],"a":[["0.00303190","3.40000000"],["0.00303200","7.88000000"],["0.00303210","0.00000000"],["0.00303220","38.40000000"],["0.00303310","252.52000000"],["0.00303350","0.00000000"],["0.00303360","0.00000000"],["0.00303470","0.00000000"],["0.00304090","13.19000000"],["0.00307170","1.96000000"]]},{"e":"depthUpdate","E":1557446023071,"s":"BNBBTC","U":264201292,"u":264201337,"b":[["0.00302840","0.00000000"],["0.00302690","54.16000000"],["0.00302490","82.88000000"],["0.00302470","0.00000000"]],"a":[["0.00303170","3.40000000"],["0.00303180","36.43000000"],["0.00303190","0.00000000"],["0.00303200","0.00000000"],["0.00303210","0.00000000"],["0.00303220","9.85000000"],["0.00303310","0.00000000"],["0.00303620","130.17000000"],["0.00306860","1.78000000"],["0.00309020","0.00000000"]]},{"e":"depthUpdate","E":1557446024071,"s":"BNBBTC","U":264201338,"u":264201356,"b":[["0.00302810","0.00000000"],["0.00302460","404.64000000"]],"a":[["0.00303170","11.64000000"],["0.00303180","28.55000000"],["0.00303220","9.85000000"],["0.00303410","79.52000000"],["0.00303470","20.00000000"],["0.00303610","0.00000000"],["0.00303630","0.00000000"],["0.00308700","1.79000000"]]},{"e":"depthUpdate","E":1557446025071,"s":"BNBBTC","U":264201357,"u":264201374,"b":[["0.00302760","0.00000000"],["0.00302710","98.95000000"],["0.00302700","0.00000000"]],"a":[["0.00303160","3.40000000"],["0.00303170","36.79000000"],["0.00303180","0.00000000"],["0.00303220","9.85000000"],["0.00304050","13.19000000"]]},{"e":"depthUpdate","E":1557446026072,"s":"BNBBTC","U":264201375,"u":264201424,"b":[["0.00302770","17.14000000"],["0.00302760","2832.75000000"],["0.00302750","0.00000000"],["0.00302740","0.00000000"],["0.00302730","35.31000000"],["0.00302720","0.00000000"],["0.00302710","39.59000000"],["0.00302470","240.02000000"],["0.00302460","81.80000000"],["0.00301430","89.20000000"]],"a":[["0.00303120","0.00000000"],["0.00303130","0.00000000"],["0.00303140","0.00000000"],["0.00303150","0.00000000"],["0.00303160","4.36000000"],["0.00303170","0.00000000"],["0.00303220","0.00000000"],["0.00303400","28.55000000"]]},{"e":"depthUpdate","E":1557446027073,"s":"BNBBTC","U":264201425,"u":264201463,"b":[["0.00302800","3.40000000"],["0.00302790","13.73000000"],["0.00302780","38.82000000"],["0.00302770","4.36000000"],["0.00302490","82.88000000"],["0.00302470","0.00000000"]],"a":[["0.00303150","32.91000000"],["0.00303160","70.00000000"],["0.00303210","0.00000000"],["0.00303220","192.35000000"],["0.00303230","0.00000000"],["0.00303390","0.00000000"],["0.00303400","0.00000000"],["0.00303420","0.00000000"],["0.00303460","0.00000000"]]},{"e":"depthUpdate","E":1557446028074,"s":"BNBBTC","U":264201464,"u":264201501,"b":[["0.00302890","0.00000000"],["0.00302880","5.49000000"],["0.00302870","16.48000000"],["0.00302860","0.00000000"],["0.00302850","0.00000000"],["0.00302840","0.00000000"],["0.00302830","0.00000000"],["0.00302820","3.40000000"],["0.00302810","3.84000000"],["0.00302800","34.16000000"],["0.00302790","0.00000000"],["0.00302690","20.00000000"]],"a":[]},{"e":"depthUpdate","E":1557446029073,"s":"BNBBTC","U":264201502,"u":264201516,"b":[["0.00302880","0.00000000"],["0.00302870","0.00000000"],["0.00302840","5.79000000"],["0.00302830","8.24000000"],["0.00302820","0.00000000"],["0.00302810","3.84000000"],["0.00302710","0.00000000"],["0.00301030","16.07000000"]],"a":[["0.00303150","36.01000000"],["0.00303220","127.95000000"]]},{"e":"depthUpdate","E":1557446030073,"s":"BNBBTC","U":264201517,"u":264201527,"b":[["0.00302870","5.79000000"],["0.00302860","8.24000000"],["0.00302850","51.36000000"],["0.00302840","0.00000000"],["0.00302830","0.00000000"],["0.00302730","23.54000000"],["0.00300740","0.00000000"]],"a":[["0.00303400","64.50000000"]]},{"e":"depthUpdate","E":1557446031073,"s":"BNBBTC","U":264201528,"u":264201547,"b":[["0.00302890","14.03000000"],["0.00302880","47.08000000"],["0.00302870","0.00000000"],["0.00302860","0.00000000"],["0.00302780","0.00000000"],["0.00302770","0.00000000"],["0.00302730","0.00000000"],["0.00300490","50.65000000"],["0.00300040","0.00000000"],["0.00300030","0.00000000"],["0.00299430","183.68000000"]],"a":[]},{"e":"depthUpdate","E":1557446032073,"s":"BNBBTC","U":264201548,"u":264201560,"b":[["0.00302920","1.54000000"],["0.00302890","14.03000000"],["0.00297950","81.16000000"]],"a":[["0.00303150","0.00000000"],["0.00303160","0.00000000"],["0.00303210","34.47000000"],["0.00303390","0.00000000"],["0.00303400","134.50000000"]]},{"e":"depthUpdate","E":1557446033074,"s":"BNBBTC","U":264201561,"u":264201580,"b":[["0.00302940","5.79000000"],["0.00302930","9.80000000"],["0.00302920","35.70000000"],["0.00302890","0.00000000"],["0.00302800","0.00000000"],["0.00301730","798.17000000"],["0.00301420","0.00000000"],["0.00298280","1.00000000"]],"a":[["0.00303210","0.00000000"],["0.00303220","0.00000000"],["0.00303390","34.47000000"],["0.00303790","0.00000000"],["0.00304740","905.29000000"],["0.00304750","0.00000000"]]},{"e":"depthUpdate","E":1557446034075,"s":"BNBBTC","U":264201581,"u":264201595,"b":[["0.00302850","0.00000000"]],"a":[["0.00303370","34.47000000"],["0.00303380","28.71000000"],["0.00303390","0.00000000"],["0.00303410","0.00000000"],["0.00303470","0.00000000"],["0.00303610","119.16000000"],["0.00303640","20.00000000"],["0.00304050","0.00000000"],["0.00304090","0.00000000"],["0.00336150","0.00000000"],["0.00349680","20.00000000"]]},{"e":"depthUpdate","E":1557446035076,"s":"BNBBTC","U":264201596,"u":264201617,"b":[["0.00302980","3.40000000"],["0.00302970","2.00000000"],["0.00302960","8.24000000"],["0.00302950","11.77000000"],["0.00302940","0.00000000"],["0.00302930","0.00000000"],["0.00302890","0.00000000"],["0.00302880","23.54000000"],["0.00302780","1.55000000"],["0.00302770","82.83000000"],["0.00302490","0.00000000"]],"a":[["0.00303370","34.86000000"],["0.00303990","76.87000000"],["0.00350330","0.00000000"]]},{"e":"depthUpdate","E":1557446036076,"s":"BNBBTC","U":264201618,"u":264201622,"b":[["0.00302880","0.00000000"],["0.00299410","0.66000000"],["0.00299060","3.86000000"]],"a":[["0.00355210","1.50000000"]]},{"e":"depthUpdate","E":1557446038076,"s":"BNBBTC","U":264201623,"u":264201633,"b":[["0.00303010","5.40000000"],["0.00303000","8.24000000"],["0.00302990","39.59000000"],["0.00302980","0.00000000"],["0.00302970","0.00000000"],["0.00302960","0.00000000"],["0.00298590","2.18000000"]],"a":[["0.00304370","0.00000000"],["0.00304670","156.64000000"]]},{"e":"depthUpdate","E":1557446039076,"s":"BNBBTC","U":264201634,"u":264201669,"b":[["0.00303070","3.40000000"],["0.00303060","2.00000000"],["0.00303050","8.24000000"],["0.00303040","11.77000000"],["0.00303030","4.00000000"],["0.00303010","0.00000000"],["0.00303000","0.00000000"],["0.00302950","0.00000000"],["0.00302920","34.16000000"],["0.00302840","3.91000000"],["0.00302830","82.81000000"],["0.00302820","606.31000000"],["0.00302800","0.00000000"],["0.00302790","0.00000000"],["0.00302780","211.08000000"],["0.00302770","0.00000000"],["0.00302480","23.01000000"],["0.00301240","0.00000000"]],"a":[["0.00303370","0.00000000"],["0.00303380","0.00000000"],["0.00303390","32.50000000"],["0.00303400","64.50000000"],["0.00303610","189.16000000"],["0.00303990","982.16000000"],["0.00304740","0.00000000"],["0.00306990","0.00000000"]]},{"e":"depthUpdate","E":1557446040077,"s":"BNBBTC","U":264201670,"u":264201722,"b":[["0.00303120","0.00000000"],["0.00303110","0.00000000"],["0.00303100","0.00000000"],["0.00303090","8.24000000"],["0.00303080","7.03000000"],["0.00303070","4.39000000"],["0.00303060","0.00000000"],["0.00303050","0.00000000"],["0.00303030","0.00000000"],["0.00303010","2.34000000"],["0.00303000","3.89000000"],["0.00302920","0.00000000"],["0.00302850","0.00000000"],["0.00302840","0.00000000"],["0.00302830","0.00000000"]],"a":[["0.00303340","9.30000000"],["0.00303350","0.00000000"],["0.00303360","0.00000000"],["0.00303370","0.00000000"],["0.00303380","9.84000000"],["0.00303390","94.65000000"],["0.00303400","92.56000000"],["0.00303610","119.16000000"],["0.00304270","13.18000000"],["0.00308700","0.00000000"],["0.00308860","1.80000000"]]},{"e":"depthUpdate","E":1557446041077,"s":"BNBBTC","U":264201723,"u":264201756,"b":[["0.00303120","0.00000000"],["0.00303110","8.24000000"],["0.00303100","7.03000000"],["0.00303090","0.00000000"],["0.00303080","0.00000000"],["0.00303010","2.34000000"],["0.00303000","3.89000000"],["0.00302690","0.00000000"],["0.00302590","20.00000000"],["0.00300490","0.65000000"],["0.00299440","50.96000000"]],"a":[["0.00303310","0.00000000"],["0.00303320","8.24000000"],["0.00303330","0.00000000"],["0.00303340","0.00000000"],["0.00303370","1.06000000"],["0.00303380","9.84000000"],["0.00304540","13.18000000"],["0.00351960","0.38000000"]]},{"e":"depthUpdate","E":1557446042077,"s":"BNBBTC","U":264201757,"u":264201793,"b":[["0.00303130","8.24000000"],["0.00303120","7.02000000"],["0.00303110","0.00000000"],["0.00303100","0.00000000"],["0.00303050","2.34000000"],["0.00303010","0.00000000"],["0.00303000","0.00000000"],["0.00302990","0.00000000"],["0.00302830","3.89000000"],["0.00302600","23.01000000"],["0.00302480","0.00000000"],["0.00299670","185.67000000"],["0.00299430","0.00000000"]],"a":[["0.00303310","1.06000000"],["0.00303320","16.48000000"],["0.00303330","0.00000000"],["0.00303340","0.00000000"],["0.00303350","0.00000000"],["0.00303360","0.00000000"],["0.00303370","0.00000000"],["0.00303380","34.49000000"],["0.00303390","70.00000000"],["0.00334640","0.38000000"],["0.00346180","300.97000000"]]},{"e":"depthUpdate","E":1557446043077,"s":"BNBBTC","U":264201794,"u":264201802,"b":[["0.00303140","6.02000000"],["0.00303120","0.00000000"],["0.00303050","0.00000000"],["0.00303040","0.00000000"],["0.00302840","2.34000000"],["0.00300330","0.00000000"],["0.00300020","6.59000000"],["0.00299720","1.10000000"]],"a":[]},{"e":"depthUpdate","E":1557446044078,"s":"BNBBTC","U":264201803,"u":264201818,"b":[["0.00302780","79.75000000"],["0.00300050","6.70000000"],["0.00299750","3.34000000"],["0.00299440","61.02000000"]],"a":[["0.00303310","0.00000000"],["0.00303320","0.00000000"],["0.00303340","1.06000000"],["0.00303350","8.24000000"],["0.00303360","0.00000000"],["0.00303370","9.84000000"],["0.00303380","24.65000000"]]},{"e":"depthUpdate","E":1557446045079,"s":"BNBBTC","U":264201819,"u":264201828,"b":[["0.00303130","0.00000000"],["0.00303080","8.24000000"],["0.00302830","86.34000000"],["0.00302460","0.00000000"],["0.00302180","125.79000000"]],"a":[["0.00303350","42.73000000"],["0.00303360","50.00000000"],["0.00303370","0.00000000"],["0.00303380","0.00000000"]]},{"e":"depthUpdate","E":1557446046079,"s":"BNBBTC","U":264201829,"u":264201838,"b":[["0.00303140","0.00000000"],["0.00303100","2.34000000"],["0.00303090","6.29000000"],["0.00302840","0.00000000"],["0.00299680","61.00000000"],["0.00299440","10.93000000"],["0.00250000","8879.97000000"]],"a":[["0.00303490","88.39000000"],["0.00304670","0.00000000"],["0.00313680","0.00000000"]]},{"e":"depthUpdate","E":1557446047079,"s":"BNBBTC","U":264201839,"u":264201847,"b":[["0.00303110","0.00000000"],["0.00303100","0.00000000"],["0.00303090","0.00000000"],["0.00303080","0.00000000"],["0.00303070","0.00000000"],["0.00302840","10.58000000"],["0.00302190","797.56000000"],["0.00301730","0.00000000"]],"a":[]},{"e":"depthUpdate","E":1557446048079,"s":"BNBBTC","U":264201848,"u":264201899,"b":[["0.00302910","2.34000000"],["0.00302900","20.39000000"],["0.00302890","39.59000000"],["0.00302880","0.00000000"],["0.00302870","4.20000000"],["0.00302840","0.00000000"],["0.00302830","82.45000000"],["0.00302780","0.00000000"]],"a":[["0.00303260","1.06000000"],["0.00303270","18.08000000"],["0.00303280","0.00000000"],["0.00303290","0.00000000"],["0.00303300","0.00000000"],["0.00303310","0.00000000"],["0.00303320","0.00000000"],["0.00303330","24.65000000"],["0.00303340","77.68000000"],["0.00303350","95.30000000"],["0.00303400","0.00000000"],["0.00303430","0.00000000"],["0.00303480","22.99000000"],["0.00303600","0.00000000"]]},{"e":"depthUpdate","E":1557446049079,"s":"BNBBTC","U":264201900,"u":264201917,"b":[["0.00302940","2.34000000"],["0.00302930","4.20000000"],["0.00302910","0.00000000"],["0.00302870","0.00000000"],["0.00302410","79.01000000"],["0.00299170","1.66000000"],["0.00298650","0.00000000"]],"a":[["0.00303260","8.24000000"],["0.00303270","0.00000000"],["0.00303310","1.06000000"],["0.00303320","0.00000000"],["0.00303600","294.94000000"],["0.00304140","13.19000000"],["0.00304590","169.41000000"],["0.00307280","13.60000000"]]},{"e":"depthUpdate","E":1557446050079,"s":"BNBBTC","U":264201918,"u":264201967,"b":[["0.00302970","0.00000000"],["0.00302960","4.20000000"],["0.00302940","0.00000000"],["0.00302930","0.00000000"],["0.00302910","2.34000000"],["0.00302900","16.48000000"],["0.00294970","175.61000000"],["0.00294030","0.45000000"]],"a":[["0.00303200","8.24000000"],["0.00303210","0.00000000"],["0.00303220","0.00000000"],["0.00303230","0.00000000"],["0.00303240","34.49000000"],["0.00303250","29.03000000"],["0.00303260","70.00000000"],["0.00303310","0.00000000"],["0.00303320","0.00000000"],["0.00303330","125.04000000"],["0.00303350","65.98000000"],["0.00303390","0.00000000"],["0.00303430","20.00000000"],["0.00303610","0.00000000"],["0.00303640","0.00000000"],["0.00306890","0.00000000"]]},{"e":"depthUpdate","E":1557446051080,"s":"BNBBTC","U":264201968,"u":264201994,"b":[["0.00302960","0.00000000"],["0.00302930","2.34000000"],["0.00302920","4.92000000"],["0.00302910","0.00000000"]],"a":[["0.00303150","1.06000000"],["0.00303160","8.24000000"],["0.00303170","0.00000000"],["0.00303180","9.84000000"],["0.00303190","28.99000000"],["0.00303200","0.00000000"],["0.00303240","0.00000000"],["0.00303250","24.65000000"]]},{"e":"depthUpdate","E":1557446052081,"s":"BNBBTC","U":264201995,"u":264202024,"b":[["0.00302950","3.40000000"],["0.00302940","4.92000000"],["0.00302930","0.00000000"],["0.00302920","0.00000000"],["0.00302890","0.00000000"],["0.00302830","0.00000000"],["0.00302460","82.81000000"]],"a":[["0.00303130","0.00000000"],["0.00303140","5.82000000"],["0.00303150","70.00000000"],["0.00303160","28.04000000"],["0.00303180","0.00000000"],["0.00303190","0.00000000"],["0.00303250","0.00000000"],["0.00303260","0.00000000"],["0.00303320","24.65000000"],["0.00303490","383.33000000"],["0.00311870","0.00000000"],["0.00313720","0.37000000"]]},{"e":"depthUpdate","E":1557446053080,"s":"BNBBTC","U":264202025,"u":264202041,"b":[["0.00302960","3.80000000"],["0.00302950","0.00000000"],["0.00302940","0.00000000"],["0.00302910","0.00000000"],["0.00302900","0.00000000"],["0.00302830","8.24000000"],["0.00302480","82.81000000"],["0.00302470","75.80000000"],["0.00302460","0.00000000"],["0.00302190","0.00000000"],["0.00301730","798.14000000"],["0.00299690","184.52000000"],["0.00299670","2.14000000"]],"a":[["0.00312000","119.42000000"],["0.00314120","0.00000000"]]},{"e":"depthUpdate","E":1557446054080,"s":"BNBBTC","U":264202042,"u":264202075,"b":[["0.00302960","0.00000000"],["0.00302900","3.40000000"],["0.00302890","8.24000000"],["0.00302880","23.54000000"],["0.00302870","0.00000000"],["0.00302860","0.00000000"],["0.00302850","3.80000000"],["0.00302840","0.00000000"],["0.00302830","0.00000000"],["0.00302770","4.36000000"],["0.00302100","10.00000000"]],"a":[["0.00303130","0.00000000"],["0.00303140","24.65000000"],["0.00303150","70.00000000"],["0.00303320","0.00000000"]]},{"e":"depthUpdate","E":1557446055080,"s":"BNBBTC","U":264202076,"u":264202083,"b":[["0.00302920","3.40000000"],["0.00302910","4.20000000"],["0.00302900","0.00000000"],["0.00302850","0.00000000"],["0.00299680","52.22000000"]],"a":[["0.00303330","145.04000000"],["0.00303430","0.00000000"],["0.00308860","0.00000000"]]},{"e":"depthUpdate","E":1557446056080,"s":"BNBBTC","U":264202084,"u":264202092,"b":[["0.00302930","4.20000000"],["0.00302920","0.00000000"],["0.00302910","0.00000000"],["0.00302900","3.40000000"],["0.00301610","28.07000000"],["0.00299120","9.28000000"]],"a":[["0.00303150","75.00000000"],["0.00308000","0.00000000"],["0.00308620","1.79000000"]]},{"e":"depthUpdate","E":1557446057080,"s":"BNBBTC","U":264202093,"u":264202094,"b":[["0.00299420","0.00000000"]],"a":[["0.00308150","0.00000000"]]},{"e":"depthUpdate","E":1557446058080,"s":"BNBBTC","U":264202095,"u":264202100,"b":[["0.00302880","0.00000000"],["0.00302770","0.00000000"],["0.00298720","12.86000000"]],"a":[["0.00303140","22.65000000"],["0.00304520","0.65000000"]]},{"e":"depthUpdate","E":1557446059080,"s":"BNBBTC","U":264202101,"u":264202112,"b":[["0.00302950","8.24000000"],["0.00302940","11.77000000"],["0.00302900","0.00000000"],["0.00302890","0.00000000"],["0.00302840","3.40000000"],["0.00302830","9.84000000"],["0.00301900","332.00000000"]],"a":[["0.00303160","0.00000000"],["0.00303490","88.39000000"],["0.00304500","128.19000000"]]},{"e":"depthUpdate","E":1557446060080,"s":"BNBBTC","U":264202113,"u":264202120,"b":[["0.00302980","3.40000000"],["0.00302970","23.54000000"],["0.00302960","12.83000000"],["0.00302930","0.00000000"],["0.00302840","0.00000000"]],"a":[["0.00303140","0.00000000"],["0.00303320","22.65000000"]]},{"e":"depthUpdate","E":1557446061080,"s":"BNBBTC","U":264202121,"u":264202122,"b":[["0.00302990","12.83000000"],["0.00302960","0.00000000"]],"a":[]},{"e":"depthUpdate","E":1557446062080,"s":"BNBBTC","U":264202123,"u":264202124,"b":[],"a":[["0.00303150","73.51000000"],["0.00356000","20.65000000"]]},{"e":"depthUpdate","E":1557446063080,"s":"BNBBTC","U":264202125,"u":264202132,"b":[["0.00302980","0.00000000"],["0.00302940","0.00000000"],["0.00302450","0.00000000"],["0.00302400","0.00000000"],["0.00301900","2.00000000"],["0.00301500","343.79000000"]],"a":[["0.00303140","30.09000000"],["0.00309000","345.44000000"]]},{"e":"depthUpdate","E":1557446064080,"s":"BNBBTC","U":264202133,"u":264202138,"b":[["0.00302970","0.00000000"],["0.00302600","0.00000000"],["0.00302190","23.01000000"]],"a":[["0.00303130","22.65000000"],["0.00303320","0.00000000"]]},{"e":"depthUpdate","E":1557446065080,"s":"BNBBTC","U":264202139,"u":264202149,"b":[["0.00302960","0.00000000"]],"a":[["0.00303120","3.65000000"],["0.00303130","0.00000000"],["0.00303140","0.00000000"],["0.00303310","22.65000000"],["0.00303320","63.08000000"],["0.00303490","319.93000000"]]},{"e":"depthUpdate","E":1557446066080,"s":"BNBBTC","U":264202150,"u":264202157,"b":[["0.00302990","0.00000000"],["0.00302950","29.58000000"],["0.00302840","3.40000000"],["0.00298980","1.30000000"]],"a":[["0.00303290","22.65000000"],["0.00303300","61.41000000"],["0.00303310","0.00000000"],["0.00303350","0.00000000"]]},{"e":"depthUpdate","E":1557446067080,"s":"BNBBTC","U":264202158,"u":264202185,"b":[["0.00302950","0.00000000"],["0.00302900","3.40000000"],["0.00302890","8.24000000"],["0.00302880","0.00000000"],["0.00302870","0.00000000"],["0.00302860","35.31000000"],["0.00302850","0.00000000"],["0.00302840","0.00000000"],["0.00302830","0.00000000"],["0.00301500","13.79000000"],["0.00301400","330.00000000"]],"a":[["0.00303290","0.00000000"],["0.00303310","22.65000000"],["0.00303490","25.00000000"]]},{"e":"depthUpdate","E":1557446068080,"s":"BNBBTC","U":264202186,"u":264202196,"b":[["0.00302930","3.40000000"],["0.00302920","8.24000000"],["0.00302910","28.82000000"],["0.00302900","0.00000000"],["0.00302890","0.00000000"],["0.00302590","0.00000000"],["0.00302490","20.00000000"]],"a":[["0.00303290","22.65000000"],["0.00303310","0.00000000"],["0.00303590","79.21000000"],["0.00303990","905.29000000"]]},{"e":"depthUpdate","E":1557446069080,"s":"BNBBTC","U":264202197,"u":264202198,"b":[["0.00302760","0.00000000"]],"a":[["0.00438530","0.00000000"]]},{"e":"depthUpdate","E":1557446070081,"s":"BNBBTC","U":264202199,"u":264202216,"b":[["0.00302930","0.00000000"],["0.00302510","82.82000000"],["0.00302500","408.01000000"],["0.00302480","0.00000000"],["0.00302410","0.00000000"],["0.00302180","0.00000000"],["0.00301720","0.00000000"],["0.00301430","24.59000000"]],"a":[["0.00303120","6.91000000"],["0.00303470","294.88000000"],["0.00304840","0.00000000"],["0.00306230","1.32000000"]]},{"e":"depthUpdate","E":1557446071081,"s":"BNBBTC","U":264202217,"u":264202229,"b":[["0.00302860","0.00000000"],["0.00302830","9.85000000"],["0.00302810","23.84000000"],["0.00302530","82.82000000"],["0.00302520","119.72000000"],["0.00302510","0.00000000"],["0.00302500","287.43000000"],["0.00301730","0.00000000"],["0.00301420","798.17000000"],["0.00295540","0.00000000"]],"a":[["0.00304540","40.97000000"]]},{"e":"depthUpdate","E":1557446072080,"s":"BNBBTC","U":264202230,"u":264202231,"b":[],"a":[["0.00304500","100.00000000"],["0.00305940","47.16000000"]]},{"e":"depthUpdate","E":1557446073080,"s":"BNBBTC","U":264202232,"u":264202238,"b":[["0.00302910","0.00000000"],["0.00302550","82.82000000"],["0.00302540","128.62000000"],["0.00302530","0.00000000"],["0.00302520","0.00000000"]],"a":[["0.00303290","0.00000000"],["0.00303310","22.65000000"]]},{"e":"depthUpdate","E":1557446074081,"s":"BNBBTC","U":264202239,"u":264202244,"b":[],"a":[["0.00303140","22.65000000"],["0.00303290","199.91000000"],["0.00303310","0.00000000"],["0.00303330","20.00000000"],["0.00303620","55.00000000"]]},{"e":"depthUpdate","E":1557446075081,"s":"BNBBTC","U":264202245,"u":264202252,"b":[["0.00302920","0.00000000"],["0.00302860","8.24000000"],["0.00302850","9.85000000"],["0.00302840","0.00000000"],["0.00302830","0.00000000"],["0.00299690","1.00000000"],["0.00299510","183.63000000"]],"a":[]},{"e":"depthUpdate","E":1557446076080,"s":"BNBBTC","U":264202253,"u":264202259,"b":[["0.00302880","3.12000000"],["0.00302870","14.53000000"],["0.00302860","0.00000000"],["0.00302850","0.00000000"]],"a":[["0.00303110","2.70000000"],["0.00305940","0.00000000"]]},{"e":"depthUpdate","E":1557446077080,"s":"BNBBTC","U":264202260,"u":264202267,"b":[],"a":[["0.00303090","5.96000000"],["0.00303100","8.04000000"],["0.00303110","0.00000000"],["0.00303120","0.00000000"]]},{"e":"depthUpdate","E":1557446078080,"s":"BNBBTC","U":264202268,"u":264202281,"b":[["0.00302890","8.24000000"],["0.00302880","0.00000000"],["0.00302830","0.00000000"]],"a":[["0.00303070","8.66000000"],["0.00303080","8.04000000"],["0.00303090","0.00000000"],["0.00303100","0.00000000"],["0.00305890","46.04000000"]]},{"e":"depthUpdate","E":1557446079080,"s":"BNBBTC","U":264202282,"u":264202307,"b":[["0.00302890","0.00000000"],["0.00302880","8.24000000"],["0.00302570","82.83000000"],["0.00302560","120.12000000"],["0.00302550","0.00000000"],["0.00302540","0.00000000"]],"a":[["0.00303060","8.03000000"],["0.00303070","5.40000000"],["0.00303080","0.00000000"],["0.00303130","3.26000000"],["0.00303790","905.53000000"],["0.00303990","0.00000000"]]},{"e":"depthUpdate","E":1557446080080,"s":"BNBBTC","U":264202308,"u":264202329,"b":[],"a":[["0.00303060","8.03000000"],["0.00303130","3.26000000"],["0.00303940","13.19000000"],["0.00305000","452.93000000"]]},{"e":"depthUpdate","E":1557446081080,"s":"BNBBTC","U":264202330,"u":264202350,"b":[],"a":[["0.00303060","8.03000000"],["0.00303130","3.26000000"],["0.00303470","0.00000000"]]},{"e":"depthUpdate","E":1557446082080,"s":"BNBBTC","U":264202351,"u":264202369,"b":[],"a":[["0.00303060","8.03000000"],["0.00303130","0.00000000"],["0.00303480","317.87000000"],["0.00304100","28.19000000"]]},{"e":"depthUpdate","E":1557446083081,"s":"BNBBTC","U":264202370,"u":264202391,"b":[],"a":[["0.00303060","8.03000000"],["0.00303130","3.26000000"],["0.00304500","0.00000000"],["0.00345850","3.16000000"]]},{"e":"depthUpdate","E":1557446084080,"s":"BNBBTC","U":264202392,"u":264202416,"b":[["0.00302880","0.00000000"],["0.00302870","0.00000000"],["0.00302830","38.13000000"],["0.00302820","529.08000000"],["0.00302580","81.35000000"],["0.00302570","0.00000000"],["0.00302500","205.95000000"],["0.00301700","330.00000000"],["0.00301400","0.00000000"]],"a":[["0.00302880","2.90000000"],["0.00303050","8.66000000"],["0.00303060","8.03000000"],["0.00303070","0.00000000"],["0.00303130","0.00000000"],["0.00304400","100.00000000"]]},{"e":"depthUpdate","E":1557446085080,"s":"BNBBTC","U":264202417,"u":264202426,"b":[["0.00302190","0.00000000"],["0.00301830","23.01000000"],["0.00301720","798.17000000"],["0.00301420","0.00000000"],["0.00298750","0.00000000"],["0.00298000","737.38000000"]],"a":[["0.00303140","0.00000000"],["0.00303270","22.65000000"],["0.00303280","64.73000000"],["0.00303300","0.00000000"]]},{"e":"depthUpdate","E":1557446086080,"s":"BNBBTC","U":264202427,"u":264202429,"b":[["0.00301260","0.00000000"],["0.00299510","0.00000000"],["0.00299360","183.72000000"]],"a":[]},{"e":"depthUpdate","E":1557446088080,"s":"BNBBTC","U":264202430,"u":264202435,"b":[],"a":[["0.00303760","0.00000000"],["0.00303940","0.00000000"],["0.00304140","0.00000000"],["0.00304270","0.00000000"],["0.00310000","355.42000000"]]},{"e":"depthUpdate","E":1557446089080,"s":"BNBBTC","U":264202436,"u":264202437,"b":[["0.00302840","5.61000000"]],"a":[["0.00304080","14.56000000"]]},{"e":"depthUpdate","E":1557446090080,"s":"BNBBTC","U":264202438,"u":264202448,"b":[["0.00302860","8.25000000"],["0.00302850","28.35000000"],["0.00302830","0.00000000"],["0.00302790","0.00000000"],["0.00302490","0.00000000"]],"a":[["0.00302880","0.00000000"],["0.00303060","6.18000000"],["0.00303760","13.20000000"]]},{"e":"depthUpdate","E":1557446091081,"s":"BNBBTC","U":264202449,"u":264202456,"b":[["0.00302870","29.20000000"],["0.00302850","0.00000000"],["0.00302590","123.88000000"],["0.00302560","0.00000000"],["0.00301830","0.00000000"]],"a":[["0.00303480","294.88000000"],["0.00303760","0.00000000"],["0.00304250","19.19000000"]]},{"e":"depthUpdate","E":1557446092080,"s":"BNBBTC","U":264202457,"u":264202457,"b":[["0.00302400","20.00000000"]],"a":[]},{"e":"depthUpdate","E":1557446093080,"s":"BNBBTC","U":264202458,"u":264202460,"b":[["0.00301190","2.08000000"],["0.00300950","1.60000000"]],"a":[["0.00303330","0.00000000"]]},{"e":"depthUpdate","E":1557446094080,"s":"BNBBTC","U":264202461,"u":264202469,"b":[["0.00302870","25.37000000"],["0.00302600","5.91000000"]],"a":[["0.00303050","121.67000000"],["0.00303150","5.00000000"],["0.00303200","22.65000000"],["0.00303210","20.00000000"],["0.00303270","0.00000000"],["0.00303930","13.19000000"]]},{"e":"depthUpdate","E":1557446095080,"s":"BNBBTC","U":264202470,"u":264202480,"b":[["0.00302870","0.00000000"],["0.00301700","0.00000000"],["0.00301600","337.48000000"],["0.00300210","3.90000000"]],"a":[["0.00303040","8.24000000"],["0.00303050","118.41000000"],["0.00303060","0.00000000"],["0.00303260","0.00000000"]]},{"e":"depthUpdate","E":1557446096080,"s":"BNBBTC","U":264202481,"u":264202490,"b":[["0.00302610","9.85000000"],["0.00302580","0.00000000"]],"a":[["0.00303020","3.26000000"],["0.00303030","41.73000000"],["0.00303040","4.98000000"],["0.00303270","77.07000000"],["0.00303590","0.00000000"],["0.00304300","100.00000000"],["0.00304400","0.00000000"]]},{"e":"depthUpdate","E":1557446097080,"s":"BNBBTC","U":264202491,"u":264202505,"b":[["0.00302860","0.00000000"],["0.00302850","8.25000000"],["0.00301730","76.93000000"],["0.00301610","0.00000000"],["0.00301600","7.48000000"],["0.00301300","330.00000000"],["0.00301190","0.00000000"],["0.00299410","184.35000000"],["0.00299360","0.00000000"],["0.00280000","3196.32000000"],["0.00250000","8384.21000000"]],"a":[["0.00303010","6.87000000"],["0.00303020","0.00000000"],["0.00303040","0.00000000"]]},{"e":"depthUpdate","E":1557446098081,"s":"BNBBTC","U":264202506,"u":264202508,"b":[],"a":[["0.00303050","168.41000000"],["0.00303660","906.86000000"],["0.00303790","0.00000000"]]},{"e":"depthUpdate","E":1557446099080,"s":"BNBBTC","U":264202509,"u":264202515,"b":[["0.00302850","0.00000000"]],"a":[["0.00303000","8.66000000"],["0.00303010","3.61000000"],["0.00303050","163.01000000"],["0.00303260","130.94000000"],["0.00303290","79.51000000"]]},{"e":"depthUpdate","E":1557446100081,"s":"BNBBTC","U":264202516,"u":264202517,"b":[],"a":[["0.00303030","0.00000000"]]},{"e":"depthUpdate","E":1557446101081,"s":"BNBBTC","U":264202518,"u":264202518,"b":[],"a":[["0.00305890","0.00000000"]]},{"e":"depthUpdate","E":1557446103082,"s":"BNBBTC","U":264202519,"u":264202522,"b":[],"a":[["0.00303930","0.00000000"],["0.00304080","1.36000000"],["0.00304250","6.00000000"],["0.00305790","40.36000000"]]},{"e":"depthUpdate","E":1557446104081,"s":"BNBBTC","U":264202523,"u":264202524,"b":[],"a":[["0.00303880","14.10000000"],["0.00304200","13.20000000"]]},{"e":"depthUpdate","E":1557446105081,"s":"BNBBTC","U":264202525,"u":264202527,"b":[["0.00230000","3290.22000000"]],"a":[["0.00303000","9.95000000"],["0.00304200","26.40000000"]]},{"e":"depthUpdate","E":1557446107082,"s":"BNBBTC","U":264202528,"u":264202532,"b":[],"a":[["0.00303880","0.90000000"],["0.00304200","0.00000000"]]},{"e":"depthUpdate","E":1557446108082,"s":"BNBBTC","U":264202533,"u":264202542,"b":[["0.00302870","1981.04000000"],["0.00302840","21.07000000"],["0.00302830","24.21000000"],["0.00302500","145.64000000"],["0.00301740","64.17000000"],["0.00300050","0.00000000"],["0.00299750","0.00000000"],["0.00299440","0.87000000"]],"a":[["0.00304200","26.40000000"]]},{"e":"depthUpdate","E":1557446109082,"s":"BNBBTC","U":264202543,"u":264202554,"b":[["0.00302880","4.36000000"],["0.00300090","6.70000000"],["0.00299790","3.34000000"],["0.00299480","10.55000000"],["0.00292560","0.00000000"],["0.00292210","32.45000000"]],"a":[["0.00303000","0.00000000"],["0.00303010","0.00000000"],["0.00303050","95.88000000"],["0.00303200","92.65000000"],["0.00304590","10.60000000"]]},{"e":"depthUpdate","E":1557446110082,"s":"BNBBTC","U":264202555,"u":264202573,"b":[["0.00302900","39.59000000"],["0.00302890","5.61000000"],["0.00302880","22.96000000"],["0.00302840","15.46000000"],["0.00302830","0.00000000"],["0.00302630","5.89000000"],["0.00302620","77.79000000"],["0.00302600","0.00000000"],["0.00302470","0.00000000"]],"a":[["0.00303050","83.43000000"],["0.00303200","0.00000000"],["0.00303210","0.00000000"],["0.00303250","22.65000000"],["0.00303330","20.00000000"],["0.00303480","70.00000000"],["0.00303600","0.00000000"]]},{"e":"depthUpdate","E":1557446111082,"s":"BNBBTC","U":264202574,"u":264202607,"b":[["0.00302950","3.39000000"],["0.00302940","8.24000000"],["0.00302930","0.00000000"],["0.00302920","0.00000000"],["0.00302910","30.54000000"],["0.00302880","4.36000000"],["0.00302650","0.00000000"],["0.00302640","131.89000000"],["0.00302630","0.00000000"],["0.00302610","0.00000000"],["0.00302590","0.00000000"],["0.00301600","337.48000000"],["0.00301300","0.00000000"]],"a":[["0.00303050","0.00000000"],["0.00303150","18.78000000"],["0.00303160","10.60000000"],["0.00303240","0.00000000"],["0.00303250","86.68000000"],["0.00303280","0.00000000"],["0.00303330","0.00000000"],["0.00303660","1.18000000"],["0.00303790","905.53000000"],["0.00304300","0.00000000"],["0.00304510","157.57000000"],["0.00304600","100.00000000"]]},{"e":"depthUpdate","E":1557446112083,"s":"BNBBTC","U":264202608,"u":264202624,"b":[["0.00302970","11.63000000"],["0.00302960","18.23000000"],["0.00302950","0.00000000"],["0.00302940","0.00000000"],["0.00302910","0.00000000"]],"a":[["0.00303140","10.60000000"],["0.00303160","0.00000000"],["0.00303240","22.65000000"],["0.00303250","64.03000000"],["0.00303260","0.00000000"],["0.00303270","0.00000000"],["0.00303280","0.00000000"],["0.00303640","294.85000000"],["0.00304510","0.00000000"],["0.00304540","13.18000000"]]},{"e":"depthUpdate","E":1557446113083,"s":"BNBBTC","U":264202625,"u":264202636,"b":[["0.00302980","18.23000000"],["0.00302970","8.24000000"],["0.00302960","0.00000000"],["0.00302910","3.39000000"],["0.00302400","0.00000000"],["0.00301560","28.04000000"]],"a":[["0.00303580","0.00000000"],["0.00303610","121.50000000"],["0.00303780","76.93000000"],["0.00304850","27.74000000"],["0.00311280","0.00000000"]]},{"e":"depthUpdate","E":1557446114084,"s":"BNBBTC","U":264202637,"u":264202640,"b":[["0.00302880","0.00000000"],["0.00299120","0.00000000"]],"a":[["0.00303290","0.00000000"],["0.00304060","0.53000000"]]},{"e":"depthUpdate","E":1557446115085,"s":"BNBBTC","U":264202641,"u":264202655,"b":[["0.00302990","39.59000000"],["0.00302910","0.00000000"],["0.00302900","3.39000000"],["0.00302550","20.00000000"],["0.00300540","2.83000000"],["0.00300450","1.20000000"],["0.00298840","9.53000000"]],"a":[["0.00303140","0.00000000"],["0.00303470","20.00000000"],["0.00303600","81.76000000"],["0.00303620","5.00000000"],["0.00303640","0.00000000"],["0.00304500","100.00000000"],["0.00304600","0.00000000"]]},{"e":"depthUpdate","E":1557446116085,"s":"BNBBTC","U":264202656,"u":264202673,"b":[["0.00303000","11.63000000"],["0.00302970","0.00000000"],["0.00302900","0.00000000"],["0.00298720","0.37000000"],["0.00298690","18.38000000"]],"a":[["0.00303150","0.00000000"],["0.00303230","8.24000000"],["0.00303240","0.00000000"],["0.00303320","0.00000000"],["0.00303340","0.00000000"],["0.00303360","0.00000000"],["0.00303470","20.00000000"],["0.00303480","92.65000000"],["0.00303590","81.24000000"],["0.00304570","153.48000000"]]},{"e":"depthUpdate","E":1557446117085,"s":"BNBBTC","U":264202674,"u":264202699,"b":[["0.00303030","3.39000000"],["0.00303020","8.24000000"],["0.00303010","6.98000000"],["0.00303000","0.00000000"],["0.00302980","0.00000000"],["0.00302900","9.84000000"],["0.00302890","11.48000000"],["0.00302880","87.08000000"]],"a":[["0.00303210","8.24000000"],["0.00303220","9.44000000"],["0.00303230","0.00000000"],["0.00303250","0.00000000"],["0.00303450","22.65000000"],["0.00303460","65.43000000"],["0.00303470","83.22000000"],["0.00303480","70.00000000"],["0.00303580","0.00000000"],["0.00303790","0.00000000"],["0.00304490","905.09000000"],["0.00304570","0.00000000"],["0.00383690","0.00000000"]]},{"e":"depthUpdate","E":1557446118086,"s":"BNBBTC","U":264202700,"u":264202706,"b":[["0.00303040","8.53000000"],["0.00303010","0.00000000"],["0.00301700","330.00000000"],["0.00301600","7.48000000"]],"a":[["0.00303200","9.44000000"],["0.00303220","0.00000000"],["0.00304850","0.00000000"]]},{"e":"depthUpdate","E":1557446119086,"s":"BNBBTC","U":264202707,"u":264202709,"b":[["0.00299690","184.52000000"],["0.00299410","0.66000000"]],"a":[["0.00305140","97.96000000"]]},{"e":"depthUpdate","E":1557446120086,"s":"BNBBTC","U":264202710,"u":264202716,"b":[["0.00303050","39.59000000"],["0.00303030","3.39000000"],["0.00302990","0.00000000"],["0.00302900","9.84000000"]],"a":[["0.00382360","0.00000000"]]},{"e":"depthUpdate","E":1557446121086,"s":"BNBBTC","U":264202717,"u":264202728,"b":[["0.00303060","7.48000000"],["0.00303040","0.00000000"],["0.00302920","15.70000000"],["0.00302910","75.87000000"],["0.00302900","0.00000000"],["0.00302890","5.61000000"],["0.00302880","0.00000000"],["0.00302810","3.84000000"],["0.00302500","65.74000000"]],"a":[["0.00304630","151.30000000"]]},{"e":"depthUpdate","E":1557446122086,"s":"BNBBTC","U":264202729,"u":264202731,"b":[["0.00302660","20.00000000"],["0.00302550","0.00000000"]],"a":[["0.00303200","0.00000000"]]},{"e":"depthUpdate","E":1557446123087,"s":"BNBBTC","U":264202732,"u":264202739,"b":[["0.00302940","15.70000000"],["0.00302930","128.58000000"],["0.00302920","0.00000000"],["0.00302640","0.00000000"],["0.00301800","330.00000000"],["0.00301700","0.00000000"]],"a":[]},{"e":"depthUpdate","E":1557446124086,"s":"BNBBTC","U":264202740,"u":264202759,"b":[["0.00303070","11.62000000"],["0.00303030","0.00000000"],["0.00303020","0.00000000"],["0.00302950","9.83000000"],["0.00302940","5.87000000"]],"a":[["0.00303210","0.00000000"],["0.00303420","30.89000000"],["0.00303430","78.11000000"],["0.00303440","0.00000000"],["0.00303450","0.00000000"],["0.00305140","70.25000000"],["0.00305790","0.00000000"]]},{"e":"depthUpdate","E":1557446125087,"s":"BNBBTC","U":264202760,"u":264202777,"b":[["0.00303090","8.23000000"],["0.00303080","16.45000000"],["0.00303070","0.00000000"],["0.00303060","0.00000000"],["0.00303050","0.00000000"],["0.00302950","13.22000000"]],"a":[["0.00303400","30.89000000"],["0.00303410","18.93000000"],["0.00303420","0.00000000"],["0.00303470","63.22000000"],["0.00303570","20.00000000"],["0.00304200","13.20000000"],["0.00304500","0.00000000"],["0.00304600","100.00000000"],["0.00306020","39.98000000"]]},{"e":"depthUpdate","E":1557446126087,"s":"BNBBTC","U":264202778,"u":264202788,"b":[["0.00303110","8.23000000"],["0.00303100","16.12000000"],["0.00303090","0.00000000"],["0.00303080","0.00000000"]],"a":[["0.00303380","30.89000000"],["0.00303390","18.93000000"],["0.00303400","0.00000000"],["0.00303410","0.00000000"],["0.00304900","27.74000000"]]},{"e":"depthUpdate","E":1557446127086,"s":"BNBBTC","U":264202789,"u":264202794,"b":[["0.00303130","8.24000000"],["0.00303120","16.12000000"],["0.00303110","0.00000000"],["0.00303100","0.00000000"],["0.00282550","25.24000000"]],"a":[["0.00304580","13.18000000"]]},{"e":"depthUpdate","E":1557446128086,"s":"BNBBTC","U":264202795,"u":264202800,"b":[["0.00302850","5.00000000"],["0.00300000","376.95000000"],["0.00230000","3273.07000000"]],"a":[["0.00303430","48.15000000"],["0.00308620","0.00000000"],["0.00308880","1.80000000"]]},{"e":"depthUpdate","E":1557446129086,"s":"BNBBTC","U":264202801,"u":264202812,"b":[["0.00303150","8.24000000"],["0.00303140","11.77000000"],["0.00303130","0.00000000"],["0.00302890","21.07000000"],["0.00302840","0.00000000"],["0.00299040","16.16000000"]],"a":[["0.00303380","8.24000000"],["0.00303430","0.00000000"],["0.00303450","22.65000000"],["0.00306020","0.79000000"]]},{"e":"depthUpdate","E":1557446130086,"s":"BNBBTC","U":264202813,"u":264202852,"b":[["0.00303160","0.00000000"],["0.00303150","7.21000000"],["0.00303120","0.00000000"],["0.00302960","3.39000000"],["0.00302950","9.83000000"],["0.00302940","66.99000000"],["0.00302660","0.00000000"],["0.00302520","20.00000000"],["0.00302500","0.00000000"],["0.00301800","0.00000000"],["0.00301600","337.48000000"],["0.00301030","0.00000000"],["0.00300020","189.91000000"],["0.00299690","1.00000000"]],"a":[["0.00303350","8.24000000"],["0.00303360","18.93000000"],["0.00303380","70.00000000"],["0.00303390","0.00000000"],["0.00303450","0.00000000"],["0.00303460","65.43000000"],["0.00303480","0.00000000"],["0.00303560","22.65000000"],["0.00378290","195.63000000"]]},{"e":"depthUpdate","E":1557446131086,"s":"BNBBTC","U":264202853,"u":264202868,"b":[],"a":[["0.00303320","0.00000000"],["0.00303330","5.88000000"],["0.00303340","0.00000000"],["0.00303350","0.00000000"],["0.00303360","0.00000000"],["0.00303370","22.65000000"],["0.00303450","0.00000000"],["0.00303560","0.00000000"],["0.00304490","0.00000000"],["0.00304590","915.69000000"]]},{"e":"depthUpdate","E":1557446132086,"s":"BNBBTC","U":264202869,"u":264202871,"b":[["0.00303150","23.31000000"]],"a":[["0.00303370","0.00000000"],["0.00303450","22.65000000"]]},{"e":"depthUpdate","E":1557446133086,"s":"BNBBTC","U":264202872,"u":264202880,"b":[["0.00303150","7.21000000"],["0.00213000","611.37000000"]],"a":[["0.00303330","0.00000000"],["0.00303370","30.89000000"],["0.00303440","0.00000000"],["0.00303450","0.00000000"],["0.00378290","0.00000000"]]},{"e":"depthUpdate","E":1557446134087,"s":"BNBBTC","U":264202881,"u":264202887,"b":[["0.00303140","0.00000000"],["0.00302960","0.00000000"],["0.00302950","13.22000000"]],"a":[["0.00303350","8.24000000"],["0.00303360","12.62000000"],["0.00303370","22.65000000"],["0.00306050","52.73000000"]]},{"e":"depthUpdate","E":1557446135087,"s":"BNBBTC","U":264202888,"u":264202896,"b":[["0.00302950","513.22000000"],["0.00302620","97.79000000"],["0.00302520","0.00000000"],["0.00301700","330.00000000"],["0.00301600","7.48000000"]],"a":[["0.00303330","8.24000000"],["0.00303340","12.62000000"],["0.00303350","0.00000000"],["0.00303360","0.00000000"]]},{"e":"depthUpdate","E":1557446136087,"s":"BNBBTC","U":264202897,"u":264202939,"b":[["0.00303150","0.00000000"],["0.00303060","8.24000000"],["0.00303050","0.00000000"],["0.00303040","0.00000000"],["0.00303030","13.22000000"],["0.00303020","5.88000000"],["0.00303010","39.59000000"],["0.00303000","0.00000000"],["0.00302990","0.00000000"],["0.00302980","0.00000000"],["0.00302970","0.00000000"],["0.00302960","0.00000000"],["0.00302950","500.00000000"],["0.00302940","61.12000000"]],"a":[["0.00303310","8.24000000"],["0.00303320","12.62000000"],["0.00303330","0.00000000"],["0.00303340","0.00000000"]]},{"e":"depthUpdate","E":1557446137087,"s":"BNBBTC","U":264202940,"u":264202944,"b":[["0.00303070","2.93000000"]],"a":[["0.00303290","8.24000000"],["0.00303300","12.62000000"],["0.00303310","0.00000000"],["0.00303320","0.00000000"]]},{"e":"depthUpdate","E":1557446138087,"s":"BNBBTC","U":264202945,"u":264202953,"b":[["0.00303060","0.00000000"],["0.00303040","8.24000000"],["0.00303030","3.39000000"]],"a":[["0.00303270","8.24000000"],["0.00303280","12.61000000"],["0.00303290","0.00000000"],["0.00303300","0.00000000"],["0.00304500","100.00000000"],["0.00304600","0.00000000"]]},{"e":"depthUpdate","E":1557446139087,"s":"BNBBTC","U":264202954,"u":264202957,"b":[["0.00302890","34.07000000"]],"a":[["0.00303270","3.45000000"],["0.00304150","13.18000000"]]},{"e":"depthUpdate","E":1557446140087,"s":"BNBBTC","U":264202958,"u":264203001,"b":[["0.00303080","8.24000000"],["0.00303070","0.00000000"],["0.00303060","0.00000000"],["0.00303050","0.00000000"],["0.00303040","0.00000000"],["0.00303030","11.37000000"],["0.00303020","1.82000000"],["0.00302960","4.36000000"],["0.00301900","332.00000000"],["0.00301700","0.00000000"],["0.00301390","2.05000000"]],"a":[["0.00303270","0.00000000"],["0.00303280","8.24000000"],["0.00303290","0.00000000"],["0.00303370","0.00000000"],["0.00303380","0.00000000"],["0.00303430","23.47000000"],["0.00303440","19.44000000"],["0.00303450","11.21000000"],["0.00303570","90.00000000"],["0.00304490","905.09000000"],["0.00304590","10.60000000"]]},{"e":"depthUpdate","E":1557446141087,"s":"BNBBTC","U":264203002,"u":264203026,"b":[["0.00303100","8.24000000"],["0.00303090","16.10000000"],["0.00303080","35.31000000"],["0.00303030","0.00000000"],["0.00303020","0.00000000"],["0.00303010","0.00000000"],["0.00302960","14.19000000"],["0.00302730","20.00000000"],["0.00302620","77.79000000"],["0.00270550","26.36000000"]],"a":[["0.00303280","4.07000000"],["0.00303290","11.21000000"],["0.00303440","16.05000000"],["0.00303450","0.00000000"],["0.00304500","0.00000000"],["0.00304600","100.00000000"]]},{"e":"depthUpdate","E":1557446142087,"s":"BNBBTC","U":264203027,"u":264203051,"b":[["0.00303160","8.24000000"],["0.00303150","0.00000000"],["0.00303140","0.00000000"],["0.00303130","0.00000000"],["0.00303120","9.83000000"],["0.00303110","11.37000000"],["0.00303100","0.00000000"],["0.00303090","0.00000000"],["0.00302960","4.36000000"]],"a":[["0.00303280","0.00000000"],["0.00303290","0.00000000"],["0.00303430","34.31000000"],["0.00303460","0.00000000"],["0.00303560","79.69000000"],["0.00303780","0.00000000"]]},{"e":"depthUpdate","E":1557446143087,"s":"BNBBTC","U":264203052,"u":264203075,"b":[["0.00303280","13.01000000"],["0.00303180","8.23000000"],["0.00303170","11.37000000"],["0.00303160","0.00000000"],["0.00303120","0.00000000"],["0.00303110","0.00000000"],["0.00303100","0.00000000"],["0.00303090","0.00000000"],["0.00302990","9.83000000"],["0.00302980","13.65000000"],["0.00302970","125.68000000"],["0.00302930","0.00000000"],["0.00301390","0.00000000"]],"a":[["0.00303550","125.71000000"],["0.00303560","0.00000000"],["0.00303570","70.00000000"],["0.00303610","0.00000000"],["0.00303680","20.00000000"],["0.00304150","0.00000000"],["0.00304600","0.00000000"],["0.00304820","62.62000000"]]},{"e":"depthUpdate","E":1557446144088,"s":"BNBBTC","U":264203076,"u":264203084,"b":[["0.00303270","5.69000000"],["0.00303170","0.00000000"],["0.00302990","13.22000000"],["0.00302970","122.29000000"],["0.00302960","0.00000000"],["0.00302730","0.00000000"]],"a":[["0.00304480","79.36000000"],["0.00304700","100.00000000"],["0.00439610","0.00000000"]]},{"e":"depthUpdate","E":1557446145088,"s":"BNBBTC","U":264203085,"u":264203096,"b":[["0.00303290","6.16000000"],["0.00303270","0.00000000"],["0.00303080","0.00000000"],["0.00302840","20.00000000"]],"a":[["0.00303420","14.86000000"],["0.00303430","19.45000000"],["0.00303440","0.00000000"],["0.00303460","0.00000000"],["0.00403700","0.00000000"]]},{"e":"depthUpdate","E":1557446146088,"s":"BNBBTC","U":264203097,"u":264203103,"b":[["0.00303290","0.00000000"],["0.00303280","11.63000000"],["0.00301160","0.00000000"]],"a":[["0.00303410","11.21000000"],["0.00303420","0.00000000"],["0.00303430","8.24000000"],["0.00303460","14.86000000"],["0.00390000","1705.72000000"]]},{"e":"depthUpdate","E":1557446147088,"s":"BNBBTC","U":264203104,"u":264203112,"b":[["0.00303280","18.15000000"],["0.00303080","1415.58000000"]],"a":[["0.00303410","0.00000000"],["0.00303450","13.26000000"],["0.00303460","0.00000000"],["0.00303540","14.86000000"],["0.00304490","0.00000000"],["0.00304620","904.49000000"],["0.00308230","116.17000000"]]},{"e":"depthUpdate","E":1557446148088,"s":"BNBBTC","U":264203113,"u":264203128,"b":[["0.00303100","13.22000000"],["0.00303090","18.00000000"],["0.00302990","0.00000000"],["0.00302980","0.00000000"],["0.00299040","16.99000000"],["0.00298990","0.00000000"]],"a":[["0.00303430","21.50000000"],["0.00303450","0.00000000"],["0.00303540","0.00000000"],["0.00303550","0.00000000"],["0.00303560","14.86000000"],["0.00304700","0.00000000"],["0.00304800","117.47000000"]]},{"e":"depthUpdate","E":1557446149088,"s":"BNBBTC","U":264203129,"u":264203131,"b":[],"a":[["0.00303430","13.26000000"],["0.00303460","8.23000000"],["0.00303790","126.93000000"]]},{"e":"depthUpdate","E":1557446150088,"s":"BNBBTC","U":264203132,"u":264203135,"b":[["0.00303280","11.63000000"]],"a":[["0.00303580","21.38000000"],["0.00304470","23.00000000"],["0.00306860","0.00000000"]]},{"e":"depthUpdate","E":1557446151088,"s":"BNBBTC","U":264203136,"u":264203142,"b":[["0.00302840","0.00000000"],["0.00302720","20.00000000"],["0.00301900","2.00000000"],["0.00301800","330.00000000"]],"a":[["0.00303460","23.09000000"],["0.00303560","0.00000000"],["0.00307080","7.14000000"]]},{"e":"depthUpdate","E":1557446152088,"s":"BNBBTC","U":264203143,"u":264203147,"b":[["0.00301560","0.00000000"]],"a":[["0.00303460","8.23000000"],["0.00303470","0.00000000"],["0.00303550","14.86000000"],["0.00303560","65.91000000"]]},{"e":"depthUpdate","E":1557446153089,"s":"BNBBTC","U":264203148,"u":264203153,"b":[["0.00303290","4.18000000"],["0.00302850","25.00000000"],["0.00302720","0.00000000"],["0.00301810","798.17000000"],["0.00301720","0.00000000"]],"a":[["0.00338080","0.00000000"]]},{"e":"depthUpdate","E":1557446154089,"s":"BNBBTC","U":264203154,"u":264203155,"b":[["0.00303090","13.64000000"]],"a":[["0.00352550","0.00000000"]]},{"e":"depthUpdate","E":1557446155089,"s":"BNBBTC","U":264203156,"u":264203156,"b":[],"a":[["0.00382620","0.00000000"]]},{"e":"depthUpdate","E":1557446156089,"s":"BNBBTC","U":264203157,"u":264203158,"b":[["0.00300230","6.58000000"]],"a":[["0.00303430","14.26000000"]]},{"e":"depthUpdate","E":1557446157089,"s":"BNBBTC","U":264203159,"u":264203162,"b":[["0.00299060","0.53000000"]],"a":[["0.00303430","1.00000000"],["0.00303460","16.62000000"],["0.00307630","177.00000000"]]},{"e":"depthUpdate","E":1557446158089,"s":"BNBBTC","U":264203163,"u":264203166,"b":[["0.00298870","3.34000000"]],"a":[["0.00303680","0.00000000"],["0.00303790","146.93000000"],["0.00307620","0.00000000"]]},{"e":"depthUpdate","E":1557446159089,"s":"BNBBTC","U":264203167,"u":264203177,"b":[["0.00303300","11.77000000"],["0.00302850","5.00000000"]],"a":[["0.00303430","0.00000000"],["0.00303460","8.39000000"],["0.00303480","8.23000000"],["0.00303550","0.00000000"],["0.00303570","14.86000000"],["0.00303590","0.00000000"],["0.00303720","71.00000000"],["0.00349450","0.71000000"]]},{"e":"depthUpdate","E":1557446160089,"s":"BNBBTC","U":264203178,"u":264203187,"b":[["0.00303320","9.63000000"],["0.00303310","20.38000000"],["0.00303290","0.00000000"],["0.00303030","20.00000000"]],"a":[["0.00303460","0.00000000"],["0.00303600","0.00000000"],["0.00303720","1.00000000"],["0.00303880","70.90000000"],["0.00304610","75.09000000"],["0.00349450","0.00000000"]]},{"e":"depthUpdate","E":1557446161089,"s":"BNBBTC","U":264203188,"u":264203196,"b":[["0.00303330","11.36000000"],["0.00303320","44.94000000"],["0.00303310","0.00000000"],["0.00300030","50.00000000"],["0.00299680","2.13000000"]],"a":[["0.00304190","78.02000000"],["0.00304200","0.00000000"]]},{"e":"depthUpdate","E":1557446162090,"s":"BNBBTC","U":264203197,"u":264203206,"b":[["0.00303340","11.77000000"],["0.00303300","0.00000000"],["0.00302850","0.00000000"],["0.00302820","0.00000000"],["0.00300040","183.30000000"],["0.00300020","6.59000000"]],"a":[["0.00304800","17.47000000"],["0.00304900","127.74000000"],["0.00306050","0.00000000"],["0.00306330","190.65000000"]]},{"e":"depthUpdate","E":1557446163089,"s":"BNBBTC","U":264203207,"u":264203208,"b":[["0.00303350","2.48000000"],["0.00303330","0.00000000"]],"a":[]},{"e":"depthUpdate","E":1557446164089,"s":"BNBBTC","U":264203209,"u":264203215,"b":[["0.00303350","0.00000000"],["0.00303340","4.08000000"],["0.00302950","0.00000000"],["0.00301530","0.00000000"]],"a":[["0.00303790","126.93000000"],["0.00303930","20.00000000"],["0.00304900","27.74000000"],["0.00305000","552.93000000"]]},{"e":"depthUpdate","E":1557446165089,"s":"BNBBTC","U":264203216,"u":264203242,"b":[["0.00303370","8.23000000"],["0.00303360","9.63000000"],["0.00303340","0.00000000"],["0.00303330","0.00000000"],["0.00303320","0.00000000"],["0.00303280","0.00000000"],["0.00303190","0.00000000"],["0.00303180","0.00000000"],["0.00303100","13.22000000"],["0.00301410","299.73000000"],["0.00300270","6.69000000"],["0.00300090","0.00000000"],["0.00299790","0.00000000"],["0.00299660","10.56000000"],["0.00299480","0.49000000"]],"a":[["0.00303480","0.00000000"],["0.00303490","0.00000000"],["0.00303550","14.86000000"],["0.00303570","0.00000000"],["0.00305000","452.93000000"],["0.00305100","101.36000000"]]},{"e":"depthUpdate","E":1557446166089,"s":"BNBBTC","U":264203243,"u":264203266,"b":[["0.00303390","7.13000000"],["0.00303380","47.08000000"],["0.00303160","23.48000000"],["0.00303150","20.00000000"],["0.00303100","3.39000000"],["0.00303090","133.19000000"],["0.00303030","0.00000000"],["0.00302980","75.57000000"],["0.00302970","0.00000000"],["0.00301730","0.00000000"],["0.00300490","50.65000000"],["0.00300480","51.12000000"],["0.00300030","0.00000000"],["0.00299970","3.83000000"],["0.00298690","51.12000000"],["0.00298000","704.56000000"]],"a":[["0.00303550","0.00000000"],["0.00303640","14.86000000"]]},{"e":"depthUpdate","E":1557446167089,"s":"BNBBTC","U":264203267,"u":264203281,"b":[["0.00303400","8.23000000"],["0.00303370","0.00000000"],["0.00303170","0.00000000"],["0.00303160","13.65000000"],["0.00303120","3.39000000"],["0.00303110","9.83000000"],["0.00303100","59.85000000"],["0.00301740","0.00000000"],["0.00300510","2.14000000"]],"a":[["0.00303560","0.00000000"],["0.00303930","0.00000000"]]},{"e":"depthUpdate","E":1557446168089,"s":"BNBBTC","U":264203282,"u":264203294,"b":[["0.00303410","9.40000000"],["0.00303390","0.00000000"],["0.00302990","29.47000000"],["0.00302890","13.00000000"]],"a":[["0.00303640","14.86000000"],["0.00303770","74.25000000"],["0.00303880","0.90000000"],["0.00303970","20.00000000"],["0.00304180","62.41000000"],["0.00388010","0.34000000"]]},{"e":"depthUpdate","E":1557446169089,"s":"BNBBTC","U":264203295,"u":264203314,"b":[["0.00303410","0.00000000"],["0.00303400","0.00000000"],["0.00303380","0.00000000"],["0.00303360","0.00000000"],["0.00303190","0.00000000"],["0.00303180","0.00000000"],["0.00303170","0.00000000"],["0.00303160","0.00000000"],["0.00303150","0.00000000"],["0.00303120","4.70000000"],["0.00303110","0.00000000"],["0.00303100","0.00000000"],["0.00303090","8.23000000"],["0.00303080","1315.43000000"],["0.00303000","4.36000000"],["0.00302910","0.00000000"],["0.00302620","0.00000000"]],"a":[["0.00303570","0.68000000"],["0.00303640","0.00000000"],["0.00303770","4.25000000"],["0.00355720","0.34000000"]]},{"e":"depthUpdate","E":1557446170089,"s":"BNBBTC","U":264203315,"u":264203348,"b":[["0.00303130","8.23000000"],["0.00303120","24.70000000"],["0.00303090","0.00000000"],["0.00302980","0.00000000"],["0.00302870","0.00000000"],["0.00301820","348.51000000"]],"a":[["0.00303530","42.41000000"],["0.00303540","187.25000000"],["0.00303550","0.00000000"],["0.00303560","0.00000000"],["0.00303570","29.96000000"],["0.00303580","119.46000000"],["0.00347650","1.19000000"]]},{"e":"depthUpdate","E":1557446171090,"s":"BNBBTC","U":264203349,"u":264203387,"b":[["0.00303170","16.46000000"],["0.00303160","0.00000000"],["0.00303150","0.00000000"],["0.00303140","0.00000000"],["0.00303130","0.00000000"],["0.00303120","20.00000000"],["0.00303080","0.00000000"],["0.00302940","0.00000000"],["0.00302190","83.86000000"],["0.00302180","137.01000000"],["0.00301940","9.84000000"],["0.00301470","1.85000000"],["0.00292030","30.00000000"]],"a":[["0.00303510","30.80000000"],["0.00303520","30.69000000"],["0.00303530","0.00000000"],["0.00303540","238.61000000"],["0.00303580","91.38000000"],["0.00303780","23.00000000"],["0.00304470","0.00000000"],["0.00339580","0.41000000"]]},{"e":"depthUpdate","E":1557446172090,"s":"BNBBTC","U":264203388,"u":264203444,"b":[["0.00303180","0.00000000"],["0.00303170","0.00000000"],["0.00303120","0.00000000"],["0.00303040","8.23000000"],["0.00303030","0.00000000"],["0.00303020","0.00000000"],["0.00303010","0.00000000"],["0.00303000","4.36000000"],["0.00302690","0.00000000"],["0.00302680","20.00000000"],["0.00302220","1.13000000"],["0.00302210","82.77000000"],["0.00302200","202.34000000"],["0.00302190","0.00000000"],["0.00302180","61.41000000"],["0.00301940","9.84000000"],["0.00301820","223.62000000"],["0.00301800","0.00000000"],["0.00299520","0.00000000"]],"a":[["0.00303440","3.39000000"],["0.00303450","28.50000000"],["0.00303460","0.00000000"],["0.00303470","0.00000000"],["0.00303480","0.00000000"],["0.00303490","27.41000000"],["0.00303500","29.24000000"],["0.00303510","0.00000000"],["0.00303520","0.00000000"],["0.00303530","6.54000000"],["0.00303860","20.00000000"],["0.00303970","0.00000000"],["0.00305900","5.62000000"]]},{"e":"depthUpdate","E":1557446173089,"s":"BNBBTC","U":264203445,"u":264203512,"b":[["0.00303060","4.28000000"],["0.00303040","0.00000000"],["0.00303000","8.23000000"],["0.00302240","0.00000000"],["0.00302230","85.11000000"],["0.00302220","74.28000000"],["0.00302210","0.00000000"],["0.00302200","125.37000000"],["0.00301900","332.00000000"],["0.00300040","0.00000000"],["0.00300020","189.91000000"],["0.00299390","2.15000000"]],"a":[["0.00303330","3.39000000"],["0.00303340","16.46000000"],["0.00303350","0.00000000"],["0.00303360","12.24000000"],["0.00303370","0.00000000"],["0.00303380","30.36000000"],["0.00303390","0.00000000"],["0.00303400","0.00000000"],["0.00303410","0.00000000"],["0.00303420","0.00000000"],["0.00303430","26.20000000"],["0.00303440","70.00000000"],["0.00303450","0.00000000"],["0.00303490","0.00000000"],["0.00303500","0.00000000"],["0.00303530","136.71000000"],["0.00303580","21.38000000"],["0.00303790","0.00000000"],["0.00303860","0.00000000"],["0.00305290","0.00000000"],["0.00305330","12.43000000"]]},{"e":"depthUpdate","E":1557446174089,"s":"BNBBTC","U":264203513,"u":264203561,"b":[["0.00303060","0.00000000"],["0.00303010","4.28000000"],["0.00301900","2.00000000"],["0.00301810","0.00000000"],["0.00301420","799.39000000"]],"a":[["0.00303240","3.39000000"],["0.00303250","16.46000000"],["0.00303260","12.24000000"],["0.00303270","0.00000000"],["0.00303280","0.00000000"],["0.00303290","0.00000000"],["0.00303300","0.00000000"],["0.00303310","0.00000000"],["0.00303320","0.00000000"],["0.00303330","100.51000000"],["0.00303340","26.20000000"],["0.00303350","29.96000000"],["0.00303360","0.00000000"],["0.00303380","0.00000000"],["0.00303430","0.00000000"],["0.00303440","0.00000000"],["0.00303510","0.00000000"],["0.00303520","78.40000000"],["0.00303570","0.00000000"],["0.00303790","905.53000000"],["0.00304480","0.00000000"],["0.00304620","0.00000000"]]},{"e":"depthUpdate","E":1557446175089,"s":"BNBBTC","U":264203562,"u":264203591,"b":[["0.00302690","2.34000000"],["0.00302230","82.77000000"],["0.00301800","330.00000000"],["0.00298840","0.00000000"]],"a":[["0.00303180","3.39000000"],["0.00303190","16.46000000"],["0.00303200","12.24000000"],["0.00303210","0.00000000"],["0.00303220","0.00000000"],["0.00303230","0.00000000"],["0.00303240","0.00000000"],["0.00303250","0.00000000"],["0.00303260","0.00000000"],["0.00303320","26.20000000"],["0.00303340","0.00000000"],["0.00303540","0.00000000"],["0.00303700","20.00000000"],["0.00304210","13.18000000"],["0.00304900","127.74000000"],["0.00305100","1.36000000"]]},{"e":"depthUpdate","E":1557446176089,"s":"BNBBTC","U":264203592,"u":264203605,"b":[["0.00303010","0.00000000"],["0.00303000","2.94000000"],["0.00299630","8.84000000"],["0.00298690","38.56000000"]],"a":[["0.00303170","10.63000000"],["0.00303180","70.00000000"],["0.00303200","0.00000000"],["0.00303310","0.00000000"],["0.00303330","30.51000000"],["0.00303530","130.17000000"],["0.00307780","0.36000000"]]},{"e":"depthUpdate","E":1557446177089,"s":"BNBBTC","U":264203606,"u":264203613,"b":[["0.00303000","0.00000000"],["0.00302900","8.24000000"],["0.00299420","11.67000000"],["0.00224960","7.98000000"],["0.00224460","0.00000000"]],"a":[["0.00304050","13.19000000"],["0.00304800","117.47000000"],["0.00304900","27.74000000"]]},{"e":"depthUpdate","E":1557446178089,"s":"BNBBTC","U":264203614,"u":264203616,"b":[["0.00260300","0.00000000"]],"a":[["0.00303350","0.00000000"],["0.00307970","0.48000000"]]},{"e":"depthUpdate","E":1557446179089,"s":"BNBBTC","U":264203617,"u":264203623,"b":[["0.00302250","82.78000000"],["0.00302240","81.65000000"],["0.00302230","0.00000000"],["0.00302220","0.00000000"],["0.00283880","0.00000000"]],"a":[["0.00303580","41.38000000"],["0.00303700","0.00000000"]]},{"e":"depthUpdate","E":1557446180090,"s":"BNBBTC","U":264203624,"u":264203627,"b":[["0.00301810","799.15000000"],["0.00301420","0.00000000"]],"a":[["0.00303790","0.00000000"],["0.00303990","905.47000000"]]},{"e":"depthUpdate","E":1557446181089,"s":"BNBBTC","U":264203628,"u":264203632,"b":[["0.00301540","0.63000000"]],"a":[["0.00303510","61.79000000"],["0.00304180","0.00000000"],["0.00304990","1.77000000"],["0.00305330","10.65000000"]]},{"e":"depthUpdate","E":1557446182089,"s":"BNBBTC","U":264203633,"u":264203639,"b":[["0.00302260","9.84000000"],["0.00302250","293.85000000"],["0.00301940","0.00000000"]],"a":[["0.00304600","100.00000000"],["0.00304800","17.47000000"],["0.00306820","1.78000000"],["0.00307080","5.35000000"]]},{"e":"depthUpdate","E":1557446183089,"s":"BNBBTC","U":264203640,"u":264203652,"b":[["0.00302280","92.62000000"],["0.00302270","202.74000000"],["0.00302260","0.00000000"],["0.00302250","211.07000000"],["0.00302240","0.00000000"],["0.00302200","0.00000000"]],"a":[["0.00303000","1.75000000"],["0.00303480","20.00000000"],["0.00303580","21.38000000"],["0.00308660","1.79000000"],["0.00308880","0.00000000"]]},{"e":"depthUpdate","E":1557446184089,"s":"BNBBTC","U":264203653,"u":264203657,"b":[],"a":[["0.00303000","0.00000000"],["0.00303170","19.85000000"],["0.00303190","0.00000000"],["0.00303880","14.10000000"]]},{"e":"depthUpdate","E":1557446185090,"s":"BNBBTC","U":264203658,"u":264203681,"b":[["0.00302990","13.52000000"],["0.00302790","20.00000000"],["0.00302690","0.00000000"],["0.00302680","0.00000000"],["0.00302310","0.00000000"],["0.00302300","85.13000000"],["0.00302290","74.74000000"],["0.00302280","10.19000000"],["0.00302270","126.80000000"],["0.00297990","1.66000000"],["0.00297530","2.16000000"]],"a":[["0.00303170","19.51000000"],["0.00303320","0.00000000"],["0.00303470","26.20000000"],["0.00303510","61.79000000"],["0.00303880","0.90000000"]]},{"e":"depthUpdate","E":1557446186089,"s":"BNBBTC","U":264203682,"u":264203709,"b":[["0.00302320","85.13000000"],["0.00302310","77.05000000"],["0.00302300","0.00000000"],["0.00302290","0.00000000"],["0.00302280","10.19000000"]],"a":[["0.00303470","0.00000000"],["0.00303500","26.20000000"]]},{"e":"depthUpdate","E":1557446187089,"s":"BNBBTC","U":264203710,"u":264203745,"b":[["0.00302790","0.00000000"],["0.00302670","20.00000000"],["0.00302340","85.13000000"],["0.00302330","77.34000000"],["0.00302320","0.00000000"],["0.00302310","0.00000000"],["0.00302300","0.00000000"],["0.00302290","0.35000000"],["0.00302280","9.84000000"],["0.00301830","799.10000000"],["0.00301810","0.00000000"]],"a":[["0.00303150","0.00000000"],["0.00303160","3.05000000"],["0.00303170","16.46000000"],["0.00303470","26.20000000"],["0.00303500","122.20000000"],["0.00303790","905.53000000"],["0.00303990","0.00000000"],["0.00410000","2290.54000000"]]},{"e":"depthUpdate","E":1557446188089,"s":"BNBBTC","U":264203746,"u":264203748,"b":[["0.00302290","3.40000000"]],"a":[["0.00303160","0.00000000"],["0.00303170","11.54000000"]]},{"e":"depthUpdate","E":1557446189090,"s":"BNBBTC","U":264203749,"u":264203749,"b":[["0.00301790","28.06000000"]],"a":[]},{"e":"depthUpdate","E":1557446190089,"s":"BNBBTC","U":264203750,"u":264203783,"b":[["0.00303000","8.24000000"],["0.00302900","0.00000000"],["0.00302680","2.35000000"],["0.00302360","82.78000000"],["0.00302350","61.66000000"],["0.00302340","0.00000000"],["0.00302290","0.00000000"],["0.00301820","159.07000000"]],"a":[["0.00303170","0.00000000"],["0.00303180","0.00000000"],["0.00303320","26.20000000"],["0.00303330","70.00000000"],["0.00303460","30.28000000"],["0.00303470","0.00000000"],["0.00303490","6.54000000"],["0.00304600","0.00000000"],["0.00304630","0.00000000"],["0.00304800","117.47000000"]]},{"e":"depthUpdate","E":1557446191089,"s":"BNBBTC","U":264203784,"u":264203843,"b":[["0.00303020","8.24000000"],["0.00303010","27.76000000"],["0.00303000","0.00000000"],["0.00302990","0.00000000"],["0.00302800","0.00000000"],["0.00302790","20.00000000"],["0.00302680","0.00000000"],["0.00302670","0.00000000"],["0.00302390","5.74000000"],["0.00302380","82.78000000"],["0.00302370","205.79000000"],["0.00302360","9.84000000"],["0.00302330","0.00000000"],["0.00302290","0.00000000"],["0.00302280","0.00000000"],["0.00302270","0.00000000"],["0.00302190","0.00000000"],["0.00300490","0.65000000"],["0.00300030","50.00000000"]],"a":[["0.00303310","28.54000000"],["0.00303320","59.98000000"],["0.00303460","0.00000000"],["0.00303470","26.20000000"],["0.00304050","0.00000000"],["0.00304670","159.82000000"],["0.00304800","17.47000000"],["0.00304820","0.00000000"],["0.00304900","127.74000000"],["0.00308660","0.00000000"],["0.00308820","1.80000000"]]},{"e":"depthUpdate","E":1557446192089,"s":"BNBBTC","U":264203844,"u":264203853,"b":[["0.00303040","8.24000000"],["0.00303030","12.49000000"],["0.00303020","0.00000000"],["0.00302790","0.00000000"],["0.00302380","82.78000000"],["0.00302360","9.84000000"]],"a":[["0.00303300","5.94000000"]]},{"e":"depthUpdate","E":1557446193089,"s":"BNBBTC","U":264203854,"u":264203881,"b":[["0.00303060","8.24000000"],["0.00303050","12.49000000"],["0.00303040","0.00000000"],["0.00303030","0.00000000"],["0.00302690","20.00000000"],["0.00302410","88.50000000"],["0.00302400","77.35000000"],["0.00302390","0.00000000"],["0.00302380","9.84000000"],["0.00302370","128.06000000"],["0.00302360","0.00000000"]],"a":[["0.00303300","0.00000000"]]},{"e":"depthUpdate","E":1557446194089,"s":"BNBBTC","U":264203882,"u":264203896,"b":[["0.00303080","8.24000000"],["0.00303070","12.49000000"],["0.00303060","0.00000000"],["0.00303050","0.00000000"],["0.00302410","88.50000000"],["0.00302390","0.00000000"],["0.00302380","0.00000000"],["0.00302360","9.84000000"],["0.00301800","0.00000000"],["0.00301600","337.48000000"]],"a":[["0.00303490","0.00000000"],["0.00304600","100.00000000"],["0.00304900","27.74000000"]]},{"e":"depthUpdate","E":1557446195089,"s":"BNBBTC","U":264203897,"u":264203923,"b":[["0.00303100","8.24000000"],["0.00303090","12.49000000"],["0.00303080","0.00000000"],["0.00303070","0.00000000"],["0.00302410","85.10000000"],["0.00302380","0.00000000"],["0.00301830","0.00000000"],["0.00301610","799.10000000"],["0.00300040","183.30000000"],["0.00300020","6.59000000"]],"a":[["0.00304500","100.00000000"],["0.00304600","0.00000000"]]},{"e":"depthUpdate","E":1557446196090,"s":"BNBBTC","U":264203924,"u":264203947,"b":[["0.00303100","7.73000000"],["0.00302410","85.10000000"],["0.00302380","3.40000000"]],"a":[["0.00303300","0.51000000"],["0.00360000","2837.98000000"]]},{"e":"depthUpdate","E":1557446197090,"s":"BNBBTC","U":264203948,"u":264203964,"b":[["0.00302410","88.50000000"],["0.00302390","0.00000000"],["0.00302380","0.00000000"],["0.00302360","9.84000000"],["0.00301360","0.00000000"]],"a":[["0.00303290","0.00000000"]]},{"e":"depthUpdate","E":1557446198090,"s":"BNBBTC","U":264203965,"u":264203990,"b":[["0.00302440","3.40000000"],["0.00302430","85.09000000"],["0.00302420","127.84000000"],["0.00302410","9.84000000"],["0.00302380","0.00000000"],["0.00302370","0.00000000"],["0.00302360","0.00000000"],["0.00301700","330.00000000"],["0.00301600","7.48000000"]],"a":[["0.00303290","0.00000000"],["0.00303300","26.71000000"],["0.00303460","129.09000000"],["0.00303470","0.00000000"],["0.00303530","0.00000000"],["0.00304500","0.00000000"],["0.00304900","127.74000000"]]},{"e":"depthUpdate","E":1557446199091,"s":"BNBBTC","U":264203991,"u":264203992,"b":[],"a":[["0.00303290","5.94000000"],["0.00303390","106.78000000"]]},{"e":"depthUpdate","E":1557446200091,"s":"BNBBTC","U":264203993,"u":264204008,"b":[["0.00302450","85.09000000"],["0.00302440","84.66000000"],["0.00302430","9.84000000"],["0.00302410","0.00000000"],["0.00302400","0.00000000"]],"a":[["0.00303270","0.00000000"],["0.00303280","0.00000000"],["0.00303300","0.51000000"],["0.00303310","26.20000000"],["0.00303490","1.00000000"]]},{"e":"depthUpdate","E":1557446201091,"s":"BNBBTC","U":264204009,"u":264204029,"b":[["0.00302810","23.84000000"],["0.00302690","0.00000000"],["0.00302460","0.00000000"],["0.00302450","88.49000000"],["0.00302440","81.26000000"],["0.00302430","0.00000000"],["0.00302360","0.00000000"]],"a":[["0.00303310","0.00000000"],["0.00303320","26.20000000"],["0.00306330","153.02000000"]]},{"e":"depthUpdate","E":1557446202091,"s":"BNBBTC","U":264204030,"u":264204060,"b":[["0.00303120","8.24000000"],["0.00303110","13.68000000"],["0.00303100","0.00000000"],["0.00303090","0.00000000"],["0.00302450","88.48000000"],["0.00302430","9.84000000"],["0.00302370","0.00000000"],["0.00302360","0.00000000"],["0.00301720","799.10000000"],["0.00301610","0.00000000"]],"a":[["0.00303290","0.00000000"],["0.00303300","0.00000000"],["0.00303320","100.32000000"],["0.00303510","0.00000000"],["0.00303640","61.57000000"]]},{"e":"depthUpdate","E":1557446203091,"s":"BNBBTC","U":264204061,"u":264204086,"b":[["0.00302460","0.00000000"],["0.00302450","85.09000000"],["0.00302440","84.65000000"],["0.00302430","9.84000000"],["0.00302360","0.00000000"]],"a":[["0.00303310","5.94000000"],["0.00303320","116.31000000"]]},{"e":"depthUpdate","E":1557446204091,"s":"BNBBTC","U":264204087,"u":264204126,"b":[["0.00303140","16.48000000"],["0.00303130","13.68000000"],["0.00303120","0.00000000"],["0.00303110","0.00000000"],["0.00302480","5.72000000"],["0.00302470","82.74000000"],["0.00302460","130.78000000"],["0.00302450","0.00000000"],["0.00302440","81.26000000"],["0.00302430","0.00000000"],["0.00302420","0.00000000"],["0.00302370","0.00000000"],["0.00302360","0.00000000"]],"a":[["0.00303320","90.11000000"],["0.00303450","26.20000000"],["0.00304900","27.74000000"],["0.00305000","552.93000000"]]},{"e":"depthUpdate","E":1557446205091,"s":"BNBBTC","U":264204127,"u":264204155,"b":[["0.00303150","13.68000000"],["0.00303130","0.00000000"],["0.00302470","82.74000000"],["0.00302360","9.84000000"],["0.00299850","2.13000000"]],"a":[["0.00303320","74.12000000"],["0.00303330","0.00000000"],["0.00303480","0.00000000"],["0.00303580","91.38000000"],["0.00303820","20.00000000"]]},{"e":"depthUpdate","E":1557446206091,"s":"BNBBTC","U":264204156,"u":264204200,"b":[["0.00303160","16.48000000"],["0.00303140","0.00000000"],["0.00302500","0.00000000"],["0.00302490","85.07000000"],["0.00302480","68.64000000"],["0.00302470","9.84000000"],["0.00302450","0.00000000"],["0.00302360","0.00000000"],["0.00302350","0.00000000"],["0.00299950","66.56000000"]],"a":[["0.00303310","0.00000000"],["0.00303320","0.00000000"],["0.00303380","8.24000000"],["0.00303450","0.00000000"],["0.00303460","0.00000000"],["0.00303490","27.20000000"],["0.00304670","0.00000000"]]},{"e":"depthUpdate","E":1557446207091,"s":"BNBBTC","U":264204201,"u":264204230,"b":[["0.00303170","3.96000000"],["0.00303150","0.00000000"],["0.00302520","2.33000000"],["0.00302510","86.12000000"],["0.00302500","78.00000000"],["0.00302490","9.84000000"],["0.00302480","65.25000000"],["0.00302470","0.00000000"],["0.00302440","0.00000000"]],"a":[["0.00303380","0.00000000"],["0.00303390","106.68000000"],["0.00303520","0.00000000"],["0.00303780","146.68000000"],["0.00303820","0.00000000"],["0.00304600","63.23000000"],["0.00304760","156.25000000"]]},{"e":"depthUpdate","E":1557446208092,"s":"BNBBTC","U":264204231,"u":264204276,"b":[["0.00303160","0.00000000"],["0.00303020","8.24000000"],["0.00302540","6.16000000"],["0.00302530","82.73000000"],["0.00302520","131.26000000"],["0.00302510","0.00000000"],["0.00302490","0.00000000"],["0.00302460","0.00000000"]],"a":[["0.00303380","25.76000000"],["0.00303490","1.00000000"],["0.00303950","0.00000000"],["0.00304180","74.76000000"]]},{"e":"depthUpdate","E":1557446209091,"s":"BNBBTC","U":264204277,"u":264204299,"b":[["0.00303170","0.00000000"],["0.00303040","1.98000000"],["0.00302530","82.73000000"],["0.00302510","0.00000000"]],"a":[["0.00306200","50.02000000"]]},{"e":"depthUpdate","E":1557446210091,"s":"BNBBTC","U":264204300,"u":264204334,"b":[["0.00302560","3.40000000"],["0.00302550","85.55000000"],["0.00302540","64.88000000"],["0.00302530","0.00000000"],["0.00302510","0.00000000"],["0.00302180","0.00000000"]],"a":[["0.00303770","909.72000000"],["0.00303790","0.00000000"],["0.00303800","193.51000000"]]},{"e":"depthUpdate","E":1557446211091,"s":"BNBBTC","U":264204335,"u":264204358,"b":[["0.00302550","85.55000000"],["0.00302530","0.00000000"],["0.00300490","50.65000000"],["0.00300030","0.00000000"]],"a":[["0.00303390","106.68000000"]]},{"e":"depthUpdate","E":1557446212091,"s":"BNBBTC","U":264204359,"u":264204382,"b":[["0.00303060","8.24000000"],["0.00303050","27.76000000"],["0.00303020","0.00000000"],["0.00303010","0.00000000"],["0.00302550","85.55000000"],["0.00302530","9.84000000"]],"a":[]},{"e":"depthUpdate","E":1557446213091,"s":"BNBBTC","U":264204383,"u":264204410,"b":[["0.00303080","1.47000000"],["0.00303040","0.00000000"],["0.00302960","20.00000000"],["0.00302810","3.84000000"],["0.00302580","3.40000000"],["0.00302570","85.54000000"],["0.00302560","74.71000000"],["0.00302550","9.84000000"],["0.00302530","0.00000000"],["0.00302510","0.00000000"],["0.00302500","0.00000000"]],"a":[]},{"e":"depthUpdate","E":1557446214091,"s":"BNBBTC","U":264204411,"u":264204427,"b":[["0.00302820","38.36000000"],["0.00302590","85.54000000"],["0.00302580","123.40000000"],["0.00302570","9.84000000"],["0.00302550","0.00000000"],["0.00302540","564.88000000"],["0.00302520","0.00000000"],["0.00302250","0.00000000"]],"a":[]},{"e":"depthUpdate","E":1557446215092,"s":"BNBBTC","U":264204428,"u":264204433,"b":[["0.00303070","0.00000000"],["0.00302610","3.40000000"],["0.00302600","9.84000000"],["0.00302580","120.00000000"],["0.00302570","0.00000000"]],"a":[]},{"e":"depthUpdate","E":1557446216092,"s":"BNBBTC","U":264204434,"u":264204435,"b":[["0.00300040","0.00000000"],["0.00294970","43.63000000"]],"a":[]},{"e":"depthUpdate","E":1557446217093,"s":"BNBBTC","U":264204436,"u":264204437,"b":[["0.00300020","189.91000000"],["0.00295500","141.74000000"]],"a":[]},{"e":"depthUpdate","E":1557446218093,"s":"BNBBTC","U":264204438,"u":264204440,"b":[],"a":[["0.00303770","4.25000000"],["0.00303990","905.29000000"],["0.00306200","0.00000000"]]},{"e":"depthUpdate","E":1557446219093,"s":"BNBBTC","U":264204441,"u":264204444,"b":[["0.00302540","64.88000000"],["0.00300930","0.00000000"],["0.00300910","0.49000000"],["0.00298280","0.00000000"]],"a":[]},{"e":"depthUpdate","E":1557446220093,"s":"BNBBTC","U":264204445,"u":264204462,"b":[["0.00303090","8.24000000"],["0.00303080","24.44000000"],["0.00303070","0.00000000"],["0.00303060","0.00000000"],["0.00302630","3.40000000"],["0.00302620","2.78000000"],["0.00302610","92.60000000"],["0.00302600","75.15000000"],["0.00302590","0.00000000"],["0.00301820","84.42000000"]],"a":[]},{"e":"depthUpdate","E":1557446221093,"s":"BNBBTC","U":264204463,"u":264204492,"b":[["0.00303130","8.24000000"],["0.00303120","24.44000000"],["0.00303090","0.00000000"],["0.00303080","0.00000000"],["0.00302820","0.00000000"],["0.00302630","0.00000000"],["0.00302620","6.17000000"],["0.00302610","82.76000000"],["0.00301940","0.00000000"],["0.00301830","9.84000000"],["0.00300490","0.65000000"],["0.00300030","50.00000000"],["0.00298260","16.73000000"],["0.00298150","0.00000000"]],"a":[["0.00304900","0.00000000"]]},{"e":"depthUpdate","E":1557446222094,"s":"BNBBTC","U":264204493,"u":264204528,"b":[["0.00303160","8.24000000"],["0.00303150","22.70000000"],["0.00303130","0.00000000"],["0.00303120","0.00000000"],["0.00302960","0.00000000"],["0.00302640","16.03000000"],["0.00302630","82.74000000"],["0.00302620","343.10000000"],["0.00302610","0.00000000"],["0.00302580","0.00000000"],["0.00302560","0.00000000"],["0.00302480","0.00000000"],["0.00301830","0.00000000"],["0.00301820","10.00000000"],["0.00301800","0.00000000"],["0.00299580","3.77000000"],["0.00299410","0.00000000"]],"a":[["0.00303380","0.00000000"],["0.00303490","26.76000000"],["0.00303700","20.00000000"],["0.00303800","173.51000000"],["0.00304440","27.83000000"]]},{"e":"depthUpdate","E":1557446223095,"s":"BNBBTC","U":264204529,"u":264204536,"b":[["0.00303190","8.24000000"],["0.00303180","17.83000000"],["0.00303160","0.00000000"],["0.00303150","0.00000000"],["0.00303060","9.85000000"],["0.00302640","6.19000000"],["0.00299480","0.00000000"]],"a":[["0.00303490","288.15000000"]]},{"e":"depthUpdate","E":1557446224094,"s":"BNBBTC","U":264204537,"u":264204554,"b":[["0.00303200","5.03000000"],["0.00303180","0.00000000"],["0.00302870","20.00000000"],["0.00302660","6.19000000"],["0.00302650","82.73000000"],["0.00302640","130.93000000"],["0.00302630","0.00000000"],["0.00302620","217.47000000"],["0.00299710","0.74000000"],["0.00299410","0.50000000"]],"a":[["0.00303380","25.76000000"],["0.00303490","262.39000000"],["0.00303770","909.78000000"],["0.00303990","0.00000000"],["0.00306130","54.64000000"]]},{"e":"depthUpdate","E":1557446225094,"s":"BNBBTC","U":264204555,"u":264204565,"b":[["0.00303190","0.00000000"],["0.00303070","8.24000000"],["0.00303060","0.00000000"],["0.00302660","16.46000000"],["0.00300270","0.00000000"],["0.00299970","0.50000000"],["0.00299890","2.14000000"],["0.00299660","0.50000000"]],"a":[["0.00303380","25.33000000"]]},{"e":"depthUpdate","E":1557446226094,"s":"BNBBTC","U":264204566,"u":264204573,"b":[["0.00303200","0.00000000"],["0.00303090","5.03000000"],["0.00302490","500.00000000"],["0.00300260","20.30000000"],["0.00299960","3.34000000"],["0.00299650","10.06000000"],["0.00299590","4.28000000"],["0.00299530","0.00000000"]],"a":[]},{"e":"depthUpdate","E":1557446227094,"s":"BNBBTC","U":264204574,"u":264204575,"b":[["0.00300220","2.14000000"],["0.00299980","0.00000000"]],"a":[]},{"e":"depthUpdate","E":1557446228094,"s":"BNBBTC","U":264204576,"u":264204589,"b":[["0.00303090","0.00000000"],["0.00303070","4.90000000"],["0.00302820","28.66000000"],["0.00302660","16.46000000"],["0.00300040","183.30000000"],["0.00300020","6.59000000"]],"a":[["0.00303380","95.33000000"],["0.00303580","21.38000000"]]},{"e":"depthUpdate","E":1557446229094,"s":"BNBBTC","U":264204590,"u":264204612,"b":[["0.00303070","0.00000000"],["0.00303060","8.24000000"],["0.00302900","0.00000000"],["0.00302820","0.00000000"],["0.00302670","3.40000000"],["0.00302660","13.06000000"],["0.00297110","0.00000000"]],"a":[["0.00306130","0.00000000"]]},{"e":"depthUpdate","E":1557446230094,"s":"BNBBTC","U":264204613,"u":264204614,"b":[["0.00297220","26.56000000"]],"a":[["0.00303390","117.35000000"]]},{"e":"depthUpdate","E":1557446231094,"s":"BNBBTC","U":264204615,"u":264204620,"b":[["0.00300490","50.65000000"],["0.00300030","0.00000000"]],"a":[["0.00303630","157.91000000"],["0.00304190","0.00000000"],["0.00304610","0.00000000"]]},{"e":"depthUpdate","E":1557446232094,"s":"BNBBTC","U":264204621,"u":264204630,"b":[["0.00302680","82.85000000"],["0.00302670","92.83000000"],["0.00302660","9.84000000"],["0.00302650","0.00000000"],["0.00299180","1.66000000"],["0.00299170","0.00000000"]],"a":[["0.00303370","5.94000000"],["0.00303380","182.47000000"],["0.00303600","20.00000000"],["0.00303700","0.00000000"]]},{"e":"depthUpdate","E":1557446233094,"s":"BNBBTC","U":264204631,"u":264204659,"b":[["0.00303080","8.24000000"],["0.00303070","32.81000000"],["0.00303060","0.00000000"],["0.00303050","0.00000000"],["0.00302870","0.00000000"],["0.00302820","0.00000000"],["0.00302700","0.00000000"],["0.00302690","0.00000000"],["0.00302680","0.00000000"],["0.00302670","0.00000000"],["0.00302660","3.24000000"],["0.00302650","92.70000000"],["0.00296890","16.61000000"],["0.00296800","0.00000000"]],"a":[["0.00303380","189.67000000"],["0.00303390","106.68000000"],["0.00303760","23.00000000"],["0.00303780","123.68000000"],["0.00306050","50.68000000"],["0.00310000","32.84000000"],["0.00393310","1.96000000"]]},{"e":"depthUpdate","E":1557446234094,"s":"BNBBTC","U":264204660,"u":264204676,"b":[["0.00302870","20.00000000"],["0.00302820","0.00000000"],["0.00302690","3.40000000"],["0.00302680","3.24000000"],["0.00302670","92.70000000"],["0.00302660","141.37000000"],["0.00302650","0.00000000"],["0.00302620","76.71000000"],["0.00301270","1.89000000"]],"a":[]},{"e":"depthUpdate","E":1557446235095,"s":"BNBBTC","U":264204677,"u":264204700,"b":[["0.00302870","0.00000000"],["0.00302820","0.00000000"],["0.00302700","13.09000000"],["0.00302690","92.70000000"],["0.00302680","127.76000000"],["0.00302670","0.00000000"],["0.00302640","0.00000000"],["0.00299630","0.00000000"],["0.00299500","0.00000000"]],"a":[["0.00303370","0.00000000"],["0.00303380","183.22000000"],["0.00303500","0.00000000"],["0.00307780","0.00000000"]]},{"e":"depthUpdate","E":1557446236095,"s":"BNBBTC","U":264204701,"u":264204704,"b":[["0.00299310","20.64000000"]],"a":[["0.00303570","81.84000000"],["0.00304180","0.00000000"],["0.00306050","0.00000000"]]},{"e":"depthUpdate","E":1557446237095,"s":"BNBBTC","U":264204705,"u":264204716,"b":[["0.00302990","9.69000000"],["0.00302980","20.00000000"],["0.00302820","3.40000000"],["0.00302710","0.00000000"],["0.00302700","0.00000000"],["0.00302690","220.20000000"],["0.00299420","0.00000000"]],"a":[["0.00307970","0.00000000"]]},{"e":"depthUpdate","E":1557446238095,"s":"BNBBTC","U":264204717,"u":264204733,"b":[["0.00302990","0.00000000"],["0.00302980","0.00000000"],["0.00302820","0.00000000"],["0.00302710","3.40000000"],["0.00302700","9.69000000"],["0.00302690","172.02000000"],["0.00301800","330.00000000"],["0.00301700","0.00000000"],["0.00299090","12.06000000"]],"a":[["0.00303380","176.02000000"],["0.00303720","906.59000000"],["0.00303770","4.25000000"],["0.00305000","452.93000000"],["0.00305100","101.36000000"]]},{"e":"depthUpdate","E":1557446239095,"s":"BNBBTC","U":264204734,"u":264204742,"b":[["0.00302880","9.69000000"],["0.00302870","20.00000000"],["0.00302820","3.40000000"],["0.00302710","0.00000000"],["0.00302700","0.00000000"],["0.00300040","0.00000000"],["0.00300020","189.91000000"]],"a":[["0.00303380","204.16000000"],["0.00307910","0.35000000"]]},{"e":"depthUpdate","E":1557446240095,"s":"BNBBTC","U":264204743,"u":264204743,"b":[],"a":[["0.00303380","203.16000000"]]},{"e":"depthUpdate","E":1557446241095,"s":"BNBBTC","U":264204744,"u":264204745,"b":[["0.00302880","10.69000000"]],"a":[]},{"e":"depthUpdate","E":1557446243095,"s":"BNBBTC","U":264204746,"u":264204750,"b":[],"a":[["0.00304210","0.00000000"],["0.00304540","0.00000000"],["0.00304580","0.00000000"],["0.00304700","100.00000000"],["0.00305100","1.36000000"]]},{"e":"depthUpdate","E":1557446244095,"s":"BNBBTC","U":264204751,"u":264204753,"b":[["0.00301810","798.17000000"],["0.00301720","0.00000000"]],"a":[["0.00304260","13.18000000"]]},{"e":"depthUpdate","E":1557446245095,"s":"BNBBTC","U":264204754,"u":264204766,"b":[["0.00303080","0.00000000"],["0.00303070","0.00000000"],["0.00302900","21.49000000"],["0.00302880","0.00000000"],["0.00302820","0.00000000"],["0.00302700","10.70000000"],["0.00302690","162.17000000"]],"a":[["0.00303370","3.85000000"],["0.00304580","26.36000000"],["0.00304600","163.23000000"],["0.00304700","0.00000000"]]},{"e":"depthUpdate","E":1557446246095,"s":"BNBBTC","U":264204767,"u":264204827,"b":[["0.00303000","8.24000000"],["0.00302990","13.25000000"],["0.00302980","0.00000000"],["0.00302970","0.00000000"],["0.00302960","0.00000000"],["0.00302950","0.00000000"],["0.00302940","0.00000000"],["0.00302930","0.00000000"],["0.00302920","2.39000000"],["0.00302910","37.45000000"],["0.00302900","0.00000000"],["0.00302880","0.00000000"],["0.00302720","93.59000000"],["0.00302710","129.40000000"],["0.00302700","0.00000000"],["0.00302690","0.00000000"],["0.00302680","0.00000000"],["0.00301800","0.00000000"],["0.00301700","330.00000000"],["0.00296880","23.53000000"],["0.00296770","1.01000000"]],"a":[["0.00303350","21.73000000"],["0.00303360","28.51000000"],["0.00303370","65.18000000"],["0.00303380","157.14000000"],["0.00303480","129.87000000"],["0.00303560","21.39000000"],["0.00303580","0.00000000"],["0.00303780","0.00000000"],["0.00304600","100.00000000"]]},{"e":"depthUpdate","E":1557446247096,"s":"BNBBTC","U":264204828,"u":264204839,"b":[["0.00303010","0.00000000"],["0.00302990","0.00000000"],["0.00302930","3.40000000"],["0.00302880","9.85000000"]],"a":[["0.00303330","21.73000000"],["0.00303340","24.57000000"],["0.00303350","0.00000000"],["0.00303360","0.00000000"]]},{"e":"depthUpdate","E":1557446248096,"s":"BNBBTC","U":264204840,"u":264204858,"b":[["0.00303020","8.24000000"],["0.00303010","14.60000000"],["0.00303000","0.00000000"],["0.00302930","0.00000000"],["0.00302880","0.00000000"],["0.00302870","0.00000000"],["0.00302820","0.00000000"],["0.00302790","3.40000000"],["0.00302780","9.85000000"],["0.00302770","20.00000000"]],"a":[["0.00303310","21.73000000"],["0.00303320","17.88000000"],["0.00303330","0.00000000"],["0.00303340","0.00000000"],["0.00303480","149.87000000"],["0.00303600","0.00000000"]]},{"e":"depthUpdate","E":1557446249095,"s":"BNBBTC","U":264204859,"u":264204865,"b":[],"a":[["0.00303290","3.85000000"],["0.00303300","17.88000000"],["0.00303310","0.00000000"],["0.00303320","0.00000000"],["0.00303360","17.88000000"],["0.00307360","27.01000000"]]},{"e":"depthUpdate","E":1557446250095,"s":"BNBBTC","U":264204866,"u":264204880,"b":[["0.00302910","0.00000000"],["0.00302790","0.00000000"],["0.00302780","10.69000000"],["0.00302740","3.40000000"],["0.00302730","9.85000000"],["0.00302720","82.89000000"]],"a":[["0.00303270","3.85000000"],["0.00303280","0.00000000"],["0.00303290","0.00000000"],["0.00303300","0.00000000"],["0.00304600","0.00000000"],["0.00304900","100.00000000"],["0.00307280","0.40000000"]]},{"e":"depthUpdate","E":1557446251095,"s":"BNBBTC","U":264204881,"u":264204909,"b":[["0.00303040","6.07000000"],["0.00302920","0.00000000"],["0.00302820","0.00000000"],["0.00302780","10.69000000"],["0.00302740","0.00000000"],["0.00302730","3.40000000"],["0.00302720","9.85000000"],["0.00301810","0.00000000"],["0.00301720","798.17000000"],["0.00300490","0.65000000"],["0.00300030","50.00000000"],["0.00298980","0.00000000"]],"a":[["0.00303260","8.24000000"],["0.00303270","70.00000000"],["0.00303350","0.00000000"],["0.00303380","87.14000000"],["0.00303480","129.87000000"],["0.00303720","926.59000000"],["0.00304150","13.18000000"],["0.00304900","0.00000000"],["0.00305100","101.36000000"]]},{"e":"depthUpdate","E":1557446252095,"s":"BNBBTC","U":264204910,"u":264204910,"b":[["0.00299080","3.23000000"]],"a":[]},{"e":"depthUpdate","E":1557446253095,"s":"BNBBTC","U":264204911,"u":264204918,"b":[["0.00303050","8.24000000"],["0.00303040","76.07000000"],["0.00303020","0.00000000"]],"a":[["0.00303260","0.00000000"],["0.00303270","0.00000000"],["0.00303360","0.00000000"],["0.00303370","27.37000000"],["0.00303480","188.35000000"]]},{"e":"depthUpdate","E":1557446254095,"s":"BNBBTC","U":264204919,"u":264204941,"b":[["0.00303080","3.40000000"],["0.00303070","1.95000000"],["0.00303050","8.24000000"],["0.00303040","70.00000000"],["0.00302820","0.00000000"],["0.00302780","0.00000000"],["0.00302740","9.85000000"],["0.00302730","28.57000000"],["0.00302720","82.86000000"],["0.00302000","162.00000000"],["0.00301700","0.00000000"]],"a":[["0.00303370","0.00000000"],["0.00303760","0.00000000"],["0.00304150","0.00000000"],["0.00304750","22.99000000"]]},{"e":"depthUpdate","E":1557446255095,"s":"BNBBTC","U":264204942,"u":264204952,"b":[["0.00303110","3.40000000"],["0.00303100","8.24000000"],["0.00303090","11.77000000"],["0.00303080","0.00000000"],["0.00303050","0.00000000"],["0.00300970","0.00000000"],["0.00300920","0.49000000"]],"a":[["0.00303480","58.48000000"],["0.00304750","83.21000000"],["0.00305000","552.93000000"],["0.00305100","1.36000000"]]},{"e":"depthUpdate","E":1557446256095,"s":"BNBBTC","U":264204953,"u":264204955,"b":[["0.00302100","170.00000000"],["0.00302000","2.00000000"]],"a":[["0.00303710","127.66000000"]]},{"e":"depthUpdate","E":1557446257095,"s":"BNBBTC","U":264204956,"u":264204963,"b":[["0.00303130","3.40000000"],["0.00303120","3.77000000"],["0.00303110","0.00000000"],["0.00303070","0.00000000"],["0.00302100","10.00000000"],["0.00301700","160.00000000"]],"a":[["0.00303720","21.00000000"],["0.00303790","905.53000000"]]},{"e":"depthUpdate","E":1557446258095,"s":"BNBBTC","U":264204964,"u":264204967,"b":[["0.00303140","3.77000000"],["0.00303130","0.00000000"],["0.00303120","0.00000000"],["0.00302750","3.40000000"]],"a":[]},{"e":"depthUpdate","E":1557446259095,"s":"BNBBTC","U":264204968,"u":264204969,"b":[["0.00303090","0.00000000"],["0.00298400","1.49000000"]],"a":[]},{"e":"depthUpdate","E":1557446260095,"s":"BNBBTC","U":264204970,"u":264204974,"b":[["0.00303100","0.00000000"],["0.00303050","8.24000000"],["0.00300020","6.59000000"],["0.00295650","0.00000000"],["0.00295600","21.85000000"]],"a":[]},{"e":"depthUpdate","E":1557446261095,"s":"BNBBTC","U":264204975,"u":264204981,"b":[["0.00303140","0.00000000"],["0.00303080","3.40000000"],["0.00303070","3.44000000"],["0.00303060","0.00000000"],["0.00302750","0.00000000"],["0.00300040","183.30000000"]],"a":[]},{"e":"depthUpdate","E":1557446262095,"s":"BNBBTC","U":264204982,"u":264204990,"b":[["0.00303100","3.44000000"],["0.00303080","0.00000000"],["0.00303070","0.00000000"],["0.00302750","3.40000000"]],"a":[["0.00303380","0.00000000"],["0.00303390","58.66000000"],["0.00303480","0.00000000"],["0.00303570","140.32000000"]]},{"e":"depthUpdate","E":1557446263096,"s":"BNBBTC","U":264204991,"u":264205007,"b":[["0.00303130","3.40000000"],["0.00303120","8.24000000"],["0.00303110","11.77000000"],["0.00303060","0.00000000"],["0.00303050","0.00000000"],["0.00302820","74.45000000"],["0.00302780","38.41000000"],["0.00302750","0.00000000"],["0.00302740","0.00000000"],["0.00302730","63.89000000"],["0.00302720","0.00000000"],["0.00302660","0.00000000"]],"a":[["0.00303390","43.10000000"]]},{"e":"depthUpdate","E":1557446264096,"s":"BNBBTC","U":264205008,"u":264205022,"b":[["0.00303160","11.64000000"],["0.00303150","21.32000000"],["0.00303130","0.00000000"],["0.00303120","0.00000000"],["0.00303100","0.00000000"],["0.00303050","28.56000000"],["0.00302900","9.85000000"],["0.00302830","186.31000000"],["0.00302780","0.00000000"],["0.00302740","82.83000000"],["0.00302710","0.00000000"],["0.00302540","0.00000000"]],"a":[]},{"e":"depthUpdate","E":1557446265096,"s":"BNBBTC","U":264205023,"u":264205040,"b":[["0.00303200","3.40000000"],["0.00303190","8.24000000"],["0.00303180","22.08000000"],["0.00303160","70.00000000"],["0.00303150","0.00000000"],["0.00303050","0.00000000"],["0.00303040","0.00000000"],["0.00302900","9.85000000"],["0.00302840","111.38000000"],["0.00302740","0.00000000"]],"a":[["0.00303390","27.14000000"],["0.00303790","0.00000000"],["0.00304750","988.50000000"]]},{"e":"depthUpdate","E":1557446266097,"s":"BNBBTC","U":264205041,"u":264205047,"b":[["0.00303220","0.00000000"],["0.00303210","21.02000000"],["0.00303200","0.00000000"],["0.00303180","0.00000000"]],"a":[["0.00303380","15.14000000"],["0.00303570","58.48000000"]]},{"e":"depthUpdate","E":1557446267096,"s":"BNBBTC","U":264205048,"u":264205054,"b":[["0.00303110","0.00000000"],["0.00302910","3.40000000"],["0.00302490","0.00000000"],["0.00301130","2.13000000"]],"a":[["0.00303380","15.14000000"],["0.00304220","78.81000000"]]},{"e":"depthUpdate","E":1557446269096,"s":"BNBBTC","U":264205055,"u":264205060,"b":[["0.00300550","3.59000000"],["0.00294930","0.00000000"],["0.00294900","0.40000000"]],"a":[["0.00304260","0.00000000"],["0.00304580","0.00000000"]]},{"e":"depthUpdate","E":1557446270096,"s":"BNBBTC","U":264205061,"u":264205067,"b":[["0.00303220","3.40000000"],["0.00303190","14.83000000"],["0.00303170","14.60000000"],["0.00303010","0.00000000"],["0.00302910","0.00000000"]],"a":[["0.00303380","0.00000000"],["0.00304260","13.18000000"]]},{"e":"depthUpdate","E":1557446271096,"s":"BNBBTC","U":264205068,"u":264205086,"b":[["0.00303230","28.29000000"],["0.00303220","0.00000000"],["0.00303210","0.00000000"],["0.00303200","3.40000000"],["0.00302980","20.00000000"],["0.00302900","0.00000000"],["0.00302860","121.20000000"],["0.00302850","77.81000000"],["0.00302840","0.00000000"],["0.00302770","0.00000000"],["0.00302600","0.00000000"],["0.00300490","50.65000000"],["0.00300030","0.00000000"]],"a":[["0.00303710","0.00000000"],["0.00304590","36.96000000"]]},{"e":"depthUpdate","E":1557446272097,"s":"BNBBTC","U":264205087,"u":264205088,"b":[["0.00303240","11.77000000"]],"a":[["0.00304580","124.94000000"]]},{"e":"depthUpdate","E":1557446273096,"s":"BNBBTC","U":264205089,"u":264205099,"b":[["0.00303250","0.00000000"],["0.00303240","0.00000000"],["0.00303230","0.00000000"],["0.00303200","0.00000000"],["0.00302980","0.00000000"],["0.00302900","13.25000000"],["0.00302860","111.36000000"],["0.00302800","20.00000000"],["0.00292510","0.00000000"]],"a":[["0.00303210","0.00000000"]]},{"e":"depthUpdate","E":1557446274096,"s":"BNBBTC","U":264205100,"u":264205108,"b":[["0.00303200","8.24000000"],["0.00303190","6.59000000"],["0.00303180","0.00000000"],["0.00301140","1.60000000"],["0.00300950","0.00000000"],["0.00292490","2.20000000"]],"a":[["0.00304570","905.09000000"],["0.00304750","83.21000000"]]},{"e":"depthUpdate","E":1557446275096,"s":"BNBBTC","U":264205109,"u":264205113,"b":[["0.00296450","0.00000000"],["0.00294050","15.95000000"],["0.00293930","0.00000000"]],"a":[["0.00304430","22.99000000"],["0.00304750","60.22000000"]]},{"e":"depthUpdate","E":1557446277096,"s":"BNBBTC","U":264205114,"u":264205116,"b":[],"a":[["0.00304260","0.00000000"],["0.00304590","10.60000000"]]},{"e":"depthUpdate","E":1557446278097,"s":"BNBBTC","U":264205117,"u":264205126,"b":[["0.00303210","3.40000000"],["0.00302920","111.37000000"],["0.00302910","128.45000000"],["0.00302900","9.85000000"],["0.00302860","0.00000000"],["0.00302830","64.48000000"]],"a":[["0.00304590","36.96000000"]]},{"e":"depthUpdate","E":1557446279097,"s":"BNBBTC","U":264205127,"u":264205127,"b":[["0.00301320","1.96000000"]],"a":[]},{"e":"depthUpdate","E":1557446280097,"s":"BNBBTC","U":264205128,"u":264205134,"b":[["0.00303210","0.00000000"],["0.00303200","0.00000000"],["0.00303190","0.00000000"],["0.00303170","0.00000000"],["0.00303160","0.00000000"],["0.00302920","0.00000000"],["0.00302910","0.00000000"],["0.00302900","0.00000000"],["0.00302890","0.00000000"],["0.00302850","0.00000000"],["0.00302830","0.00000000"],["0.00302820","0.00000000"],["0.00302810","0.00000000"],["0.00302800","0.00000000"],["0.00302730","0.00000000"],["0.00302620","0.00000000"],["0.00302170","98.39000000"],["0.00301320","4.02000000"]],"a":[["0.00303390","24.60000000"],["0.00303620","70.78000000"],["0.00303640","0.00000000"],["0.00304270","13.18000000"],["0.00316000","151.84000000"]]},{"e":"depthUpdate","E":1557446281097,"s":"BNBBTC","U":264205135,"u":264205210,"b":[["0.00302910","8.24000000"],["0.00302900","0.00000000"],["0.00302740","0.00000000"],["0.00302290","15.75000000"],["0.00302190","5.00000000"],["0.00302180","1179.01000000"],["0.00302170","121.60000000"],["0.00301730","182.23000000"],["0.00301720","0.00000000"],["0.00301700","0.00000000"],["0.00301240","79.21000000"],["0.00300490","0.65000000"],["0.00300340","6.69000000"],["0.00300260","13.61000000"],["0.00300240","18.47000000"],["0.00300050","800.66000000"],["0.00300030","3.33000000"],["0.00300010","95.99000000"],["0.00299960","0.00000000"],["0.00299940","19.97000000"],["0.00299650","0.00000000"],["0.00299270","50.12000000"],["0.00294700","54.14000000"],["0.00294120","169.84000000"],["0.00275900","361.81000000"]],"a":[["0.00303320","3.40000000"],["0.00303330","125.07000000"],["0.00303340","221.49000000"],["0.00303350","0.00000000"],["0.00303360","0.00000000"],["0.00303370","0.00000000"],["0.00303380","57.90000000"],["0.00303390","94.60000000"],["0.00303480","267.50000000"],["0.00303560","0.00000000"],["0.00303570","0.00000000"],["0.00303630","0.00000000"],["0.00303720","926.59000000"],["0.00304220","0.00000000"],["0.00304570","0.00000000"],["0.00304580","0.00000000"],["0.00304750","0.00000000"]]},{"e":"depthUpdate","E":1557446282097,"s":"BNBBTC","U":264205211,"u":264205276,"b":[["0.00302950","8.24000000"],["0.00302940","10.51000000"],["0.00302910","0.00000000"],["0.00302300","72.26000000"],["0.00302290","0.00000000"],["0.00302190","0.00000000"],["0.00302180","4.36000000"],["0.00302010","882.49000000"],["0.00301730","121.81000000"],["0.00301500","173.79000000"],["0.00301240","233.56000000"],["0.00300240","1.84000000"],["0.00300040","0.00000000"],["0.00299940","0.00000000"],["0.00299730","10.05000000"],["0.00299320","183.74000000"],["0.00294700","0.00000000"],["0.00275900","0.00000000"]],"a":[["0.00303260","17.10000000"],["0.00303270","0.00000000"],["0.00303280","0.00000000"],["0.00303290","0.00000000"],["0.00303300","28.55000000"],["0.00303310","113.25000000"],["0.00303320","191.70000000"],["0.00303330","0.00000000"],["0.00303480","77.25000000"],["0.00303720","1003.64000000"],["0.00303990","79.32000000"]]},{"e":"depthUpdate","E":1557446283097,"s":"BNBBTC","U":264205277,"u":264205347,"b":[["0.00302990","0.00000000"],["0.00302980","0.00000000"],["0.00302970","0.00000000"],["0.00302950","0.00000000"],["0.00302940","0.00000000"],["0.00302410","72.26000000"],["0.00302400","15.45000000"],["0.00302390","0.00000000"],["0.00302380","0.00000000"],["0.00302310","0.00000000"],["0.00302300","0.00000000"],["0.00302190","5.00000000"],["0.00302010","0.00000000"]],"a":[["0.00303200","7.25000000"],["0.00303210","0.00000000"],["0.00303220","0.00000000"],["0.00303230","0.00000000"],["0.00303240","38.40000000"],["0.00303250","82.82000000"],["0.00303260","99.86000000"],["0.00303290","0.00000000"],["0.00303300","0.00000000"],["0.00303310","0.00000000"],["0.00303320","126.56000000"],["0.00303390","24.60000000"]]},{"e":"depthUpdate","E":1557446284097,"s":"BNBBTC","U":264205348,"u":264205383,"b":[["0.00302550","72.26000000"],["0.00302540","72.26000000"],["0.00302530","0.00000000"],["0.00302520","37.45000000"],["0.00302510","0.00000000"],["0.00302500","0.00000000"],["0.00302490","0.00000000"],["0.00302480","3.03000000"],["0.00302420","0.00000000"],["0.00302410","0.00000000"],["0.00302190","0.00000000"],["0.00301740","60.36000000"],["0.00301710","0.00000000"],["0.00294120","0.34000000"]],"a":[["0.00303190","3.40000000"],["0.00303200","42.25000000"],["0.00303210","29.06000000"],["0.00303230","82.82000000"],["0.00303240","59.99000000"],["0.00303250","0.00000000"],["0.00303260","70.00000000"],["0.00303610","20.00000000"],["0.00303720","983.64000000"],["0.00304080","14.55000000"],["0.00304760","0.00000000"]]},{"e":"depthUpdate","E":1557446285097,"s":"BNBBTC","U":264205384,"u":264205413,"b":[["0.00302600","17.63000000"],["0.00302560","72.26000000"],["0.00302550","0.00000000"],["0.00302540","0.00000000"],["0.00302480","0.00000000"],["0.00302400","0.00000000"],["0.00302180","0.00000000"],["0.00301380","256.81000000"]],"a":[["0.00303140","3.40000000"],["0.00303150","3.85000000"],["0.00303160","9.85000000"],["0.00303170","28.55000000"],["0.00303180","29.96000000"],["0.00303190","0.00000000"],["0.00303200","0.00000000"],["0.00303230","0.00000000"],["0.00303240","0.00000000"],["0.00303250","82.82000000"],["0.00303340","84.53000000"],["0.00303380","21.40000000"],["0.00304400","160.73000000"]]},{"e":"depthUpdate","E":1557446286098,"s":"BNBBTC","U":264205414,"u":264205453,"b":[["0.00302660","0.00000000"],["0.00302650","0.25000000"],["0.00302600","0.00000000"],["0.00302560","0.00000000"],["0.00301940","655.84000000"],["0.00300490","50.77000000"],["0.00299270","0.00000000"]],"a":[["0.00303090","3.40000000"],["0.00303100","125.07000000"],["0.00303110","129.47000000"],["0.00303120","0.00000000"],["0.00303130","0.00000000"],["0.00303140","70.00000000"],["0.00303150","0.00000000"],["0.00303160","7.49000000"],["0.00303170","0.00000000"],["0.00303240","64.93000000"],["0.00303250","0.00000000"],["0.00303260","0.00000000"],["0.00303340","0.00000000"],["0.00326000","751.43000000"]]},{"e":"depthUpdate","E":1557446287097,"s":"BNBBTC","U":264205454,"u":264205467,"b":[["0.00302650","0.00000000"],["0.00302580","72.26000000"],["0.00302570","2.76000000"],["0.00302530","0.00000000"],["0.00302050","4.36000000"],["0.00301420","799.94000000"],["0.00300050","0.00000000"]],"a":[["0.00303490","282.39000000"],["0.00303610","0.00000000"],["0.00303640","906.52000000"],["0.00303720","78.05000000"],["0.00308620","1.79000000"],["0.00308820","0.00000000"]]},{"e":"depthUpdate","E":1557446288098,"s":"BNBBTC","U":264205468,"u":264205474,"b":[["0.00302630","3.05000000"],["0.00302580","0.00000000"],["0.00302570","0.00000000"],["0.00302520","0.00000000"],["0.00302180","5.00000000"],["0.00298340","0.00000000"]],"a":[["0.00303240","0.00000000"]]},{"e":"depthUpdate","E":1557446289098,"s":"BNBBTC","U":264205475,"u":264205532,"b":[["0.00302630","0.00000000"],["0.00302340","56.50000000"],["0.00302330","79.09000000"],["0.00302320","0.00000000"],["0.00302310","37.45000000"],["0.00302300","0.00000000"],["0.00302290","0.00000000"],["0.00302280","0.00000000"],["0.00302270","0.00000000"],["0.00302260","5.18000000"],["0.00302210","0.00000000"],["0.00302200","15.46000000"],["0.00302190","0.00000000"],["0.00302180","0.00000000"],["0.00301940","0.00000000"],["0.00301410","16.07000000"],["0.00301230","1.66000000"],["0.00297730","0.50000000"]],"a":[["0.00303050","126.62000000"],["0.00303060","77.04000000"],["0.00303070","0.00000000"],["0.00303080","0.00000000"],["0.00303090","265.94000000"],["0.00303100","0.00000000"],["0.00303180","0.00000000"],["0.00303320","0.00000000"],["0.00303480","0.00000000"]]},{"e":"depthUpdate","E":1557446290098,"s":"BNBBTC","U":264205533,"u":264205567,"b":[["0.00302470","56.50000000"],["0.00302460","56.50000000"],["0.00302450","0.00000000"],["0.00302440","0.00000000"],["0.00302430","0.00000000"],["0.00302420","0.00000000"],["0.00302410","5.18000000"],["0.00302350","0.00000000"],["0.00302340","0.00000000"],["0.00302330","0.00000000"],["0.00302260","0.00000000"],["0.00300920","284.61000000"],["0.00300620","406.49000000"]],"a":[["0.00303030","126.62000000"],["0.00303040","62.18000000"],["0.00303050","0.00000000"],["0.00303090","0.00000000"],["0.00303110","0.00000000"],["0.00303160","0.00000000"],["0.00303930","13.19000000"]]},{"e":"depthUpdate","E":1557446291098,"s":"BNBBTC","U":264205568,"u":264205649,"b":[["0.00302600","8.25000000"],["0.00302590","0.00000000"],["0.00302580","0.00000000"],["0.00302570","0.00000000"],["0.00302560","0.00000000"],["0.00302550","0.00000000"],["0.00302540","0.00000000"],["0.00302530","0.00000000"],["0.00302520","5.18000000"],["0.00302490","0.00000000"],["0.00302480","56.50000000"],["0.00302470","0.00000000"],["0.00302460","0.00000000"],["0.00302410","0.00000000"],["0.00302200","0.00000000"],["0.00302050","0.00000000"],["0.00300490","0.65000000"],["0.00300010","146.11000000"]],"a":[["0.00302950","30.76000000"],["0.00302960","0.00000000"],["0.00302970","0.00000000"],["0.00302980","0.00000000"],["0.00302990","0.00000000"],["0.00303000","0.00000000"],["0.00303010","0.00000000"],["0.00303020","0.00000000"],["0.00303030","70.00000000"],["0.00303040","0.00000000"],["0.00303050","0.00000000"],["0.00303140","0.00000000"],["0.00303200","0.00000000"],["0.00303370","0.00000000"],["0.00303380","41.40000000"],["0.00303470","82.82000000"],["0.00303480","203.00000000"],["0.00303490","262.39000000"],["0.00303610","0.00000000"],["0.00328990","11.76000000"],["0.00356000","120.65000000"]]},{"e":"depthUpdate","E":1557446292098,"s":"BNBBTC","U":264205650,"u":264205699,"b":[["0.00302640","1.58000000"],["0.00302610","1.58000000"],["0.00302600","3.90000000"],["0.00302530","56.50000000"],["0.00302520","0.00000000"],["0.00302480","0.00000000"],["0.00302110","9.86000000"],["0.00301960","601.43000000"],["0.00301610","0.00000000"],["0.00301440","0.00000000"],["0.00299310","11.53000000"],["0.00299070","9.32000000"]],"a":[["0.00302940","1.47000000"],["0.00302950","24.85000000"],["0.00302960","0.00000000"],["0.00302970","0.00000000"],["0.00303060","47.08000000"],["0.00303370","0.00000000"],["0.00303460","60.19000000"],["0.00303470","82.82000000"],["0.00305690","0.00000000"]]},{"e":"depthUpdate","E":1557446293099,"s":"BNBBTC","U":264205700,"u":264205735,"b":[["0.00302610","0.00000000"],["0.00302600","0.00000000"],["0.00302550","1.58000000"],["0.00302540","8.25000000"],["0.00302530","0.00000000"],["0.00302330","0.00000000"],["0.00302320","0.00000000"],["0.00302110","9.86000000"],["0.00301420","0.00000000"],["0.00301250","799.94000000"],["0.00298690","5.82000000"],["0.00298070","69.13000000"],["0.00289200","44.00000000"]],"a":[["0.00302920","1.82000000"],["0.00302930","8.25000000"],["0.00302940","0.00000000"],["0.00302950","0.00000000"],["0.00303000","0.00000000"],["0.00303010","28.55000000"],["0.00303020","82.82000000"],["0.00303470","0.00000000"],["0.00350000","4287.37000000"]]},{"e":"depthUpdate","E":1557446294098,"s":"BNBBTC","U":264205736,"u":264205799,"b":[["0.00302640","0.00000000"],["0.00302610","8.25000000"],["0.00302600","37.45000000"],["0.00302590","0.00000000"],["0.00302580","0.00000000"],["0.00302570","0.00000000"],["0.00302560","0.00000000"],["0.00302550","0.00000000"],["0.00302540","0.00000000"],["0.00302310","0.00000000"],["0.00302110","0.00000000"],["0.00301960","0.53000000"],["0.00301940","9.86000000"],["0.00301910","1.58000000"],["0.00301830","0.00000000"],["0.00301800","0.00000000"],["0.00301750","0.00000000"],["0.00301610","0.00000000"],["0.00300020","189.91000000"],["0.00299320","0.00000000"]],"a":[["0.00302900","1.82000000"],["0.00302910","91.07000000"],["0.00302920","70.00000000"],["0.00302930","0.00000000"],["0.00303010","0.00000000"],["0.00303020","0.00000000"],["0.00303030","0.00000000"],["0.00303050","0.00000000"],["0.00303060","0.00000000"],["0.00303200","28.55000000"],["0.00303370","0.00000000"],["0.00303380","41.40000000"],["0.00304400","0.00000000"]]},{"e":"depthUpdate","E":1557446295098,"s":"BNBBTC","U":264205800,"u":264205812,"b":[["0.00302640","4.85000000"],["0.00301940","0.00000000"],["0.00301910","681.18000000"],["0.00301750","0.00000000"],["0.00301420","0.00000000"]],"a":[["0.00303200","0.00000000"],["0.00303220","28.55000000"],["0.00303230","20.00000000"],["0.00303380","21.40000000"],["0.00304320","161.62000000"]]},{"e":"depthUpdate","E":1557446296099,"s":"BNBBTC","U":264205813,"u":264205826,"b":[["0.00302180","125.65000000"],["0.00302170","98.39000000"],["0.00301940","0.00000000"],["0.00301910","0.00000000"],["0.00301800","0.00000000"],["0.00301790","0.00000000"],["0.00301730","0.00000000"],["0.00301610","1.58000000"],["0.00301420","9.86000000"]],"a":[["0.00304430","0.00000000"]]},{"e":"depthUpdate","E":1557446297098,"s":"BNBBTC","U":264205827,"u":264205835,"b":[["0.00302190","1.58000000"],["0.00302110","9.86000000"],["0.00301940","266.06000000"],["0.00301610","0.00000000"],["0.00301420","0.00000000"],["0.00299090","0.00000000"]],"a":[["0.00305050","25.24000000"],["0.00307910","0.00000000"],["0.00376000","126.70000000"]]},{"e":"depthUpdate","E":1557446298098,"s":"BNBBTC","U":264205836,"u":264205839,"b":[["0.00302600","0.00000000"],["0.00298860","12.34000000"]],"a":[["0.00302900","30.37000000"],["0.00303220","0.00000000"]]},{"e":"depthUpdate","E":1557446299099,"s":"BNBBTC","U":264205840,"u":264205854,"b":[["0.00302610","0.00000000"],["0.00302210","8.25000000"],["0.00302200","89.97000000"],["0.00302190","11.44000000"],["0.00302110","0.00000000"]],"a":[["0.00302880","1.82000000"],["0.00302890","8.25000000"],["0.00302900","28.55000000"],["0.00302910","82.82000000"]]},{"e":"depthUpdate","E":1557446300099,"s":"BNBBTC","U":264205855,"u":264205918,"b":[["0.00302640","0.00000000"],["0.00302430","56.50000000"],["0.00302420","0.00000000"],["0.00302410","0.00000000"],["0.00302400","11.45000000"],["0.00302390","0.00000000"],["0.00302380","0.00000000"],["0.00302370","0.00000000"],["0.00302360","0.00000000"],["0.00302350","37.45000000"],["0.00302340","0.00000000"],["0.00302330","0.00000000"],["0.00302320","0.00000000"],["0.00302310","0.00000000"],["0.00302300","0.00000000"],["0.00302290","0.00000000"],["0.00302280","0.00000000"],["0.00302270","26.04000000"],["0.00302220","0.00000000"],["0.00302210","0.00000000"],["0.00302200","0.00000000"],["0.00302190","0.00000000"],["0.00300370","0.00000000"],["0.00300000","377.45000000"],["0.00299610","0.99000000"]],"a":[["0.00302910","0.00000000"],["0.00303130","20.00000000"],["0.00303230","0.00000000"],["0.00303470","82.82000000"],["0.00303760","13.20000000"]]},{"e":"depthUpdate","E":1557446301099,"s":"BNBBTC","U":264205919,"u":264205960,"b":[["0.00302530","3.40000000"],["0.00302520","8.25000000"],["0.00302510","11.77000000"],["0.00302500","0.00000000"],["0.00302490","0.00000000"],["0.00302480","0.00000000"],["0.00302470","26.04000000"],["0.00302440","0.00000000"],["0.00302430","0.00000000"],["0.00302400","0.00000000"],["0.00302370","9.87000000"],["0.00302360","16.04000000"],["0.00302350","60.99000000"],["0.00302270","0.00000000"]],"a":[["0.00302880","0.00000000"],["0.00302890","9.09000000"],["0.00302900","0.00000000"],["0.00303380","21.40000000"],["0.00303450","12.58000000"],["0.00304320","0.00000000"]]},{"e":"depthUpdate","E":1557446302099,"s":"BNBBTC","U":264205961,"u":264205995,"b":[["0.00302570","8.25000000"],["0.00302560","14.55000000"],["0.00302530","0.00000000"],["0.00302520","0.00000000"],["0.00302470","0.00000000"],["0.00302370","0.00000000"],["0.00302360","0.00000000"],["0.00302200","5.22000000"],["0.00302190","25.91000000"]],"a":[["0.00302890","0.00000000"],["0.00302900","9.38000000"],["0.00303200","12.58000000"],["0.00303350","122.20000000"],["0.00303380","21.40000000"],["0.00303450","0.00000000"]]},{"e":"depthUpdate","E":1557446303099,"s":"BNBBTC","U":264205996,"u":264206008,"b":[["0.00302610","0.34000000"],["0.00302600","8.25000000"],["0.00302590","10.01000000"],["0.00302570","0.00000000"],["0.00302560","0.00000000"],["0.00302190","16.04000000"],["0.00301940","0.00000000"],["0.00301420","9.87000000"]],"a":[["0.00303200","0.00000000"],["0.00303330","12.58000000"],["0.00303340","22.99000000"],["0.00303380","0.00000000"],["0.00305000","452.93000000"]]},{"e":"depthUpdate","E":1557446304099,"s":"BNBBTC","U":264206009,"u":264206014,"b":[["0.00302630","8.25000000"],["0.00302620","10.01000000"],["0.00302600","0.00000000"],["0.00302590","0.00000000"]],"a":[["0.00303320","21.40000000"],["0.00304400","100.00000000"]]},{"e":"depthUpdate","E":1557446305099,"s":"BNBBTC","U":264206015,"u":264206035,"b":[["0.00302640","2.76000000"],["0.00302620","0.00000000"],["0.00302350","0.00000000"],["0.00302200","0.00000000"],["0.00302010","239.02000000"],["0.00301610","15.08000000"],["0.00301420","0.00000000"],["0.00298320","0.00000000"]],"a":[["0.00302900","21.96000000"],["0.00302910","82.82000000"],["0.00303330","0.00000000"],["0.00303470","0.00000000"],["0.00304200","100.00000000"],["0.00304280","161.24000000"],["0.00304300","0.00000000"],["0.00304400","0.00000000"],["0.00305470","3.28000000"]]},{"e":"depthUpdate","E":1557446306099,"s":"BNBBTC","U":264206036,"u":264206064,"b":[["0.00302630","0.00000000"],["0.00302620","8.25000000"],["0.00302510","0.00000000"],["0.00302210","16.03000000"],["0.00302200","90.34000000"],["0.00302190","15.08000000"],["0.00301610","0.00000000"],["0.00298030","1.67000000"]],"a":[]},{"e":"depthUpdate","E":1557446307100,"s":"BNBBTC","U":264206065,"u":264206086,"b":[["0.00302210","21.25000000"],["0.00302200","90.34000000"],["0.00302190","9.86000000"]],"a":[["0.00304200","0.00000000"],["0.00304400","100.00000000"]]},{"e":"depthUpdate","E":1557446308099,"s":"BNBBTC","U":264206087,"u":264206106,"b":[["0.00302660","8.25000000"],["0.00302650","16.59000000"],["0.00302620","0.00000000"],["0.00302210","0.00000000"],["0.00302200","0.00000000"],["0.00302190","28.02000000"],["0.00301610","9.86000000"]],"a":[["0.00302900","0.00000000"],["0.00303200","5.81000000"],["0.00304280","0.35000000"],["0.00366060","0.42000000"]]},{"e":"depthUpdate","E":1557446309099,"s":"BNBBTC","U":264206107,"u":264206116,"b":[["0.00302680","2.69000000"],["0.00302640","0.00000000"]],"a":[["0.00302890","82.82000000"],["0.00302900","65.00000000"],["0.00302910","5.81000000"],["0.00303200","0.00000000"],["0.00303460","0.00000000"]]},{"e":"depthUpdate","E":1557446310099,"s":"BNBBTC","U":264206117,"u":264206119,"b":[["0.00302190","528.02000000"]],"a":[["0.00302940","26.18000000"],["0.00304320","160.35000000"]]},{"e":"depthUpdate","E":1557446311099,"s":"BNBBTC","U":264206120,"u":264206139,"b":[["0.00302690","0.00000000"],["0.00302220","5.22000000"],["0.00302210","47.84000000"],["0.00302200","192.80000000"],["0.00302190","500.00000000"],["0.00302180","0.00000000"],["0.00301740","0.00000000"],["0.00301610","0.00000000"],["0.00300030","53.45000000"],["0.00300010","95.99000000"]],"a":[["0.00302890","67.73000000"],["0.00390000","1769.72000000"]]},{"e":"depthUpdate","E":1557446312099,"s":"BNBBTC","U":264206140,"u":264206164,"b":[["0.00302240","43.20000000"],["0.00302230","99.35000000"],["0.00302220","0.00000000"],["0.00302210","0.00000000"],["0.00302010","0.00000000"],["0.00280000","3196.82000000"]],"a":[]},{"e":"depthUpdate","E":1557446313099,"s":"BNBBTC","U":264206165,"u":264206174,"b":[["0.00302240","0.00000000"],["0.00302230","0.00000000"],["0.00302210","53.06000000"],["0.00302200","127.68000000"]],"a":[]},{"e":"depthUpdate","E":1557446314099,"s":"BNBBTC","U":264206175,"u":264206183,"b":[["0.00302210","53.63000000"],["0.00302200","123.32000000"],["0.00301390","59.91000000"],["0.00297000","34.81000000"]],"a":[["0.00302890","67.16000000"],["0.00303120","77.95000000"],["0.00303480","123.68000000"],["0.00304740","25.52000000"]]},{"e":"depthUpdate","E":1557446315099,"s":"BNBBTC","U":264206184,"u":264206195,"b":[["0.00302180","63.02000000"],["0.00300020","6.59000000"],["0.00247510","1.76000000"]],"a":[["0.00302870","0.00000000"],["0.00302880","0.00000000"],["0.00302890","0.00000000"],["0.00302900","0.00000000"],["0.00302910","67.16000000"],["0.00303120","83.76000000"]]},{"e":"depthUpdate","E":1557446316099,"s":"BNBBTC","U":264206196,"u":264206215,"b":[["0.00302230","38.55000000"],["0.00302220","69.78000000"],["0.00302210","9.86000000"],["0.00301390","0.00000000"],["0.00299420","183.68000000"]],"a":[["0.00302890","67.16000000"],["0.00302900","196.40000000"],["0.00302910","5.81000000"],["0.00303120","77.95000000"],["0.00303470","65.25000000"],["0.00303480","0.00000000"],["0.00303620","5.00000000"]]},{"e":"depthUpdate","E":1557446317100,"s":"BNBBTC","U":264206216,"u":264206219,"b":[["0.00296450","6.56000000"]],"a":[["0.00302900","65.56000000"],["0.00304300","100.00000000"],["0.00304400","0.00000000"]]},{"e":"depthUpdate","E":1557446318100,"s":"BNBBTC","U":264206220,"u":264206223,"b":[["0.00302210","32.42000000"]],"a":[["0.00303340","145.49000000"],["0.00304200","100.00000000"],["0.00304300","0.00000000"]]},{"e":"depthUpdate","E":1557446319101,"s":"BNBBTC","U":264206224,"u":264206253,"b":[["0.00302700","8.25000000"],["0.00302690","11.77000000"],["0.00302660","0.00000000"],["0.00302230","69.88000000"],["0.00302210","32.42000000"],["0.00294100","14.21000000"]],"a":[["0.00302890","35.83000000"],["0.00304200","0.00000000"],["0.00304400","100.00000000"]]},{"e":"depthUpdate","E":1557446320100,"s":"BNBBTC","U":264206254,"u":264206270,"b":[["0.00302260","5.22000000"],["0.00302250","69.87000000"],["0.00302240","131.45000000"],["0.00302230","0.00000000"],["0.00302220","74.42000000"],["0.00302210","22.56000000"],["0.00302200","0.00000000"],["0.00300010","96.99000000"]],"a":[]},{"e":"depthUpdate","E":1557446321100,"s":"BNBBTC","U":264206271,"u":264206274,"b":[["0.00302710","9.07000000"],["0.00302680","0.00000000"],["0.00290000","3408.65000000"]],"a":[["0.00302940","0.00000000"]]},{"e":"depthUpdate","E":1557446322100,"s":"BNBBTC","U":264206275,"u":264206281,"b":[["0.00302730","11.77000000"],["0.00302720","11.77000000"],["0.00302250","80.99000000"]],"a":[["0.00302890","24.71000000"],["0.00303640","0.00000000"],["0.00303720","984.06000000"]]},{"e":"depthUpdate","E":1557446323100,"s":"BNBBTC","U":264206282,"u":264206300,"b":[["0.00302770","13.46000000"],["0.00302760","11.77000000"],["0.00302750","0.00000000"],["0.00302740","5.56000000"],["0.00302710","0.00000000"],["0.00302700","0.00000000"],["0.00302690","0.00000000"],["0.00302260","0.00000000"]],"a":[["0.00302890","0.00000000"],["0.00302900","0.00000000"],["0.00302910","0.00000000"],["0.00302920","0.00000000"],["0.00303110","30.52000000"],["0.00303120","147.95000000"]]},{"e":"depthUpdate","E":1557446324101,"s":"BNBBTC","U":264206301,"u":264206337,"b":[["0.00302880","0.84000000"],["0.00302780","6.02000000"],["0.00302770","8.24000000"],["0.00302760","23.54000000"],["0.00302740","0.00000000"],["0.00302660","0.00000000"],["0.00302280","28.00000000"],["0.00302270","68.04000000"],["0.00302260","157.56000000"],["0.00302250","0.00000000"],["0.00302220","64.56000000"],["0.00301240","77.62000000"]],"a":[["0.00303110","55.24000000"],["0.00303120","70.00000000"],["0.00303210","0.00000000"],["0.00303310","5.81000000"],["0.00303480","60.68000000"],["0.00303760","0.00000000"],["0.00304320","0.00000000"],["0.00304740","0.00000000"]]},{"e":"depthUpdate","E":1557446325101,"s":"BNBBTC","U":264206338,"u":264206384,"b":[["0.00302840","5.22000000"],["0.00302830","8.24000000"],["0.00302820","0.00000000"],["0.00302810","0.00000000"],["0.00302800","6.66000000"],["0.00302780","0.00000000"],["0.00302770","0.00000000"],["0.00302300","80.92000000"],["0.00302290","65.10000000"],["0.00302280","0.00000000"],["0.00302270","0.00000000"],["0.00302220","0.00000000"]],"a":[["0.00303110","0.00000000"],["0.00303120","0.00000000"],["0.00303130","0.00000000"],["0.00303240","77.04000000"],["0.00303250","20.00000000"],["0.00303280","0.00000000"],["0.00303290","24.71000000"],["0.00303300","77.06000000"],["0.00303310","70.00000000"],["0.00303330","0.00000000"],["0.00304400","0.00000000"],["0.00304460","158.53000000"],["0.00305050","25.52000000"],["0.00305280","25.21000000"]]},{"e":"depthUpdate","E":1557446326101,"s":"BNBBTC","U":264206385,"u":264206430,"b":[["0.00302880","6.06000000"],["0.00302870","8.24000000"],["0.00302860","9.45000000"],["0.00302840","0.00000000"],["0.00302830","0.00000000"],["0.00302800","0.00000000"],["0.00302730","0.00000000"],["0.00302720","0.00000000"],["0.00302320","80.92000000"],["0.00302310","74.78000000"],["0.00302300","9.85000000"],["0.00302270","0.00000000"],["0.00301240","0.00000000"],["0.00299420","0.00000000"]],"a":[["0.00303230","229.41000000"],["0.00303240","77.04000000"],["0.00303250","28.96000000"],["0.00303290","0.00000000"],["0.00303340","22.99000000"],["0.00303720","907.01000000"],["0.00303930","0.00000000"],["0.00304460","0.00000000"],["0.00304800","17.47000000"],["0.00304900","100.00000000"]]},{"e":"depthUpdate","E":1557446327101,"s":"BNBBTC","U":264206431,"u":264206464,"b":[["0.00302910","8.24000000"],["0.00302900","9.86000000"],["0.00302880","0.84000000"],["0.00302870","0.00000000"],["0.00302860","0.00000000"],["0.00302760","11.77000000"],["0.00302340","58.14000000"],["0.00302330","63.21000000"],["0.00302320","22.77000000"],["0.00302310","80.00000000"],["0.00302300","9.85000000"],["0.00300040","183.30000000"],["0.00300010","36.73000000"]],"a":[["0.00303210","5.81000000"],["0.00303220","28.74000000"],["0.00303230","223.60000000"],["0.00303250","0.00000000"],["0.00303320","0.00000000"],["0.00303470","0.00000000"]]},{"e":"depthUpdate","E":1557446328101,"s":"BNBBTC","U":264206465,"u":264206497,"b":[["0.00302930","8.24000000"],["0.00302920","9.88000000"],["0.00302910","0.00000000"],["0.00302900","0.00000000"],["0.00302770","11.67000000"],["0.00302760","0.00000000"],["0.00302650","0.00000000"],["0.00302370","22.77000000"],["0.00302360","58.14000000"],["0.00302350","122.66000000"],["0.00302340","0.00000000"],["0.00302330","68.43000000"],["0.00302320","9.85000000"],["0.00302310","74.78000000"],["0.00302300","0.00000000"],["0.00302240","0.00000000"]],"a":[["0.00303190","5.81000000"],["0.00303200","28.69000000"],["0.00303210","0.00000000"],["0.00303220","0.00000000"],["0.00303380","20.00000000"],["0.00303710","63.55000000"]]},{"e":"depthUpdate","E":1557446329101,"s":"BNBBTC","U":264206498,"u":264206500,"b":[],"a":[["0.00303240","14.98000000"]]},{"e":"depthUpdate","E":1557446330101,"s":"BNBBTC","U":264206501,"u":264206531,"b":[["0.00302360","63.36000000"],["0.00302340","0.00000000"],["0.00302330","63.21000000"],["0.00302320","117.13000000"],["0.00302180","0.00000000"],["0.00301250","0.00000000"],["0.00300930","799.94000000"],["0.00299040","0.83000000"],["0.00298850","22.27000000"]],"a":[["0.00303170","5.81000000"],["0.00303180","24.71000000"],["0.00303190","70.00000000"],["0.00303220","78.30000000"],["0.00303230","198.89000000"],["0.00303240","0.00000000"],["0.00303290","0.00000000"],["0.00303310","0.00000000"],["0.00303990","0.00000000"]]},{"e":"depthUpdate","E":1557446331102,"s":"BNBBTC","U":264206532,"u":264206556,"b":[["0.00302390","22.77000000"],["0.00302380","63.36000000"],["0.00302370","65.24000000"],["0.00302360","0.00000000"],["0.00302340","9.85000000"],["0.00302320","107.28000000"],["0.00302290","0.00000000"],["0.00300490","50.77000000"],["0.00300030","3.33000000"]],"a":[["0.00302940","26.18000000"],["0.00303150","0.00000000"],["0.00303160","30.79000000"],["0.00303170","0.00000000"],["0.00303200","0.00000000"],["0.00304500","159.76000000"]]},{"e":"depthUpdate","E":1557446332101,"s":"BNBBTC","U":264206557,"u":264206576,"b":[["0.00302620","0.00000000"],["0.00302400","0.00000000"],["0.00302340","9.85000000"],["0.00301500","160.00000000"],["0.00296000","182.02000000"]],"a":[["0.00302940","0.48000000"],["0.00303160","0.00000000"],["0.00303170","5.81000000"],["0.00303180","24.71000000"],["0.00303210","0.00000000"],["0.00303820","13.20000000"]]},{"e":"depthUpdate","E":1557446333101,"s":"BNBBTC","U":264206577,"u":264206589,"b":[["0.00302950","8.24000000"],["0.00302940","34.83000000"],["0.00302930","0.00000000"],["0.00302380","58.14000000"],["0.00302370","70.46000000"],["0.00302360","9.85000000"],["0.00302340","0.00000000"]],"a":[["0.00302940","0.00000000"],["0.00303160","28.76000000"],["0.00303170","0.00000000"],["0.00303190","120.00000000"],["0.00303210","5.81000000"]]},{"e":"depthUpdate","E":1557446334101,"s":"BNBBTC","U":264206590,"u":264206612,"b":[["0.00302960","3.68000000"],["0.00302920","0.00000000"],["0.00302420","22.77000000"],["0.00302410","58.13000000"],["0.00302400","77.88000000"],["0.00302390","5.22000000"],["0.00302380","9.85000000"],["0.00302370","65.24000000"],["0.00302360","0.00000000"],["0.00302260","81.19000000"]],"a":[["0.00303210","0.00000000"],["0.00303220","0.00000000"],["0.00303230","0.00000000"],["0.00303270","5.81000000"],["0.00303280","20.00000000"],["0.00303300","0.00000000"],["0.00303340","0.00000000"],["0.00303380","0.00000000"],["0.00303610","44.39000000"],["0.00303820","0.00000000"]]},{"e":"depthUpdate","E":1557446335101,"s":"BNBBTC","U":264206613,"u":264206617,"b":[["0.00302320","0.00000000"]],"a":[["0.00303470","209.74000000"],["0.00303640","153.85000000"]]},{"e":"depthUpdate","E":1557446336101,"s":"BNBBTC","U":264206618,"u":264206641,"b":[["0.00302940","23.06000000"],["0.00302460","0.00000000"],["0.00302450","5.22000000"],["0.00302440","67.98000000"],["0.00302430","190.26000000"],["0.00302420","0.00000000"],["0.00302410","0.00000000"],["0.00302400","175.19000000"],["0.00302390","0.00000000"],["0.00302380","0.00000000"],["0.00302370","0.00000000"],["0.00302350","0.00000000"]],"a":[["0.00303190","125.00000000"]]},{"e":"depthUpdate","E":1557446337101,"s":"BNBBTC","U":264206642,"u":264206651,"b":[["0.00302940","0.00000000"],["0.00302460","0.00000000"],["0.00302450","37.84000000"],["0.00302440","58.13000000"],["0.00300040","0.00000000"]],"a":[["0.00303150","5.81000000"],["0.00303270","0.00000000"]]},{"e":"depthUpdate","E":1557446338101,"s":"BNBBTC","U":264206652,"u":264206661,"b":[["0.00302950","0.00000000"],["0.00302890","8.24000000"],["0.00299500","183.63000000"],["0.00295000","1055.88000000"]],"a":[["0.00303130","5.81000000"],["0.00303140","28.48000000"],["0.00303150","0.00000000"],["0.00303160","0.00000000"],["0.00303630","906.01000000"],["0.00303720","1.00000000"]]},{"e":"depthUpdate","E":1557446339101,"s":"BNBBTC","U":264206662,"u":264206670,"b":[["0.00302960","0.00000000"],["0.00302900","2.33000000"],["0.00302450","27.99000000"],["0.00302440","67.98000000"],["0.00300230","5.26000000"]],"a":[["0.00303110","5.81000000"],["0.00303120","28.73000000"],["0.00303130","0.00000000"],["0.00303140","0.00000000"]]},{"e":"depthUpdate","E":1557446340101,"s":"BNBBTC","U":264206671,"u":264206674,"b":[["0.00302610","0.00000000"],["0.00299890","3.47000000"]],"a":[["0.00303180","44.71000000"],["0.00303280","0.00000000"]]},{"e":"depthUpdate","E":1557446341101,"s":"BNBBTC","U":264206675,"u":264206694,"b":[["0.00302780","5.22000000"],["0.00302460","0.00000000"],["0.00302450","0.00000000"],["0.00302440","28.56000000"],["0.00300490","0.65000000"],["0.00299500","233.71000000"],["0.00298870","0.00000000"]],"a":[["0.00302990","0.00000000"],["0.00303000","320.32000000"],["0.00303110","0.00000000"],["0.00303120","0.00000000"],["0.00303180","0.00000000"]]},{"e":"depthUpdate","E":1557446342101,"s":"BNBBTC","U":264206695,"u":264206709,"b":[["0.00302450","9.85000000"],["0.00302400","77.88000000"],["0.00302270","308.31000000"],["0.00300340","0.00000000"],["0.00300030","0.00000000"],["0.00299730","0.00000000"],["0.00299450","6.71000000"],["0.00299140","3.34000000"],["0.00298550","3.34000000"]],"a":[["0.00303000","302.08000000"],["0.00303380","20.00000000"],["0.00303460","6.54000000"]]},{"e":"depthUpdate","E":1557446343101,"s":"BNBBTC","U":264206710,"u":264206734,"b":[["0.00302910","11.77000000"],["0.00302880","0.00000000"],["0.00302470","0.00000000"],["0.00302460","28.56000000"],["0.00302450","62.95000000"],["0.00302440","9.85000000"],["0.00302430","129.18000000"],["0.00298840","10.08000000"]],"a":[]},{"e":"depthUpdate","E":1557446344101,"s":"BNBBTC","U":264206735,"u":264206752,"b":[["0.00302460","38.41000000"],["0.00302440","0.00000000"]],"a":[]},{"e":"depthUpdate","E":1557446345101,"s":"BNBBTC","U":264206753,"u":264206772,"b":[["0.00302460","28.56000000"],["0.00302440","0.00000000"]],"a":[["0.00303880","14.10000000"]]},{"e":"depthUpdate","E":1557446346101,"s":"BNBBTC","U":264206773,"u":264206795,"b":[["0.00302460","28.56000000"],["0.00302440","0.00000000"],["0.00301410","13.94000000"],["0.00300920","286.75000000"]],"a":[["0.00303340","77.65000000"],["0.00303460","0.00000000"],["0.00303640","74.87000000"]]},{"e":"depthUpdate","E":1557446347102,"s":"BNBBTC","U":264206796,"u":264206815,"b":[["0.00302460","28.56000000"],["0.00302440","0.00000000"]],"a":[]},{"e":"depthUpdate","E":1557446348102,"s":"BNBBTC","U":264206816,"u":264206839,"b":[["0.00302920","11.77000000"],["0.00302460","28.90000000"],["0.00302440","0.00000000"]],"a":[["0.00303330","130.59000000"],["0.00303470","81.96000000"]]},{"e":"depthUpdate","E":1557446349102,"s":"BNBBTC","U":264206840,"u":264206878,"b":[["0.00303300","0.00000000"],["0.00302960","13.46000000"],["0.00302950","0.00000000"],["0.00302940","0.00000000"],["0.00302930","23.54000000"],["0.00302920","81.77000000"],["0.00302910","0.00000000"],["0.00302890","0.00000000"],["0.00302800","28.56000000"],["0.00302790","28.26000000"],["0.00302780","0.00000000"],["0.00302770","0.00000000"],["0.00302480","9.84000000"],["0.00302470","129.61000000"],["0.00302460","0.34000000"],["0.00302440","0.00000000"],["0.00302430","0.00000000"],["0.00302340","82.80000000"],["0.00302270","0.00000000"],["0.00300020","189.91000000"],["0.00299500","50.08000000"]],"a":[["0.00303000","0.00000000"],["0.00303190","0.00000000"],["0.00303320","28.57000000"],["0.00303380","78.48000000"]]},{"e":"depthUpdate","E":1557446350102,"s":"BNBBTC","U":264206879,"u":264206923,"b":[["0.00303040","8.24000000"],["0.00303030","0.00000000"],["0.00303020","0.00000000"],["0.00303010","0.00000000"],["0.00303000","5.22000000"],["0.00302990","10.77000000"],["0.00302970","73.83000000"],["0.00302960","0.00000000"],["0.00302940","0.00000000"],["0.00302900","0.00000000"],["0.00302490","9.84000000"],["0.00302480","82.79000000"],["0.00302340","0.00000000"],["0.00298700","2.09000000"]],"a":[["0.00303310","47.08000000"],["0.00303320","0.00000000"],["0.00303330","0.00000000"],["0.00303340","0.00000000"],["0.00303380","58.48000000"],["0.00303550","20.00000000"],["0.00303880","0.90000000"],["0.00304080","1.36000000"],["0.00304500","0.00000000"]]},{"e":"depthUpdate","E":1557446351102,"s":"BNBBTC","U":264206924,"u":264206945,"b":[["0.00303080","5.22000000"],["0.00303070","8.24000000"],["0.00303060","10.18000000"],["0.00303050","0.00000000"],["0.00303040","70.00000000"],["0.00303000","0.00000000"],["0.00302990","0.00000000"],["0.00302920","11.77000000"],["0.00301710","28.05000000"],["0.00299500","0.00000000"],["0.00299270","50.08000000"],["0.00299260","1849.83000000"],["0.00299040","0.00000000"],["0.00298830","3.26000000"]],"a":[["0.00303380","0.00000000"],["0.00303550","0.00000000"],["0.00303600","129.39000000"],["0.00303610","102.87000000"],["0.00303790","79.72000000"],["0.00304630","155.64000000"]]},{"e":"depthUpdate","E":1557446352103,"s":"BNBBTC","U":264206946,"u":264206966,"b":[["0.00303120","5.21000000"],["0.00303110","8.24000000"],["0.00303100","13.24000000"],["0.00303080","0.00000000"],["0.00303070","0.00000000"],["0.00303060","0.00000000"],["0.00302510","92.59000000"],["0.00302500","74.61000000"],["0.00302490","0.00000000"],["0.00302480","0.00000000"],["0.00302460","0.00000000"],["0.00302400","0.00000000"],["0.00300920","2.63000000"],["0.00300620","0.00000000"],["0.00299070","9.32000000"]],"a":[["0.00303310","0.00000000"],["0.00303710","0.00000000"]]},{"e":"depthUpdate","E":1557446353103,"s":"BNBBTC","U":264206967,"u":264206998,"b":[["0.00303160","0.00000000"],["0.00303150","8.24000000"],["0.00303140","11.80000000"],["0.00303130","23.54000000"],["0.00303120","0.00000000"],["0.00303110","0.00000000"],["0.00303100","0.00000000"],["0.00302930","0.00000000"],["0.00302920","0.00000000"],["0.00302520","5.21000000"],["0.00302510","9.84000000"],["0.00302340","82.74000000"],["0.00301600","290.96000000"],["0.00301300","405.57000000"],["0.00300930","0.00000000"],["0.00300030","799.94000000"]],"a":[["0.00303350","24.47000000"],["0.00303610","44.39000000"],["0.00303720","59.48000000"],["0.00303790","99.72000000"],["0.00304900","0.00000000"],["0.00305000","552.93000000"],["0.00308620","0.00000000"]]},{"e":"depthUpdate","E":1557446354103,"s":"BNBBTC","U":264206999,"u":264207020,"b":[["0.00303170","12.55000000"],["0.00303160","11.77000000"],["0.00303150","70.00000000"],["0.00303140","0.00000000"],["0.00303040","0.00000000"],["0.00302800","0.00000000"],["0.00302510","28.53000000"],["0.00302480","0.00000000"],["0.00302340","9.84000000"],["0.00302320","82.74000000"],["0.00302000","162.00000000"],["0.00301500","0.00000000"],["0.00290000","3413.65000000"]],"a":[["0.00303350","8.02000000"],["0.00303480","0.00000000"],["0.00308840","1.80000000"]]},{"e":"depthUpdate","E":1557446355103,"s":"BNBBTC","U":264207021,"u":264207039,"b":[["0.00302970","0.00000000"],["0.00302520","5.21000000"],["0.00302510","111.27000000"],["0.00302490","0.00000000"],["0.00302480","9.84000000"],["0.00302460","425.49000000"],["0.00302340","0.00000000"],["0.00302320","0.00000000"],["0.00301470","0.00000000"]],"a":[["0.00303590","21.38000000"],["0.00303610","0.00000000"],["0.00304760","23.00000000"],["0.00304820","62.61000000"]]},{"e":"depthUpdate","E":1557446356103,"s":"BNBBTC","U":264207040,"u":264207064,"b":[["0.00303190","2.08000000"],["0.00303170","8.24000000"],["0.00302530","82.73000000"],["0.00302520","68.86000000"],["0.00302510","9.84000000"],["0.00302480","0.00000000"],["0.00302450","0.00000000"],["0.00302000","2.00000000"],["0.00294970","0.00000000"]],"a":[]},{"e":"depthUpdate","E":1557446357103,"s":"BNBBTC","U":264207065,"u":264207089,"b":[["0.00303130","11.77000000"],["0.00302800","28.53000000"],["0.00302560","5.21000000"],["0.00302550","82.73000000"],["0.00302540","81.31000000"],["0.00302530","0.00000000"],["0.00302520","63.65000000"],["0.00302510","9.84000000"],["0.00302260","0.00000000"],["0.00301900","162.00000000"],["0.00298860","0.00000000"]],"a":[["0.00303350","60.05000000"],["0.00303590","79.86000000"],["0.00303720","1.00000000"]]},{"e":"depthUpdate","E":1557446358103,"s":"BNBBTC","U":264207090,"u":264207098,"b":[["0.00303160","0.00000000"],["0.00303130","0.00000000"],["0.00302810","9.84000000"],["0.00302510","0.00000000"],["0.00299390","0.00000000"],["0.00299010","55.71000000"],["0.00294610","44.04000000"]],"a":[["0.00307530","177.00000000"],["0.00307630","0.00000000"]]},{"e":"depthUpdate","E":1557446359103,"s":"BNBBTC","U":264207099,"u":264207103,"b":[["0.00299150","2.15000000"]],"a":[["0.00303350","65.05000000"],["0.00303640","0.00000000"],["0.00303690","20.00000000"],["0.00303790","79.72000000"]]},{"e":"depthUpdate","E":1557446360103,"s":"BNBBTC","U":264207104,"u":264207116,"b":[["0.00303170","0.00000000"],["0.00303160","8.24000000"],["0.00302510","183.91000000"],["0.00302460","0.00000000"],["0.00301390","798.88000000"],["0.00300040","183.30000000"],["0.00300030","0.00000000"],["0.00300020","6.59000000"]],"a":[["0.00303580","61.77000000"],["0.00303630","0.00000000"],["0.00303790","985.25000000"],["0.00303990","77.12000000"],["0.00355740","0.00000000"]]},{"e":"depthUpdate","E":1557446361104,"s":"BNBBTC","U":264207117,"u":264207121,"b":[["0.00303160","8.57000000"]],"a":[["0.00303350","64.22000000"],["0.00304900","100.00000000"],["0.00305000","452.93000000"],["0.00364310","0.00000000"]]},{"e":"depthUpdate","E":1557446362104,"s":"BNBBTC","U":264207122,"u":264207122,"b":[["0.00299220","0.00000000"]],"a":[]},{"e":"depthUpdate","E":1557446363105,"s":"BNBBTC","U":264207123,"u":264207133,"b":[["0.00303300","700.00000000"],["0.00302580","5.21000000"],["0.00302570","82.73000000"],["0.00302560","125.68000000"],["0.00302550","0.00000000"],["0.00302510","0.00000000"],["0.00302470","0.00000000"],["0.00299380","1.16000000"]],"a":[]},{"e":"depthUpdate","E":1557446364105,"s":"BNBBTC","U":264207134,"u":264207152,"b":[["0.00303310","12.02000000"],["0.00303190","0.00000000"],["0.00303170","0.00000000"],["0.00302840","5.21000000"],["0.00302830","38.35000000"],["0.00302820","76.97000000"],["0.00302810","0.00000000"],["0.00302800","0.00000000"],["0.00302580","0.00000000"],["0.00302500","0.00000000"],["0.00301900","162.00000000"],["0.00301380","0.00000000"]],"a":[["0.00303470","0.00000000"],["0.00303580","0.00000000"],["0.00303600","0.00000000"],["0.00304630","0.00000000"]]},{"e":"depthUpdate","E":1557446365105,"s":"BNBBTC","U":264207153,"u":264207164,"b":[["0.00303310","82.02000000"],["0.00303150","0.00000000"],["0.00302850","0.00000000"],["0.00302840","9.83000000"],["0.00302830","28.52000000"],["0.00302580","5.21000000"],["0.00302090","256.21000000"]],"a":[["0.00303780","145.73000000"],["0.00304220","126.65000000"]]},{"e":"depthUpdate","E":1557446366105,"s":"BNBBTC","U":264207165,"u":264207184,"b":[["0.00302860","43.56000000"],["0.00302850","63.63000000"],["0.00302840","0.00000000"],["0.00302830","0.00000000"],["0.00302580","0.00000000"],["0.00302520","0.00000000"],["0.00302200","797.14000000"],["0.00301390","0.00000000"],["0.00297720","2.16000000"],["0.00297530","0.00000000"]],"a":[["0.00303350","50.73000000"],["0.00303590","21.38000000"],["0.00303720","59.48000000"],["0.00303790","79.72000000"],["0.00304820","967.10000000"],["0.00304890","150.96000000"]]},{"e":"depthUpdate","E":1557446367105,"s":"BNBBTC","U":264207185,"u":264207201,"b":[["0.00302860","116.43000000"],["0.00302570","0.00000000"],["0.00302220","0.00000000"]],"a":[["0.00303350","0.00000000"],["0.00303390","15.63000000"],["0.00303780","79.89000000"]]},{"e":"depthUpdate","E":1557446368105,"s":"BNBBTC","U":264207202,"u":264207226,"b":[["0.00303310","87.23000000"],["0.00302860","111.22000000"],["0.00302220","0.00000000"]],"a":[["0.00303390","1.25000000"],["0.00303980","63.03000000"]]},{"e":"depthUpdate","E":1557446369105,"s":"BNBBTC","U":264207227,"u":264207246,"b":[["0.00303320","11.77000000"],["0.00303310","82.02000000"],["0.00302860","111.22000000"],["0.00302220","0.00000000"]],"a":[]},{"e":"depthUpdate","E":1557446370105,"s":"BNBBTC","U":264207247,"u":264207276,"b":[["0.00303330","11.77000000"],["0.00302880","28.52000000"],["0.00302870","28.26000000"],["0.00302860","82.70000000"],["0.00302790","0.00000000"],["0.00302220","0.00000000"]],"a":[["0.00303390","0.00000000"],["0.00303490","259.25000000"],["0.00305050","0.00000000"],["0.00305280","0.00000000"],["0.00305570","25.19000000"],["0.00311840","861.07000000"]]},{"e":"depthUpdate","E":1557446371105,"s":"BNBBTC","U":264207277,"u":264207302,"b":[["0.00303340","11.77000000"],["0.00302870","28.26000000"],["0.00302860","82.70000000"],["0.00302220","0.00000000"],["0.00302000","162.00000000"],["0.00301900","2.00000000"],["0.00300040","0.00000000"],["0.00300020","189.91000000"]],"a":[["0.00304440","0.00000000"]]},{"e":"depthUpdate","E":1557446372105,"s":"BNBBTC","U":264207303,"u":264207322,"b":[["0.00302870","28.26000000"],["0.00302860","82.70000000"],["0.00302220","0.00000000"]],"a":[]},{"e":"depthUpdate","E":1557446373105,"s":"BNBBTC","U":264207323,"u":264207347,"b":[["0.00303320","5.21000000"],["0.00302870","28.26000000"],["0.00302860","82.70000000"],["0.00302220","0.00000000"]],"a":[["0.00303490","251.65000000"],["0.00304820","994.86000000"]]},{"e":"depthUpdate","E":1557446374106,"s":"BNBBTC","U":264207348,"u":264207365,"b":[["0.00303350","23.54000000"],["0.00303330","0.00000000"],["0.00302910","9.83000000"],["0.00302900","111.21000000"],["0.00302890","75.85000000"],["0.00302880","0.00000000"],["0.00302860","0.00000000"],["0.00302820","0.00000000"],["0.00302220","0.00000000"]],"a":[]},{"e":"depthUpdate","E":1557446375106,"s":"BNBBTC","U":264207366,"u":264207370,"b":[["0.00303340","0.00000000"],["0.00302000","2.00000000"],["0.00301900","162.00000000"]],"a":[["0.00303490","282.25000000"],["0.00306820","0.00000000"]]},{"e":"depthUpdate","E":1557446376107,"s":"BNBBTC","U":264207371,"u":264207374,"b":[["0.00303360","11.77000000"]],"a":[["0.00303980","86.03000000"],["0.00304760","0.00000000"],["0.00307140","3.49000000"]]},{"e":"depthUpdate","E":1557446377107,"s":"BNBBTC","U":264207375,"u":264207376,"b":[],"a":[["0.00304800","117.47000000"],["0.00304900","0.00000000"]]},{"e":"depthUpdate","E":1557446378107,"s":"BNBBTC","U":264207377,"u":264207381,"b":[["0.00303370","11.77000000"],["0.00303350","0.00000000"],["0.00299890","2.14000000"]],"a":[["0.00305240","25.49000000"]]},{"e":"depthUpdate","E":1557446379107,"s":"BNBBTC","U":264207382,"u":264207391,"b":[["0.00303380","11.77000000"],["0.00303320","5.21000000"],["0.00303300","0.00000000"],["0.00303170","9.83000000"],["0.00302920","0.00000000"],["0.00302910","0.00000000"]],"a":[["0.00304790","904.49000000"],["0.00304820","90.37000000"]]},{"e":"depthUpdate","E":1557446380107,"s":"BNBBTC","U":264207392,"u":264207403,"b":[["0.00303390","0.00000000"],["0.00303360","0.00000000"],["0.00303310","70.00000000"],["0.00302920","111.19000000"],["0.00302910","139.55000000"],["0.00302900","0.00000000"],["0.00302330","0.00000000"],["0.00302310","0.00000000"]],"a":[]},{"e":"depthUpdate","E":1557446381107,"s":"BNBBTC","U":264207404,"u":264207406,"b":[],"a":[["0.00303580","20.00000000"],["0.00303690","0.00000000"],["0.00305240","0.00000000"]]},{"e":"depthUpdate","E":1557446382107,"s":"BNBBTC","U":264207407,"u":264207414,"b":[["0.00303370","0.00000000"],["0.00303320","0.00000000"],["0.00302950","5.21000000"],["0.00302940","28.51000000"],["0.00302930","129.85000000"],["0.00302920","0.00000000"],["0.00302560","0.00000000"]],"a":[]},{"e":"depthUpdate","E":1557446383107,"s":"BNBBTC","U":264207415,"u":264207440,"b":[["0.00303380","0.00000000"],["0.00303320","5.54000000"],["0.00303170","0.00000000"],["0.00302980","0.00000000"],["0.00302970","0.00000000"],["0.00302960","28.52000000"],["0.00302950","0.00000000"],["0.00302940","0.00000000"],["0.00302860","88.30000000"]],"a":[["0.00303580","78.48000000"],["0.00303720","1.00000000"]]},{"e":"depthUpdate","E":1557446384107,"s":"BNBBTC","U":264207441,"u":264207462,"b":[["0.00303330","11.77000000"],["0.00303320","11.24000000"],["0.00302990","5.21000000"],["0.00302980","38.35000000"],["0.00302970","64.06000000"],["0.00302960","0.00000000"],["0.00302950","0.00000000"],["0.00302940","0.00000000"],["0.00302860","0.00000000"],["0.00302850","0.00000000"],["0.00302550","189.65000000"]],"a":[["0.00312170","0.43000000"]]},{"e":"depthUpdate","E":1557446385108,"s":"BNBBTC","U":264207463,"u":264207468,"b":[["0.00303340","9.27000000"],["0.00303320","0.33000000"],["0.00303160","8.24000000"]],"a":[["0.00303720","81.68000000"],["0.00303790","0.00000000"],["0.00305280","25.50000000"]]},{"e":"depthUpdate","E":1557446386107,"s":"BNBBTC","U":264207469,"u":264207472,"b":[["0.00303350","11.77000000"],["0.00301710","0.00000000"]],"a":[["0.00304210","905.09000000"],["0.00304790","0.00000000"]]},{"e":"depthUpdate","E":1557446387107,"s":"BNBBTC","U":264207473,"u":264207474,"b":[["0.00303340","0.00000000"],["0.00299950","0.00000000"]],"a":[]},{"e":"depthUpdate","E":1557446388107,"s":"BNBBTC","U":264207475,"u":264207487,"b":[["0.00303360","11.77000000"],["0.00303330","0.00000000"],["0.00302980","28.52000000"],["0.00302550","0.00000000"],["0.00302220","9.83000000"]],"a":[]},{"e":"depthUpdate","E":1557446389107,"s":"BNBBTC","U":264207488,"u":264207499,"b":[["0.00302980","28.52000000"],["0.00302220","9.83000000"]],"a":[]},{"e":"depthUpdate","E":1557446390107,"s":"BNBBTC","U":264207500,"u":264207530,"b":[["0.00303380","5.21000000"],["0.00303370","32.78000000"],["0.00303350","11.77000000"],["0.00303160","0.00000000"],["0.00303020","0.00000000"],["0.00303010","20.00000000"],["0.00302990","9.83000000"],["0.00302980","28.52000000"],["0.00302940","82.68000000"],["0.00302230","23.01000000"],["0.00302220","0.00000000"]],"a":[["0.00303490","0.00000000"],["0.00303580","0.00000000"],["0.00303590","0.00000000"],["0.00303620","0.00000000"],["0.00303650","0.00000000"],["0.00303660","0.00000000"],["0.00303670","0.00000000"],["0.00303690","4.84000000"],["0.00303700","20.47000000"],["0.00303710","0.00000000"],["0.00303720","16.17000000"],["0.00303970","294.62000000"]]},{"e":"depthUpdate","E":1557446391108,"s":"BNBBTC","U":264207531,"u":264207561,"b":[["0.00303410","5.21000000"],["0.00303400","8.23000000"],["0.00303390","28.87000000"],["0.00303380","0.00000000"],["0.00303370","0.00000000"],["0.00303350","0.00000000"],["0.00303020","81.88000000"],["0.00302990","0.00000000"],["0.00302980","111.18000000"],["0.00302940","0.00000000"],["0.00302890","0.00000000"],["0.00302880","28.26000000"],["0.00302870","0.00000000"],["0.00298750","32.74000000"],["0.00298070","36.32000000"]],"a":[["0.00303660","4.84000000"],["0.00303670","14.03000000"],["0.00303690","0.00000000"],["0.00303700","0.00000000"],["0.00303720","0.00000000"],["0.00304270","0.00000000"],["0.00310000","33.66000000"]]},{"e":"depthUpdate","E":1557446392108,"s":"BNBBTC","U":264207562,"u":264207611,"b":[["0.00303440","0.00000000"],["0.00303430","8.89000000"],["0.00303420","29.39000000"],["0.00303410","70.00000000"],["0.00303400","0.00000000"],["0.00303390","0.00000000"],["0.00303310","0.00000000"],["0.00303040","9.83000000"],["0.00303030","82.66000000"],["0.00303020","110.39000000"],["0.00302990","0.00000000"],["0.00302980","0.00000000"],["0.00302940","0.00000000"],["0.00302220","0.00000000"],["0.00302200","957.14000000"],["0.00301900","2.00000000"],["0.00301890","28.02000000"]],"a":[["0.00303640","4.84000000"],["0.00303650","14.03000000"],["0.00303660","0.00000000"],["0.00303670","0.00000000"],["0.00303720","189.88000000"],["0.00303980","23.00000000"],["0.00304220","0.00000000"],["0.00304880","78.43000000"],["0.00304890","0.00000000"],["0.00305280","0.00000000"]]},{"e":"depthUpdate","E":1557446393108,"s":"BNBBTC","U":264207612,"u":264207628,"b":[["0.00303450","8.89000000"],["0.00303440","28.14000000"],["0.00303430","0.00000000"],["0.00303420","0.00000000"],["0.00303360","0.00000000"],["0.00303050","5.21000000"],["0.00302210","820.65000000"],["0.00302200","160.00000000"]],"a":[["0.00303620","4.84000000"],["0.00303630","14.03000000"],["0.00303640","0.00000000"],["0.00303650","0.00000000"],["0.00303670","20.00000000"],["0.00303720","126.88000000"],["0.00303970","0.00000000"],["0.00303990","981.70000000"],["0.00304210","0.00000000"]]},{"e":"depthUpdate","E":1557446394108,"s":"BNBBTC","U":264207629,"u":264207635,"b":[],"a":[["0.00303620","0.00000000"],["0.00303670","0.00000000"],["0.00303710","8.89000000"],["0.00303980","381.58000000"],["0.00304800","17.47000000"],["0.00304900","100.00000000"]]},{"e":"depthUpdate","E":1557446395108,"s":"BNBBTC","U":264207636,"u":264207708,"b":[["0.00303450","0.00000000"],["0.00303440","0.00000000"],["0.00303410","0.00000000"],["0.00303320","0.00000000"],["0.00303060","0.00000000"],["0.00303050","0.00000000"],["0.00303040","0.00000000"],["0.00303030","0.00000000"],["0.00303020","0.00000000"],["0.00303010","0.00000000"],["0.00302970","0.00000000"],["0.00302930","0.00000000"],["0.00302910","0.00000000"],["0.00302880","0.00000000"],["0.00302540","0.00000000"],["0.00302400","8.90000000"],["0.00302390","0.00000000"],["0.00302380","0.00000000"],["0.00302370","0.00000000"],["0.00302360","0.00000000"],["0.00302350","0.00000000"],["0.00302340","0.00000000"],["0.00302330","16.85000000"],["0.00302280","15.46000000"],["0.00302270","90.71000000"],["0.00302240","4.36000000"],["0.00302230","0.00000000"],["0.00302220","14.34000000"],["0.00302210","863.17000000"],["0.00302200","0.00000000"],["0.00300090","16.64000000"],["0.00299720","21.09000000"],["0.00299690","24.32000000"],["0.00294890","60.95000000"],["0.00276060","361.60000000"]],"a":[["0.00303270","9.83000000"],["0.00303280","12.28000000"],["0.00303290","0.00000000"],["0.00303300","0.00000000"],["0.00303310","0.00000000"],["0.00303320","0.00000000"],["0.00303330","0.00000000"],["0.00303340","28.51000000"],["0.00303350","23.00000000"],["0.00303620","82.66000000"],["0.00303630","70.00000000"],["0.00303700","77.04000000"],["0.00303710","23.72000000"],["0.00303780","20.00000000"]]},{"e":"depthUpdate","E":1557446396108,"s":"BNBBTC","U":264207709,"u":264207816,"b":[["0.00302620","29.87000000"],["0.00302610","8.90000000"],["0.00302600","0.00000000"],["0.00302590","0.00000000"],["0.00302580","0.00000000"],["0.00302570","0.00000000"],["0.00302560","0.00000000"],["0.00302550","0.00000000"],["0.00302540","0.00000000"],["0.00302530","0.00000000"],["0.00302520","0.00000000"],["0.00302510","0.00000000"],["0.00302500","0.00000000"],["0.00302490","2.73000000"],["0.00302420","0.00000000"],["0.00302410","50.29000000"],["0.00302400","70.00000000"],["0.00302330","0.00000000"],["0.00302280","0.00000000"],["0.00302220","0.00000000"],["0.00302210","793.17000000"],["0.00302100","10.00000000"],["0.00302090","0.00000000"],["0.00301600","7.48000000"],["0.00301310","61.92000000"],["0.00301300","0.00000000"],["0.00300490","203.85000000"],["0.00300110","74.72000000"],["0.00300030","75.77000000"],["0.00299310","73.06000000"]],"a":[["0.00303190","3.39000000"],["0.00303200","8.89000000"],["0.00303210","0.00000000"],["0.00303220","0.00000000"],["0.00303230","0.00000000"],["0.00303240","0.00000000"],["0.00303250","111.17000000"],["0.00303260","47.08000000"],["0.00303270","70.00000000"],["0.00303280","28.60000000"],["0.00303330","0.00000000"],["0.00303340","0.00000000"],["0.00303610","204.70000000"],["0.00303620","0.00000000"],["0.00303630","0.00000000"],["0.00303690","0.00000000"],["0.00303710","6.54000000"],["0.00303780","0.00000000"],["0.00303980","294.62000000"],["0.00304820","27.76000000"]]},{"e":"depthUpdate","E":1557446397108,"s":"BNBBTC","U":264207817,"u":264207910,"b":[["0.00302630","11.66000000"],["0.00302620","70.00000000"],["0.00302610","0.00000000"],["0.00302500","90.38000000"],["0.00302400","0.00000000"],["0.00302220","417.28000000"],["0.00301700","160.00000000"],["0.00301410","270.73000000"],["0.00301110","315.83000000"],["0.00300810","406.23000000"],["0.00300090","0.00000000"],["0.00299720","1.10000000"],["0.00299690","1.00000000"],["0.00294890","6.85000000"],["0.00276060","0.00000000"]],"a":[["0.00303050","26.01000000"],["0.00303060","7.10000000"],["0.00303070","28.51000000"],["0.00303080","0.00000000"],["0.00303090","0.00000000"],["0.00303100","0.00000000"],["0.00303110","0.00000000"],["0.00303120","0.00000000"],["0.00303130","0.00000000"],["0.00303140","0.00000000"],["0.00303150","0.00000000"],["0.00303160","0.00000000"],["0.00303170","0.00000000"],["0.00303180","23.00000000"],["0.00303190","0.00000000"],["0.00303200","0.00000000"],["0.00303250","0.00000000"],["0.00303260","129.74000000"],["0.00303650","20.00000000"],["0.00303690","0.00000000"],["0.00304070","13.19000000"],["0.00307140","1.70000000"]]},{"e":"depthUpdate","E":1557446398109,"s":"BNBBTC","U":264207911,"u":264207981,"b":[["0.00302650","8.90000000"],["0.00302640","11.77000000"],["0.00302630","0.00000000"],["0.00302500","0.00000000"],["0.00302280","2.76000000"]],"a":[["0.00303000","3.39000000"],["0.00303010","51.13000000"],["0.00303020","0.00000000"],["0.00303030","0.00000000"],["0.00303040","0.00000000"],["0.00303050","0.00000000"],["0.00303060","0.00000000"],["0.00303070","0.00000000"],["0.00303170","0.00000000"],["0.00303250","7.10000000"],["0.00303260","129.74000000"],["0.00303340","0.00000000"],["0.00303690","0.00000000"],["0.00303700","65.27000000"],["0.00303930","13.19000000"],["0.00304430","157.99000000"],["0.00305300","25.20000000"],["0.00305570","0.00000000"],["0.00306850","1.78000000"],["0.00308840","0.00000000"]]},{"e":"depthUpdate","E":1557446399109,"s":"BNBBTC","U":264207982,"u":264208007,"b":[["0.00303000","9.57000000"],["0.00302690","1.55000000"],["0.00302660","3.40000000"],["0.00302490","0.00000000"],["0.00302280","2.75000000"],["0.00302240","0.00000000"],["0.00298750","0.00000000"],["0.00298110","34.96000000"]],"a":[["0.00303000","0.00000000"],["0.00303010","28.51000000"],["0.00303170","7.10000000"],["0.00303250","0.00000000"],["0.00303700","0.00000000"],["0.00303710","0.00000000"],["0.00308690","3.53000000"]]},{"e":"depthUpdate","E":1557446400109,"s":"BNBBTC","U":264208008,"u":264208079,"b":[["0.00303000","0.00000000"],["0.00302690","0.00000000"],["0.00302660","6.15000000"],["0.00302640","0.00000000"],["0.00302620","155.86000000"],["0.00302430","0.00000000"],["0.00302420","1.43000000"],["0.00302280","0.00000000"],["0.00302270","0.00000000"],["0.00302210","0.00000000"],["0.00301120","799.91000000"]],"a":[["0.00302980","0.00000000"],["0.00302990","12.77000000"],["0.00303010","0.00000000"],["0.00303160","0.00000000"],["0.00303170","7.10000000"],["0.00303230","0.00000000"],["0.00303240","0.00000000"],["0.00303250","109.78000000"],["0.00303260","102.63000000"],["0.00303270","0.00000000"],["0.00303340","0.00000000"],["0.00303490","0.00000000"],["0.00303500","0.00000000"],["0.00303600","0.00000000"],["0.00303650","0.00000000"],["0.00303710","0.00000000"],["0.00303970","905.32000000"],["0.00303980","0.00000000"],["0.00303990","77.12000000"]]},{"e":"depthUpdate","E":1557446401109,"s":"BNBBTC","U":264208080,"u":264208168,"b":[["0.00302800","9.85000000"],["0.00302790","45.59000000"],["0.00302780","0.00000000"],["0.00302770","0.00000000"],["0.00302760","0.00000000"],["0.00302750","0.00000000"],["0.00302740","0.00000000"],["0.00302730","0.00000000"],["0.00302720","0.00000000"],["0.00302710","0.00000000"],["0.00302700","0.00000000"],["0.00302690","0.00000000"],["0.00302680","0.00000000"],["0.00302670","97.37000000"],["0.00302660","0.00000000"],["0.00302420","0.00000000"],["0.00302410","0.00000000"],["0.00299490","9.25000000"],["0.00299450","0.00000000"],["0.00299310","123.18000000"],["0.00299270","0.00000000"],["0.00299140","0.00000000"],["0.00298880","31.88000000"],["0.00298840","0.00000000"]],"a":[["0.00302990","0.00000000"],["0.00303170","0.00000000"],["0.00303180","16.87000000"],["0.00303250","0.00000000"],["0.00303260","55.55000000"],["0.00303280","0.00000000"],["0.00303340","27.12000000"],["0.00303600","82.66000000"],["0.00303710","0.00000000"],["0.00304820","0.00000000"],["0.00304900","0.00000000"],["0.00305000","552.93000000"]]},{"e":"depthUpdate","E":1557446402109,"s":"BNBBTC","U":264208169,"u":264208240,"b":[["0.00302880","0.00000000"],["0.00302870","0.00000000"],["0.00302860","0.00000000"],["0.00302850","0.00000000"],["0.00302840","0.00000000"],["0.00302830","0.00000000"],["0.00302820","3.40000000"],["0.00302810","9.84000000"],["0.00302800","70.00000000"],["0.00302790","0.00000000"],["0.00302680","0.00000000"],["0.00302660","1.41000000"],["0.00302650","17.55000000"],["0.00302620","85.86000000"],["0.00302220","0.00000000"],["0.00302200","462.84000000"],["0.00299180","5.00000000"]],"a":[["0.00303180","0.00000000"],["0.00303260","0.00000000"],["0.00303340","0.00000000"],["0.00303350","23.44000000"],["0.00303590","109.78000000"],["0.00303600","55.55000000"],["0.00303680","20.00000000"],["0.00303710","0.00000000"],["0.00304430","0.00000000"],["0.00304500","27.77000000"]]},{"e":"depthUpdate","E":1557446403109,"s":"BNBBTC","U":264208241,"u":264208283,"b":[["0.00302830","11.77000000"],["0.00302820","0.00000000"],["0.00302810","28.89000000"],["0.00302690","1.41000000"],["0.00302680","28.89000000"],["0.00302660","0.00000000"],["0.00302210","23.01000000"],["0.00300290","1849.47000000"],["0.00300020","6.59000000"],["0.00299360","183.72000000"],["0.00299260","0.36000000"]],"a":[["0.00303330","3.40000000"],["0.00303340","82.66000000"],["0.00303350","78.99000000"],["0.00303560","27.12000000"],["0.00303570","27.57000000"],["0.00303580","260.62000000"],["0.00303590","0.00000000"],["0.00303600","0.00000000"],["0.00303610","64.35000000"],["0.00303720","0.00000000"],["0.00303760","71.10000000"],["0.00303930","0.00000000"],["0.00303990","0.00000000"],["0.00304070","0.00000000"],["0.00304540","155.58000000"]]},{"e":"depthUpdate","E":1557446404110,"s":"BNBBTC","U":264208284,"u":264208317,"b":[["0.00302860","9.60000000"],["0.00302850","23.54000000"],["0.00302840","0.00000000"],["0.00302810","0.00000000"],["0.00302690","0.00000000"],["0.00302680","28.89000000"],["0.00302670","73.83000000"],["0.00302660","0.00000000"],["0.00302220","387.19000000"],["0.00302200","0.00000000"]],"a":[["0.00303330","32.79000000"],["0.00303350","55.99000000"],["0.00303540","27.12000000"],["0.00303550","22.99000000"],["0.00303560","0.00000000"],["0.00303570","0.00000000"],["0.00303960","81.19000000"]]},{"e":"depthUpdate","E":1557446405111,"s":"BNBBTC","U":264208318,"u":264208336,"b":[["0.00302680","28.89000000"],["0.00302660","0.00000000"],["0.00299580","3.11000000"],["0.00299530","0.66000000"]],"a":[["0.00356070","1.97000000"]]},{"e":"depthUpdate","E":1557446406111,"s":"BNBBTC","U":264208337,"u":264208380,"b":[["0.00302880","0.00000000"],["0.00302870","0.00000000"],["0.00302860","0.00000000"],["0.00302850","0.00000000"],["0.00302830","0.00000000"],["0.00302800","0.00000000"],["0.00302690","0.00000000"],["0.00302680","0.00000000"],["0.00302670","0.00000000"],["0.00302660","0.00000000"],["0.00302650","0.00000000"],["0.00302620","79.49000000"],["0.00302230","298.20000000"],["0.00302220","0.00000000"],["0.00300120","50.12000000"],["0.00299310","73.06000000"],["0.00278110","0.00000000"]],"a":[["0.00303280","0.00000000"],["0.00303290","28.53000000"],["0.00303300","15.06000000"],["0.00303310","0.00000000"],["0.00303320","28.89000000"],["0.00303330","27.57000000"],["0.00303540","0.00000000"],["0.00303670","71.10000000"],["0.00304210","13.18000000"],["0.00308690","1.74000000"],["0.00308820","1.80000000"]]},{"e":"depthUpdate","E":1557446407111,"s":"BNBBTC","U":264208381,"u":264208423,"b":[["0.00302630","8.90000000"],["0.00302620","11.05000000"],["0.00278320","11.08000000"]],"a":[["0.00303180","15.06000000"],["0.00303190","0.00000000"],["0.00303200","0.00000000"],["0.00303210","0.00000000"],["0.00303220","0.00000000"],["0.00303230","0.00000000"],["0.00303240","0.00000000"],["0.00303250","0.00000000"],["0.00303260","111.19000000"],["0.00303270","83.02000000"],["0.00303280","30.23000000"],["0.00303290","0.00000000"],["0.00303300","0.00000000"],["0.00303310","0.00000000"],["0.00303330","0.00000000"],["0.00303340","0.00000000"],["0.00303580","182.24000000"]]},{"e":"depthUpdate","E":1557446408111,"s":"BNBBTC","U":264208424,"u":264208512,"b":[["0.00302860","1.00000000"],["0.00302240","124.35000000"],["0.00300490","75.23000000"]],"a":[["0.00303020","28.53000000"],["0.00303030","26.70000000"],["0.00303040","0.00000000"],["0.00303050","0.00000000"],["0.00303060","0.00000000"],["0.00303070","0.00000000"],["0.00303080","0.00000000"],["0.00303090","0.00000000"],["0.00303100","0.00000000"],["0.00303110","0.00000000"],["0.00303120","0.00000000"],["0.00303130","0.00000000"],["0.00303140","0.00000000"],["0.00303150","15.06000000"],["0.00303160","0.63000000"],["0.00303170","111.20000000"],["0.00303180","70.00000000"],["0.00303250","192.63000000"],["0.00303260","0.00000000"],["0.00303270","82.39000000"],["0.00303280","0.00000000"],["0.00303350","0.44000000"],["0.00303550","42.99000000"],["0.00303570","76.41000000"],["0.00303580","0.00000000"],["0.00303680","0.00000000"],["0.00304060","13.72000000"]]},{"e":"depthUpdate","E":1557446409111,"s":"BNBBTC","U":264208513,"u":264208589,"b":[["0.00302250","33.78000000"],["0.00302230","0.00000000"],["0.00301700","0.00000000"],["0.00301600","167.48000000"]],"a":[["0.00302880","5.22000000"],["0.00302890","19.70000000"],["0.00302900","0.00000000"],["0.00302910","0.00000000"],["0.00302920","0.00000000"],["0.00302930","0.00000000"],["0.00302940","0.00000000"],["0.00302950","0.00000000"],["0.00302960","0.00000000"],["0.00302970","0.00000000"],["0.00302980","0.00000000"],["0.00302990","9.84000000"],["0.00303000","28.53000000"],["0.00303010","82.66000000"],["0.00303020","70.00000000"],["0.00303030","0.00000000"],["0.00303150","0.00000000"],["0.00303160","0.00000000"],["0.00303170","27.91000000"],["0.00303180","0.00000000"],["0.00303250","130.94000000"],["0.00303290","4.99000000"],["0.00303570","0.00000000"]]},{"e":"depthUpdate","E":1557446410111,"s":"BNBBTC","U":264208590,"u":264208643,"b":[["0.00302860","0.00000000"],["0.00302670","8.91000000"],["0.00302660","8.69000000"],["0.00302630","0.00000000"],["0.00302320","20.00000000"],["0.00302260","3.39000000"],["0.00302250","51.52000000"],["0.00302220","1.93000000"],["0.00302180","144.35000000"],["0.00215850","0.00000000"]],"a":[["0.00302830","0.00000000"],["0.00302840","0.00000000"],["0.00302870","0.00000000"],["0.00302880","66.71000000"],["0.00302890","0.00000000"],["0.00302990","0.00000000"],["0.00303000","0.00000000"],["0.00303010","0.00000000"],["0.00303020","0.00000000"],["0.00303160","0.00000000"],["0.00303230","28.53000000"],["0.00303240","0.00000000"],["0.00303320","0.00000000"],["0.00303540","7.91000000"],["0.00303650","82.66000000"],["0.00303660","61.74000000"],["0.00303670","0.00000000"],["0.00303720","373.72000000"],["0.00303760","0.00000000"],["0.00303960","0.00000000"]]},{"e":"depthUpdate","E":1557446411112,"s":"BNBBTC","U":264208644,"u":264208659,"b":[["0.00302680","3.39000000"],["0.00302330","10.56000000"],["0.00302260","0.00000000"],["0.00302180","0.00000000"],["0.00299070","0.00000000"]],"a":[["0.00303160","36.44000000"],["0.00303230","0.00000000"],["0.00303270","47.08000000"],["0.00303540","0.00000000"],["0.00303550","22.99000000"],["0.00303600","75.16000000"],["0.00303650","82.66000000"]]},{"e":"depthUpdate","E":1557446412112,"s":"BNBBTC","U":264208660,"u":264208667,"b":[["0.00302340","33.78000000"],["0.00299130","9.26000000"]],"a":[["0.00303270","0.00000000"],["0.00303400","20.00000000"],["0.00303540","66.21000000"],["0.00303760","13.20000000"]]},{"e":"depthUpdate","E":1557446413112,"s":"BNBBTC","U":264208668,"u":264208670,"b":[["0.00302330","0.00000000"]],"a":[["0.00303720","79.12000000"],["0.00345850","0.00000000"]]},{"e":"depthUpdate","E":1557446414113,"s":"BNBBTC","U":264208671,"u":264208737,"b":[["0.00302910","8.90000000"],["0.00302900","10.80000000"],["0.00302890","0.00000000"],["0.00302880","21.51000000"],["0.00302860","2.84000000"],["0.00302730","0.00000000"],["0.00302720","0.00000000"],["0.00302710","0.00000000"],["0.00302700","0.00000000"],["0.00302690","40.66000000"],["0.00302680","17.74000000"],["0.00302670","0.00000000"],["0.00302660","0.00000000"],["0.00302340","33.78000000"],["0.00302330","0.00000000"],["0.00302260","23.78000000"],["0.00302250","33.78000000"],["0.00302220","1.93000000"],["0.00299360","0.00000000"]],"a":[["0.00302880","0.00000000"],["0.00303160","98.71000000"],["0.00303170","97.91000000"],["0.00303540","0.00000000"],["0.00303590","0.00000000"],["0.00303650","0.00000000"],["0.00303970","0.00000000"],["0.00304530","905.29000000"],["0.00308360","52.12000000"],["0.00308820","0.00000000"],["0.00342790","3.16000000"]]},{"e":"depthUpdate","E":1557446415112,"s":"BNBBTC","U":264208738,"u":264208782,"b":[["0.00302940","0.00000000"],["0.00302930","8.90000000"],["0.00302920","10.80000000"],["0.00302910","51.53000000"],["0.00302900","0.00000000"],["0.00302880","0.00000000"],["0.00302680","0.00000000"],["0.00302520","0.00000000"],["0.00302510","20.00000000"],["0.00302360","23.77000000"],["0.00302350","64.22000000"],["0.00302340","0.00000000"],["0.00302320","0.00000000"],["0.00302260","0.00000000"],["0.00302250","0.00000000"],["0.00301310","0.00000000"],["0.00300300","183.15000000"],["0.00250150","53.23000000"]],"a":[["0.00303160","0.00000000"],["0.00303170","70.00000000"],["0.00303250","0.00000000"],["0.00303400","0.00000000"],["0.00303530","20.00000000"],["0.00303540","0.00000000"],["0.00303580","16.05000000"],["0.00303590","82.66000000"],["0.00303650","66.21000000"],["0.00303710","66.21000000"],["0.00303760","0.00000000"],["0.00304540","0.00000000"]]},{"e":"depthUpdate","E":1557446416112,"s":"BNBBTC","U":264208783,"u":264208821,"b":[["0.00302950","8.90000000"],["0.00302940","15.93000000"],["0.00302930","0.00000000"],["0.00302920","0.00000000"],["0.00302690","29.96000000"],["0.00302510","0.00000000"],["0.00302360","23.77000000"],["0.00302230","140.44000000"],["0.00302220","0.00000000"],["0.00302190","0.00000000"],["0.00301660","1.92000000"],["0.00301440","0.00000000"],["0.00301270","0.00000000"]],"a":[["0.00303170","0.00000000"],["0.00303270","7.91000000"],["0.00303280","28.89000000"],["0.00303340","90.80000000"],["0.00303350","70.44000000"],["0.00303520","124.84000000"],["0.00303530","0.00000000"],["0.00303540","0.00000000"],["0.00303570","0.00000000"],["0.00303580","0.00000000"],["0.00303590","0.00000000"],["0.00303640","0.00000000"]]},{"e":"depthUpdate","E":1557446417112,"s":"BNBBTC","U":264208822,"u":264208837,"b":[["0.00302970","8.90000000"],["0.00302960","18.88000000"],["0.00302950","0.00000000"],["0.00302940","0.00000000"],["0.00302630","20.00000000"],["0.00299180","3.34000000"],["0.00298730","1.67000000"]],"a":[["0.00303250","7.91000000"],["0.00303260","24.19000000"],["0.00303270","24.58000000"],["0.00303340","82.66000000"],["0.00303640","20.00000000"],["0.00304800","117.47000000"],["0.00305000","452.93000000"]]},{"e":"depthUpdate","E":1557446418112,"s":"BNBBTC","U":264208838,"u":264208861,"b":[["0.00302990","8.90000000"],["0.00302980","18.87000000"],["0.00302970","0.00000000"],["0.00302960","0.00000000"],["0.00302710","3.39000000"],["0.00302700","33.78000000"],["0.00302640","20.38000000"],["0.00302360","0.00000000"],["0.00299010","43.54000000"]],"a":[["0.00303230","7.91000000"],["0.00303240","8.14000000"],["0.00303250","94.58000000"],["0.00303260","16.05000000"],["0.00303270","0.00000000"],["0.00303340","0.00000000"],["0.00303350","0.44000000"],["0.00303500","0.00000000"],["0.00303510","82.66000000"],["0.00303640","0.00000000"],["0.00303650","0.00000000"]]},{"e":"depthUpdate","E":1557446419112,"s":"BNBBTC","U":264208862,"u":264208899,"b":[["0.00303030","8.90000000"],["0.00303020","18.88000000"],["0.00303010","0.00000000"],["0.00303000","0.00000000"],["0.00302990","0.00000000"],["0.00302980","0.00000000"],["0.00302710","0.00000000"],["0.00302690","0.00000000"],["0.00302640","0.00000000"],["0.00302630","0.00000000"],["0.00302550","20.00000000"],["0.00302360","20.38000000"],["0.00302230","0.00000000"],["0.00301660","3.39000000"],["0.00301440","1.92000000"],["0.00300600","0.00000000"],["0.00298850","34.64000000"]],"a":[["0.00303220","24.58000000"],["0.00303230","0.00000000"],["0.00303240","0.00000000"],["0.00303250","70.00000000"],["0.00303490","7.91000000"],["0.00303500","8.14000000"],["0.00303670","20.00000000"]]},{"e":"depthUpdate","E":1557446420113,"s":"BNBBTC","U":264208900,"u":264208940,"b":[["0.00303050","8.90000000"],["0.00303040","18.88000000"],["0.00303030","64.87000000"],["0.00303020","0.00000000"],["0.00302930","0.00000000"],["0.00302920","0.00000000"],["0.00302910","0.00000000"],["0.00302710","22.29000000"],["0.00302550","0.00000000"],["0.00302360","3.39000000"],["0.00302250","202.01000000"],["0.00301660","0.00000000"],["0.00301610","75.47000000"],["0.00301440","0.00000000"],["0.00300490","0.65000000"],["0.00299400","0.00000000"]],"a":[["0.00303210","0.00000000"],["0.00303220","0.00000000"],["0.00303250","0.00000000"],["0.00303280","0.00000000"],["0.00303480","98.71000000"],["0.00303490","70.00000000"],["0.00303500","0.00000000"],["0.00303510","0.00000000"],["0.00304560","155.88000000"]]},{"e":"depthUpdate","E":1557446421112,"s":"BNBBTC","U":264208941,"u":264208968,"b":[["0.00303070","8.90000000"],["0.00303060","28.84000000"],["0.00303050","0.00000000"],["0.00303040","0.00000000"],["0.00302690","20.00000000"],["0.00298210","2.57000000"]],"a":[["0.00303460","16.05000000"],["0.00303470","61.79000000"],["0.00303480","82.66000000"],["0.00303660","0.00000000"]]},{"e":"depthUpdate","E":1557446422112,"s":"BNBBTC","U":264208969,"u":264209006,"b":[["0.00303090","8.90000000"],["0.00303080","42.02000000"],["0.00303070","0.00000000"],["0.00303060","0.00000000"],["0.00302710","0.00000000"],["0.00302700","54.15000000"],["0.00302360","3.39000000"],["0.00301830","1.92000000"],["0.00301660","0.00000000"]],"a":[["0.00303260","0.00000000"],["0.00303470","144.45000000"],["0.00303480","0.00000000"]]},{"e":"depthUpdate","E":1557446423113,"s":"BNBBTC","U":264209007,"u":264209045,"b":[["0.00303120","0.00000000"],["0.00303110","8.90000000"],["0.00303100","40.25000000"],["0.00303090","0.00000000"],["0.00303080","0.00000000"],["0.00302870","42.23000000"],["0.00302700","54.15000000"],["0.00302360","0.00000000"],["0.00302270","3.39000000"],["0.00302260","1.92000000"],["0.00301960","0.00000000"],["0.00301830","0.00000000"],["0.00300610","12.72000000"],["0.00300540","1.84000000"]],"a":[["0.00303470","144.45000000"],["0.00303480","0.00000000"],["0.00303520","0.00000000"],["0.00304060","0.53000000"],["0.00304560","0.00000000"]]},{"e":"depthUpdate","E":1557446424113,"s":"BNBBTC","U":264209046,"u":264209075,"b":[["0.00303130","8.90000000"],["0.00303120","40.41000000"],["0.00303110","0.00000000"],["0.00303100","0.00000000"],["0.00302700","33.78000000"],["0.00302370","0.00000000"],["0.00302360","26.40000000"],["0.00302310","283.56000000"],["0.00302270","0.00000000"],["0.00302260","0.00000000"],["0.00302210","0.00000000"],["0.00301600","7.48000000"]],"a":[["0.00303470","61.79000000"],["0.00303480","0.00000000"],["0.00303550","0.00000000"],["0.00303790","130.44000000"],["0.00304490","22.99000000"]]},{"e":"depthUpdate","E":1557446425113,"s":"BNBBTC","U":264209076,"u":264209102,"b":[["0.00303170","8.90000000"],["0.00303160","28.67000000"],["0.00303150","0.00000000"],["0.00303140","0.00000000"],["0.00303130","64.87000000"],["0.00303120","0.00000000"],["0.00303030","0.00000000"],["0.00302880","3.39000000"],["0.00302700","54.14000000"],["0.00302370","0.00000000"],["0.00302360","150.63000000"],["0.00302240","0.00000000"],["0.00301800","160.00000000"]],"a":[["0.00303480","0.00000000"],["0.00303590","82.66000000"],["0.00303710","0.0